Workbook
Name Dept: '[1]1_New Hire'!#REF!
Name Dept: '[1]1_New Hire'!#REF!

Sheet 账单明细
G1: 收款通知书
G2: ADVISE ON COLLECTION
G3: 46174
A5: 公司名称：美诺电器有限公司.
A6: 序号 | B6: 姓名 | C6: 员工编号 | D6: 发生年月 | E6: 入职日期 | F6: 离职日期 | G6: 管理费 | H6: 当月社保基数 | I6: 当月公积金基数 | J6: 社保类 公司支付 Social Insurance Premiums Paid by Employer | S6: 公积金类 公司支付 Provident Fund Paid by Employer | T6: 公司合计 | U6: 社保类 个人支付 Social Insurance Premiums Paid by Employee | AA6: 公积金类 个人支付 Provident Fund Paid by Employee | AB6: 个人合计 | AC6: 实发工资 | AD6: 税前工资 | AE6: 13薪/奖金 | AF6: 其他 | AG6: 离职补尝金 | AH6: 总费用 | AI6: 附件税 | AJ6: 增值税 | AK6: 总计 | AL6: 备注 | AM6: 证件号码 | AN6: 社保缴纳地 | AO6: 所属公司 | AP6: 收入
A7: S/N | B7: Name | C7: Number | D7: YYYYMM | E7: Employment Start Date | F7: Employment Departure Date | G7: Adm Fee | H7: Social Insurance Base Amount of Current Month | I7: Provident Fund Base Amount of Current Month | J7: 养老保险 Endowment | K7: 医疗保险 Medical | L7: 失业保险 Unemploy-ment | M7: 工伤保险 Employment Injury | N7: 医疗生育保险 Medical Maternity | O7: 大病 Major Disease | P7: 保障金 Disabled people&Back pay Fund | Q7: 采暖费Heating Fee | R7: 社保工会费 Trade union fee | S7: 公积金 Provident Fund | T7: Subtotal of Employer Payment | U7: 养老保险 Endowment | V7: 医疗保险 Medical | W7: 失业保险 Unemploy-ment | X7: 工伤保险 Employment Injury | Y7: 生育保险 Maternity | Z7: 大病 Major Disease | AA7: 公积金 Provident Fund | AB7: Subtotal of Personal Payment | AL7: Remarks | AM7: ID Card | AN7: Location
A8: 1 | B8: 傅禄杰 | C8: MNCN00101 | D8: 202606 | E8: 2016-3-1 | G8: 595 | H8: 9902.6 | I8: 9902.6 | J8: =ROUND($H8*16%,2) -> 1584.42 | K8: =ROUNDDOWN(H8*9%,2) -> 891.23 | L8: =ROUND(H8*0.5%,2) -> 49.51 | M8: =ROUND(H8*0.32%,2) -> 31.69 | P8: =ROUND(H8*(1.5%*0.9),2) -> 133.69 | S8: =ROUND(I8*7%,0) -> 693 | T8: =ROUND(SUM(J8:S8),2) -> 3383.54 | U8: =ROUND(H8*8%,2) -> 792.21 | V8: =ROUND(H8*2%,2) -> 198.05 | W8: =ROUND(H8*0.5%,2) -> 49.51 | AA8: =ROUND(I8*7%,0) -> 693 | AB8: =ROUND(SUM(U8:AA8),2) -> 1732.77 | AC8: =VLOOKUP(AM:AM,工资明细!E:AP,38,0) -> 6306.12 | AD8: =VLOOKUP(AM:AM,工资明细!E:AH,30,0) -> 6400.11 | AH8: =ROUND(G8+T8+AB8+AD8+AF8+AG8+AE8,2) -> 12111.42 | AI8: =ROUND(AH8*(1/(1-0.78%)-1),2) -> 95.21 | AJ8: =ROUND(SUM(AH8:AI8)*6%,2) -> 732.4 | AK8: =ROUND(SUM(AH8:AJ8),2) -> 12939.03 | AM8: 310103198112094018 | AN8: 上海市 | AO8: 上海合杰 | AP8: =U8 -> 792.21 | AQ8: =V8+Z8 -> 198.05 | AR8: =W8 -> 49.51 | AS8: =AA8 -> 693
A9: 2 | B9: 刘星全 | C9: MNCN00263 | D9: 202606 | E9: 2016-4-13 | G9: 595 | H9: 14649.8 | I9: 14649.8 | J9: =ROUND($H9*16%,2) -> 2343.97 | K9: =ROUNDDOWN(H9*9%,2) -> 1318.48 | L9: =ROUND(H9*0.5%,2) -> 73.25 | M9: =ROUND(H9*0.32%,2) -> 46.88 | P9: =ROUND(H9*(1.5%*0.9),2) -> 197.77 | S9: =ROUND(I9*7%,0) -> 1025 | T9: =ROUND(SUM(J9:S9),2) -> 5005.35 | U9: =ROUND(H9*8%,2) -> 1171.98 | V9: =ROUND(H9*2%,2) -> 293 | W9: =ROUND(H9*0.5%,2) -> 73.25 | AA9: =ROUND(I9*7%,0) -> 1025 | AB9: =ROUND(SUM(U9:AA9),2) -> 2563.23 | AC9: =VLOOKUP(AM:AM,工资明细!E:AP,38,0) -> 9316.74 | AD9: =VLOOKUP(AM:AM,工资明细!E:AH,30,0) -> 9316.74 | AH9: =ROUND(G9+T9+AB9+AD9+AF9+AG9+AE9,2) -> 17480.32 | AI9: =ROUND(AH9*(1/(1-0.78%)-1),2) -> 137.42 | AJ9: =ROUND(SUM(AH9:AI9)*6%,2) -> 1057.06 | AK9: =ROUND(SUM(AH9:AJ9),2) -> 18674.8 | AM9: 37292519890401691X | AN9: 上海市 | AO9: 上海合杰 | AP9: =U9 -> 1171.98 | AQ9: =V9+Z9 -> 293 | AR9: =W9 -> 73.25 | AS9: =AA9 -> 1025
A10: 3 | B10: 卢晓香 | C10: MNCN00391 | D10: 202606 | E10: 2018-2-7 | G10: 595 | H10: 11167.4 | I10: 11167.4 | J10: =ROUND($H10*16%,2) -> 1786.78 | K10: =ROUND(H10*9%,2) -> 1005.07 | L10: =ROUND(H10*0.5%,2) -> 55.84 | M10: =ROUND(H10*0.32%,2) -> 35.74 | P10: =ROUND(H10*(1.5%*0.9),2) -> 150.76 | S10: =ROUND(I10*7%,0) -> 782 | T10: =ROUND(SUM(J10:S10),2) -> 3816.19 | U10: =ROUND(H10*8%,2) -> 893.39 | V10: =ROUND(H10*2%,2) -> 223.35 | W10: =ROUND(H10*0.5%,2) -> 55.84 | AA10: =ROUND(I10*7%,0) -> 782 | AB10: =ROUND(SUM(U10:AA10),2) -> 1954.58 | AC10: =VLOOKUP(AM:AM,工资明细!E:AP,38,0) -> 5921.19 | AD10: =VLOOKUP(AM:AM,工资明细!E:AH,30,0) -> 5921.19 | AH10: =ROUND(G10+T10+AB10+AD10+AF10+AG10+AE10,2) -> 12286.96 | AI10: =ROUND(AH10*(1/(1-0.78%)-1),2) -> 96.59 | AJ10: =ROUND(SUM(AH10:AI10)*6%,2) -> 743.01 | AK10: =ROUND(SUM(AH10:AJ10),2) -> 13126.56 | AM10: 422324198009156823 | AN10: 上海市 | AO10: 上海合杰 | AP10: =U10 -> 893.39 | AQ10: =V10+Z10 -> 223.35 | AR10: =W10 -> 55.84 | AS10: =AA10 -> 782
A11: 4 | B11: 秦懿 | C11: MNCN00369 | D11: 202606 | E11: 2017-10-9 | G11: 595 | H11: 9803.1 | I11: 9803.1 | J11: =ROUND($H11*16%,2) -> 1568.5 | K11: =ROUND(H11*9%,2) -> 882.28 | L11: =ROUND(H11*0.5%,2) -> 49.02 | M11: =ROUND(H11*0.32%,2) -> 31.37 | P11: =ROUND(H11*(1.5%*0.9),2) -> 132.34 | S11: =ROUND(I11*7%,0) -> 686 | T11: =ROUND(SUM(J11:S11),2) -> 3349.51 | U11: =ROUND(H11*8%,2) -> 784.25 | V11: =ROUND(H11*2%,2) -> 196.06 | W11: =ROUND(H11*0.5%,2) -> 49.02 | AA11: =ROUND(I11*7%,0) -> 686 | AB11: =ROUND(SUM(U11:AA11),2) -> 1715.33 | AC11: =VLOOKUP(AM:AM,工资明细!E:AP,38,0) -> 5379.19 | AD11: =VLOOKUP(AM:AM,工资明细!E:AH,30,0) -> 5379.19 | AH11: =ROUND(G11+T11+AB11+AD11+AF11+AG11+AE11,2) -> 11039.03 | AI11: =ROUND(AH11*(1/(1-0.78%)-1),2) -> 86.78 | AJ11: =ROUND(SUM(AH11:AI11)*6%,2) -> 667.55 | AK11: =ROUND(SUM(AH11:AJ11),2) -> 11793.36 | AM11: 310105198108060045 | AN11: 上海市 | AO11: 上海合杰 | AP11: =U11 -> 784.25 | AQ11: =V11+Z11 -> 196.06 | AR11: =W11 -> 49.02 | AS11: =AA11 -> 686
A12: 5 | B12: 周之绮 | C12: MNCN00390 | D12: 202606 | E12: 43136 | G12: 595 | H12: 17572.3 | I12: 17572.3 | J12: =ROUND($H12*16%,2) -> 2811.57 | K12: =ROUND(H12*9%,2) -> 1581.51 | L12: =ROUND(H12*0.5%,2) -> 87.86 | M12: =ROUND(H12*0.32%,2) -> 56.23 | P12: =ROUND(H12*(1.5%*0.9),2) -> 237.23 | S12: =ROUND(I12*7%,0) -> 1230 | T12: =ROUND(SUM(J12:S12),2) -> 6004.4 | U12: =ROUND(H12*8%,2) -> 1405.78 | V12: =ROUND(H12*2%,2) -> 351.45 | W12: =ROUND(H12*0.5%,2) -> 87.86 | AA12: =ROUND(I12*7%,0) -> 1230 | AB12: =ROUND(SUM(U12:AA12),2) -> 3075.09 | AC12: =VLOOKUP(AM:AM,工资明细!E:AP,38,0) -> 14293.88 | AD12: =VLOOKUP(AM:AM,工资明细!E:AH,30,0) -> 14300.84 | AH12: =ROUND(G12+T12+AB12+AD12+AF12+AG12+AE12,2) -> 23975.33 | AI12: =ROUND(AH12*(1/(1-0.78%)-1),2) -> 188.48 | AJ12: =ROUND(SUM(AH12:AI12)*6%,2) -> 1449.83 | AK12: =ROUND(SUM(AH12:AJ12),2) -> 25613.64 | AM12: 310107198302217221 | AN12: 上海市 | AO12: 上海合杰 | AP12: =U12 -> 1405.78 | AQ12: =V12+Z12 -> 351.45 | AR12: =W12 -> 87.86 | AS12: =AA12 -> 1230
A13: 6 | B13: 李旻天 | C13: MNCN00399 | D13: 202606 | E13: 43189 | G13: 595 | H13: 16112 | I13: 16112 | J13: =ROUND($H13*16%,2) -> 2577.92 | K13: =ROUND(H13*9%,2) -> 1450.08 | L13: =ROUND(H13*0.5%,2) -> 80.56 | M13: =ROUND(H13*0.32%,2) -> 51.56 | P13: =ROUND(H13*(1.5%*0.9),2) -> 217.51 | S13: =ROUND(I13*7%,0) -> 1128 | T13: =ROUND(SUM(J13:S13),2) -> 5505.63 | U13: =ROUND(H13*8%,2) -> 1288.96 | V13: =ROUND(H13*2%,2) -> 322.24 | W13: =ROUND(H13*0.5%,2) -> 80.56 | AA13: =ROUND(I13*7%,0) -> 1128 | AB13: =ROUND(SUM(U13:AA13),2) -> 2819.76 | AC13: =VLOOKUP(AM:AM,工资明细!E:AP,38,0) -> 11657.88 | AD13: =VLOOKUP(AM:AM,工资明细!E:AH,30,0) -> 11927.38 | AH13: =ROUND(G13+T13+AB13+AD13+AF13+AG13+AE13,2) -> 20847.77 | AI13: =ROUND(AH13*(1/(1-0.78%)-1),2) -> 163.89 | AJ13: =ROUND(SUM(AH13:AI13)*6%,2) -> 1260.7 | AK13: =ROUND(SUM(AH13:AJ13),2) -> 22272.36 | AM13: 310107198503120944 | AN13: 上海市 | AO13: 上海合杰 | AP13: =U13 -> 1288.96 | AQ13: =V13+Z13 -> 322.24 | AR13: =W13 -> 80.56 | AS13: =AA13 -> 1128
A14: 7 | B14: 陆立琴 | C14: MNCN00414 | D14: 202606 | E14: 43236 | G14: 595 | H14: 7460 | I14: 7405.3 | J14: =ROUND($H14*16%,2) -> 1193.6 | K14: =ROUND(H14*9%,2) -> 671.4 | L14: =ROUND(H14*0.5%,2) -> 37.3 | M14: =ROUND(H14*0.32%,2) -> 23.87 | P14: =ROUND(H14*(1.5%*0.9),2) -> 100.71 | S14: =ROUND(I14*7%,0) -> 518 | T14: =ROUND(SUM(J14:S14),2) -> 2544.88 | U14: =ROUND(H14*8%,2) -> 596.8 | V14: =ROUND(H14*2%,2) -> 149.2 | W14: =ROUND(H14*0.5%,2) -> 37.3 | AA14: =ROUND(I14*7%,0) -> 518 | AB14: =ROUND(SUM(U14:AA14),2) -> 1301.3 | AC14: =VLOOKUP(AM:AM,工资明细!E:AP,38,0) -> 5516.01 | AD14: =VLOOKUP(AM:AM,工资明细!E:AH,30,0) -> 5516.01 | AH14: =ROUND(G14+T14+AB14+AD14+AF14+AG14+AE14,2) -> 9957.19 | AI14: =ROUND(AH14*(1/(1-0.78%)-1),2) -> 78.28 | AJ14: =ROUND(SUM(AH14:AI14)*6%,2) -> 602.13 | AK14: =ROUND(SUM(AH14:AJ14),2) -> 10637.6 | AM14: 320924198001065721 | AN14: 上海市 | AO14: 上海合杰 | AP14: =U14 -> 596.8 | AQ14: =V14+Z14 -> 149.2 | AR14: =W14 -> 37.3 | AS14: =AA14 -> 518
A15: 8 | B15: 王金栋 | C15: MNCN00163 | D15: 202606 | E15: 2016-3-1 | G15: 595 | H15: 29348 | I15: 29348 | J15: =ROUND(H15*16%,2) -> 4695.68 | K15: =ROUND(H15*9.8%,2) -> 2876.1 | L15: =ROUND(H15*0.5%,2) -> 146.74 | M15: =ROUND(H15*0.32%,2) -> 93.91 | P15: =ROUND(H15*1.5%,2) -> 440.22 | S15: =ROUND(I15*12%,0) -> 3522 | T15: =ROUND(SUM(J15:S15),2) -> 11774.65 | U15: =ROUND(H15*8%,2) -> 2347.84 | V15: =ROUND(H15*2%,2) -> 586.96 | W15: =ROUND(H15*0.5%,2) -> 146.74 | Z15: 3 | AA15: =S15 -> 3522 | AB15: =ROUND(SUM(U15:AA15),2) -> 6606.54 | AC15: =VLOOKUP(AM:AM,工资明细!E:AP,38,0) -> 2540 | AD15: =VLOOKUP(AM:AM,工资明细!E:AH,30,0) -> 2540 | AH15: =ROUND(G15+T15+AB15+AD15+AF15+AG15+AE15,2) -> 21516.19 | AI15: =ROUND(AH15*(1/(1-0.78%)-1),2) -> 169.15 | AJ15: =ROUND(SUM(AH15:AI15)*6%,2) -> 1301.12 | AK15: =ROUND(SUM(AH15:AJ15),2) -> 22986.46 | AM15: 110223198702142714 | AN15: 北京市 | AO15: 北京合杰 | AP15: =U15 -> 2347.84 | AQ15: =V15+Z15 -> 589.96 | AR15: =W15 -> 146.74 | AS15: =AA15 -> 3522
A16: 9 | B16: 徐乐 | C16: MNCN00238 | D16: 202606 | E16: 2016-3-1 | G16: 595 | H16: 27346 | I16: 27346 | J16: =ROUND(H16*16%,2) -> 4375.36 | K16: =ROUND(H16*9.8%,2) -> 2679.91 | L16: =ROUND(H16*0.5%,2) -> 136.73 | M16: =ROUND(H16*0.32%,2) -> 87.51 | P16: =ROUND(H16*1.5%,2) -> 410.19 | S16: =ROUND(I16*12%,0) -> 3282 | T16: =ROUND(SUM(J16:S16),2) -> 10971.7 | U16: =ROUND(H16*8%,2) -> 2187.68 | V16: =ROUND(H16*2%,2) -> 546.92 | W16: =ROUND(H16*0.5%,2) -> 136.73 | Z16: 3 | AA16: =S16 -> 3282 | AB16: =ROUND(SUM(U16:AA16),2) -> 6156.33 | AC16: =VLOOKUP(AM:AM,工资明细!E:AP,38,0) -> 5765.02 | AD16: =VLOOKUP(AM:AM,工资明细!E:AH,30,0) -> 6030.89 | AH16: =ROUND(G16+T16+AB16+AD16+AF16+AG16+AE16,2) -> 23753.92 | AI16: =ROUND(AH16*(1/(1-0.78%)-1),2) -> 186.74 | AJ16: =ROUND(SUM(AH16:AI16)*6%,2) -> 1436.44 | AK16: =ROUND(SUM(AH16:AJ16),2) -> 25377.1 | AM16: 110222198702056027 | AN16: 北京市 | AO16: 北京合杰 | AP16: =U16 -> 2187.68 | AQ16: =V16+Z16 -> 549.92 | AR16: =W16 -> 136.73 | AS16: =AA16 -> 3282
A17: 10 | B17: 吕静雯 | C17: MNCN00461 | D17: 202606 | E17: 44301 | G17: 595 | H17: 29678 | I17: 29678 | J17: =ROUND(H17*16%,2) -> 4748.48 | K17: =ROUND(H17*9.8%,2) -> 2908.44 | L17: =ROUND(H17*0.5%,2) -> 148.39 | M17: =ROUND(H17*0.32%,2) -> 94.97 | P17: =ROUND(H17*1.5%,2) -> 445.17 | S17: =ROUND(I17*12%,0) -> 3561 | T17: =ROUND(SUM(J17:S17),2) -> 11906.45 | U17: =ROUND(H17*8%,2) -> 2374.24 | V17: =ROUND(H17*2%,2) -> 593.56 | W17: =ROUND(H17*0.5%,2) -> 148.39 | Z17: 3 | AA17: =S17 -> 3561 | AB17: =ROUND(SUM(U17:AA17),2) -> 6680.19 | AC17: =VLOOKUP(AM:AM,工资明细!E:AP,38,0) -> 4310.52 | AD17: =VLOOKUP(AM:AM,工资明细!E:AH,30,0) -> 4651.18 | AH17: =ROUND(G17+T17+AB17+AD17+AF17+AG17+AE17,2) -> 23832.82 | AI17: =ROUND(AH17*(1/(1-0.78%)-1),2) -> 187.36 | AJ17: =ROUND(SUM(AH17:AI17)*6%,2) -> 1441.21 | AK17: =ROUND(SUM(AH17:AJ17),2) -> 25461.39 | AM17: 130181198905025229 | AN17: 北京市 | AO17: 北京合杰 | AP17: =U17 -> 2374.24 | AQ17: =V17+Z17 -> 596.56 | AR17: =W17 -> 148.39 | AS17: =AA17 -> 3561
A18: 11 | B18: 张晨 | C18: MNCN00553 | D18: 202606 | E18: 44301 | G18: 595 | H18: 7230 | I18: 7230 | J18: =ROUND(H18*16%,2) -> 1156.8 | K18: =ROUND(H18*9.8%,2) -> 708.54 | L18: =ROUND(H18*0.5%,2) -> 36.15 | M18: =ROUND(H18*0.32%,2) -> 23.14 | P18: =ROUND(H18*1.5%,2) -> 108.45 | S18: =ROUND(I18*12%,0) -> 868 | T18: =ROUND(SUM(J18:S18),2) -> 2901.08 | U18: =ROUND(H18*8%,2) -> 578.4 | V18: =ROUND(H18*2%,2) -> 144.6 | W18: =ROUND(H18*0.5%,2) -> 36.15 | Z18: 3 | AA18: =S18 -> 868 | AB18: =ROUND(SUM(U18:AA18),2) -> 1630.15 | AC18: =VLOOKUP(AM:AM,工资明细!E:AP,38,0) -> 7804.78 | AD18: =VLOOKUP(AM:AM,工资明细!E:AH,30,0) -> 7804.78 | AH18: =ROUND(G18+T18+AB18+AD18+AF18+AG18+AE18,2) -> 12931.01 | AI18: =ROUND(AH18*(1/(1-0.78%)-1),2) -> 101.65 | AJ18: =ROUND(SUM(AH18:AI18)*6%,2) -> 781.96 | AK18: =ROUND(SUM(AH18:AJ18),2) -> 13814.62 | AM18: 11010219811008041X | AN18: 北京市 | AO18: 北京合杰 | AP18: =U18 -> 578.4 | AQ18: =V18+Z18 -> 147.6 | AR18: =W18 -> 36.15 | AS18: =AA18 -> 868
A19: 12 | B19: 贾璞 | C19: MNCN00552 | D19: 202606 | E19: 44301 | G19: 595 | H19: 12502 | I19: 12502 | J19: =ROUND(H19*16%,2) -> 2000.32 | K19: =ROUND(H19*9.8%,2) -> 1225.2 | L19: =ROUND(H19*0.5%,2) -> 62.51 | M19: =ROUND(H19*0.32%,2) -> 40.01 | P19: =ROUND(H19*1.5%,2) -> 187.53 | S19: =ROUND(I19*12%,0) -> 1500 | T19: =ROUND(SUM(J19:S19),2) -> 5015.57 | U19: =ROUND(H19*8%,2) -> 1000.16 | V19: =ROUND(H19*2%,2) -> 250.04 | W19: =ROUND(H19*0.5%,2) -> 62.51 | Z19: 3 | AA19: =S19 -> 1500 | AB19: =ROUND(SUM(U19:AA19),2) -> 2815.71 | AC19: =VLOOKUP(AM:AM,工资明细!E:AP,38,0) -> 11590.83 | AD19: =VLOOKUP(AM:AM,工资明细!E:AH,30,0) -> 12636.01 | AH19: =ROUND(G19+T19+AB19+AD19+AF19+AG19+AE19,2) -> 21062.29 | AI19: =ROUND(AH19*(1/(1-0.78%)-1),2) -> 165.58 | AJ19: =ROUND(SUM(AH19:AI19)*6%,2) -> 1273.67 | AK19: =ROUND(SUM(AH19:AJ19),2) -> 22501.54 | AM19: 130624198708032411 | AN19: 北京市 | AO19: 北京合杰 | AP19: =U19 -> 1000.16 | AQ19: =V19+Z19 -> 253.04 | AR19: =W19 -> 62.51 | AS19: =AA19 -> 1500
A20: 13 | B20: 韩英 | C20: MNCN00226 | D20: 202606 | E20: 2016-3-1 | G20: 595 | H20: 23864 | I20: 21696 | J20: =ROUND($H20*16%,2) -> 3818.24 | K20: =ROUND($H20*7%,2) -> 1670.48 | L20: =ROUND(H20*0.5%,2) -> 119.32 | M20: =ROUND($H20*0.4%,2) -> 95.46 | N20: =ROUND($H20*0.8%,2) -> 190.91 | S20: =ROUND(I20*12%,0) -> 2604 | T20: =ROUND(SUM(J20:S20),2) -> 8498.41 | U20: =ROUND($H20*8%,2) -> 1909.12 | V20: =ROUND($H20*2%,2) -> 477.28 | W20: =ROUND($H20*0.5%,2) -> 119.32 | Z20: 10 | AA20: =S20 -> 2604 | AB20: =ROUND(SUM(U20:AA20),2) -> 5119.72 | AC20: =VLOOKUP(AM:AM,工资明细!E:AP,38,0) -> 8187.29 | AD20: =VLOOKUP(AM:AM,工资明细!E:AH,30,0) -> 8776.96 | AH20: =ROUND(G20+T20+AB20+AD20+AF20+AG20+AE20,2) -> 22990.09 | AI20: =ROUND(AH20*(1/(1-0.78%)-1),2) -> 180.73 | AJ20: =ROUND(SUM(AH20:AI20)*6%,2) -> 1390.25 | AK20: =ROUND(SUM(AH20:AJ20),2) -> 24561.07 | AM20: 320123197712131022 | AN20: 南京市 | AO20: 上海合杰 | AP20: =U20 -> 1909.12 | AQ20: =V20+Z20 -> 487.28 | AR20: =W20 -> 119.32 | AS20: =AA20 -> 2604
A21: 14 | B21: 沈国伟 | C21: MNCN00246 | D21: 202606 | E21: 2016-3-1 | G21: 595 | H21: 16997.91 | I21: 13128.87 | J21: =ROUND($H21*16%,2) -> 2719.67 | K21: =ROUND($H21*9.5%,2) -> 1614.8 | L21: =ROUND(H21*0.5%,2) -> 84.99 | M21: =ROUND(H21*0.2%,2) -> 34 | P21: =ROUND(H21*1.5%,2) -> 254.97 | S21: 1575 | T21: =ROUND(SUM(J21:S21),2) -> 6283.43 | U21: =ROUND($H21*8%,2) -> 1359.83 | V21: =ROUND($H21*2%,2) -> 339.96 | W21: =ROUND($H21*0.5%,2) -> 84.99 | AA21: =S21 -> 1575 | AB21: =ROUND(SUM(U21:AA21),2) -> 3359.78 | AC21: =VLOOKUP(AM:AM,工资明细!E:AP,38,0) -> 6578.64 | AD21: =VLOOKUP(AM:AM,工资明细!E:AH,30,0) -> 6578.64 | AH21: =ROUND(G21+T21+AB21+AD21+AF21+AG21+AE21,2) -> 16816.85 | AI21: =ROUND(AH21*(1/(1-0.78%)-1),2) -> 132.2 | AJ21: =ROUND(SUM(AH21:AI21)*6%,2) -> 1016.94 | AK21: =ROUND(SUM(AH21:AJ21),2) -> 17965.99 | AM21: 330184198807080319 | AN21: 杭州市 | AO21: 合杰区域分公司 | AP21: =U21 -> 1359.83 | AQ21: =V21+Z21 -> 339.96 | AR21: =W21 -> 84.99 | AS21: =AA21 -> 1575
A22: 15 | B22: 周华荣 | C22: MNCN00281 | D22: 202606 | E22: 2016-7-1 | G22: 595 | H22: 7464 | I22: 7932 | J22: =ROUND($H22*16%,2) -> 1194.24 | K22: =ROUND(H22*10.5%,2) -> 783.72 | L22: =ROUND(H22*0.5%,2) -> 37.32 | M22: =ROUND(H22*0.4%,2) -> 29.86 | P22: =ROUND(H22*1.5%,2) -> 111.96 | S22: =ROUND(I22*11%,0) -> 873 | T22: =ROUND(SUM(J22:S22),2) -> 3030.1 | U22: =ROUND(H22*8%,2) -> 597.12 | V22: =ROUND(H22*2%,2) -> 149.28 | W22: =ROUND(H22*0.5%,2) -> 37.32 | Z22: 21 | AA22: =S22 -> 873 | AB22: =ROUND(SUM(U22:AA22),2) -> 1677.72 | AC22: =VLOOKUP(AM:AM,工资明细!E:AP,38,0) -> 5546.15 | AD22: =VLOOKUP(AM:AM,工资明细!E:AH,30,0) -> 5546.15 | AH22: =ROUND(G22+T22+AB22+AD22+AF22+AG22+AE22,2) -> 10848.97 | AI22: =ROUND(AH22*(1/(1-0.78%)-1),2) -> 85.29 | AJ22: =ROUND(SUM(AH22:AI22)*6%,2) -> 656.06 | AK22: =ROUND(SUM(AH22:AJ22),2) -> 11590.32 | AM22: 420822198801105563 | AN22: 天津市 | AO22: 合杰区域分公司 | AP22: =U22 -> 597.12 | AQ22: =V22+Z22 -> 170.28 | AR22: =W22 -> 37.32 | AS22: =AA22 -> 873
A23: 16 | B23: 李爱芳 | C23: MNCN00300 | D23: 202606 | E23: 2016-12-17 | G23: 595 | H23: 9488 | I23: 7203.65 | J23: =ROUND($H23*16%,2) -> 1518.08 | K23: =ROUND(H23*6%,2) -> 569.28 | L23: =ROUND($H23*0.5%,2) -> 47.44 | M23: =ROUND($H23*0.4%,2) -> 37.95 | N23: =ROUND($H23*0.8%,2) -> 75.9 | S23: =ROUND(I23*8%,2) -> 576.29 | T23: =ROUND(SUM(J23:S23),2) -> 2824.94 | U23: =ROUND($H23*8%,2) -> 759.04 | V23: =ROUND($H23*2%,2) -> 189.76 | W23: =ROUND($H23*0.5%,2) -> 47.44 | Z23: 5 | AA23: =S23 -> 576.29 | AB23: =ROUND(SUM(U23:AA23),2) -> 1577.53 | AC23: =VLOOKUP(AM:AM,工资明细!E:AP,38,0) -> 8969.56 | AD23: =VLOOKUP(AM:AM,工资明细!E:AH,30,0) -> 9111.31 | AH23: =ROUND(G23+T23+AB23+AD23+AF23+AG23+AE23,2) -> 14108.78 | AI23: =ROUND(AH23*(1/(1-0.78%)-1),2) -> 110.91 | AJ23: =ROUND(SUM(AH23:AI23)*6%,2) -> 853.18 | AK23: =ROUND(SUM(AH23:AJ23),2) -> 15072.87 | AM23: 320981197710083482 | AN23: 苏州园区 | AO23: 上海合杰 | AP23: =U23 -> 759.04 | AQ23: =V23+Z23 -> 194.76 | AR23: =W23 -> 47.44 | AS23: =AA23 -> 576.29
A24: 17 | B24: 程琪 | C24: MNCN00355 | D24: 202606 | E24: 2017-8-16 | G24: 595 | H24: 11666 | I24: 11666.12 | J24: =ROUND($H24*16%,2) -> 1866.56 | K24: =ROUND($H24*8.7%,2) -> 1014.94 | L24: =ROUND($H24*0.7%,2) -> 81.66 | M24: =ROUND($H24*0.2%,2) -> 23.33 | P24: =ROUND(H24*1.5%,2) -> 174.99 | S24: =ROUND($I24*8%,2) -> 933.29 | T24: =ROUND(SUM(J24:S24),2) -> 4094.77 | U24: =ROUND($H24*8%,2) -> 933.28 | V24: =ROUND($H24*2%,2) -> 233.32 | W24: =ROUND($H24*0.3%,2) -> 35 | Z24: 7 | AA24: =S24 -> 933.29 | AB24: =ROUND(SUM(U24:AA24),2) -> 2141.89 | AC24: =VLOOKUP(AM:AM,工资明细!E:AP,38,0) -> 7718.13 | AD24: =VLOOKUP(AM:AM,工资明细!E:AH,30,0) -> 7858.39 | AH24: =ROUND(G24+T24+AB24+AD24+AF24+AG24+AE24,2) -> 14690.05 | AI24: =ROUND(AH24*(1/(1-0.78%)-1),2) -> 115.48 | AJ24: =ROUND(SUM(AH24:AI24)*6%,2) -> 888.33 | AK24: =ROUND(SUM(AH24:AJ24),2) -> 15693.86 | AM24: 42010219880908082x | AN24: 武汉市 | AO24: 合杰区域分公司 | AP24: =U24 -> 933.28 | AQ24: =V24+Z24 -> 240.32 | AR24: =W24 -> 35 | AS24: =AA24 -> 933.29
B25: 贾锐 | D25: 202605 | E25: 43103 | G25: 595 | H25: 2761 | I25: 10640 | J25: =ROUND(H25*16%,2) -> 441.76 | K25: =ROUND(H25*7.55%,2) -> 208.46 | L25: =ROUND(H25*0.6%,2) -> 16.57 | M25: =ROUND(H25*0.4%,2) -> 11.04 | O25: =ROUND(H25*0.75%,2) -> 20.71 | P25: =ROUND(H25*1.5%,2) -> 41.42 | T25: =ROUND(SUM(J25:S25),2) -> 739.96 | U25: =ROUND(H25*8%,2) -> 220.88 | V25: =ROUND(H25*2%,2) -> 55.22 | W25: =ROUND(H25*0.4%,2) -> 11.04 | AA25: =S25 -> 0 | AB25: =ROUND(SUM(U25:AA25),2) -> 287.14 | AH25: =ROUND(G25+T25+AB25+AD25+AF25+AG25+AE25,2) -> 1622.1 | AI25: =ROUND(AH25*(1/(1-0.78%)-1),2) -> 12.75 | AJ25: =ROUND(SUM(AH25:AI25)*6%,2) -> 98.09 | AK25: =ROUND(SUM(AH25:AJ25),2) -> 1732.94 | AL25: 5月基数差异费用 | AM25: 510104198710260016 | AN25: 成都市 | AO25: 成都合杰 | AP25: =U25 -> 220.88 | AQ25: =V25+Z25 -> 55.22 | AR25: =W25 -> 11.04 | AS25: =AA25 -> 0
A26: 18 | B26: 贾锐 | C26: MNCN00381 | D26: 202606 | E26: 43103 | G26: 595 | H26: 6809 | I26: 10640 | J26: =ROUND(H26*16%,2) -> 1089.44 | K26: =ROUND(H26*7.55%,2) -> 514.08 | L26: =ROUND(H26*0.6%,2) -> 40.85 | M26: =ROUND(H26*0.4%,2) -> 27.24 | O26: =ROUND(H26*0.75%,2) -> 51.07 | P26: =ROUND(H26*1.5%,2) -> 102.14 | S26: =ROUNDUP(I26*6%,0) -> 639 | T26: =ROUND(SUM(J26:S26),2) -> 2463.82 | U26: =ROUND(H26*8%,2) -> 544.72 | V26: =ROUND(H26*2%,2) -> 136.18 | W26: =ROUND(H26*0.4%,2) -> 27.24 | AA26: =S26 -> 639 | AB26: =ROUND(SUM(U26:AA26),2) -> 1347.14 | AC26: =VLOOKUP(AM:AM,工资明细!E:AP,38,0) -> 6153.37 | AD26: =VLOOKUP(AM:AM,工资明细!E:AH,30,0) -> 6225.63 | AH26: =ROUND(G26+T26+AB26+AD26+AF26+AG26+AE26,2) -> 10631.59 | AI26: =ROUND(AH26*(1/(1-0.78%)-1),2) -> 83.58 | AJ26: =ROUND(SUM(AH26:AI26)*6%,2) -> 642.91 | AK26: =ROUND(SUM(AH26:AJ26),2) -> 11358.08 | AM26: 510104198710260016 | AN26: 成都市 | AO26: 成都合杰 | AP26: =U26 -> 544.72 | AQ26: =V26+Z26 -> 136.18 | AR26: =W26 -> 27.24 | AS26: =AA26 -> 639
A27: 19 | B27: 胡伟 | C27: MNCN00400 | D27: 202606 | E27: 43199 | G27: 595 | H27: 8994 | I27: 9958 | J27: =ROUND(H27*16%,2) -> 1439.04 | K27: =ROUND($H27*8.5%,2) -> 764.49 | L27: =ROUND($H27*0.5%,2) -> 44.97 | M27: =ROUND($H27*0.6%,2) -> 53.96 | O27: =ROUND(H27*1.5%,2) -> 134.91 | P27: =ROUND(H27*1.5%,2) -> 134.91 | S27: =ROUND(I27*5%,0) -> 498 | T27: =ROUND(SUM(J27:S27),2) -> 3070.28 | U27: =ROUND($H27*8%,2) -> 719.52 | V27: =ROUND($H27*2%,2) -> 179.88 | W27: =ROUND($H27*0.5%,2) -> 44.97 | Z27: 5 | AA27: =S27 -> 498 | AB27: =ROUND(SUM(U27:AA27),2) -> 1447.37 | AC27: =VLOOKUP(AM:AM,工资明细!E:AP,38,0) -> 4511.63 | AD27: =VLOOKUP(AM:AM,工资明细!E:AH,30,0) -> 4511.63 | AH27: =ROUND(G27+T27+AB27+AD27+AF27+AG27+AE27,2) -> 9624.28 | AI27: =ROUND(AH27*(1/(1-0.78%)-1),2) -> 75.66 | AJ27: =ROUND(SUM(AH27:AI27)*6%,2) -> 582 | AK27: =ROUND(SUM(AH27:AJ27),2) -> 10281.94 | AM27: 513029198606282471 | AN27: 重庆市 | AO27: 合杰区域分公司 | AP27: =U27 -> 719.52 | AQ27: =V27+Z27 -> 184.88 | AR27: =W27 -> 44.97 | AS27: =AA27 -> 498
A28: 20 | B28: 王李赫 | C28: MNCN00412 | D28: 202606 | E28: 43224 | G28: 595 | H28: 14912.07 | I28: 17105.25 | J28: =ROUND(H28*16%,2) -> 2385.93 | K28: =ROUND(H28*7%,2) -> 1043.84 | L28: =ROUND(H28*0.7%,2) -> 104.38 | M28: =ROUND(H28*0.32%,2) -> 47.72 | O28: 6.4 | P28: =ROUND(H28*1.5%,2) -> 223.68 | S28: =ROUND(I28*5%,0) -> 855 | T28: =ROUND(SUM(J28:S28),2) -> 4666.95 | U28: =ROUND(H28*8%,2) -> 1192.97 | V28: =ROUND(H28*2%,2) -> 298.24 | W28: =ROUND(H28*0.3%,2) -> 44.74 | Z28: 1.6 | AA28: =S28 -> 855 | AB28: =ROUND(SUM(U28:AA28),2) -> 2392.55 | AC28: =VLOOKUP(AM:AM,工资明细!E:AP,38,0) -> 10202.36 | AD28: =VLOOKUP(AM:AM,工资明细!E:AH,30,0) -> 10250.42 | AH28: =ROUND(G28+T28+AB28+AD28+AF28+AG28+AE28,2) -> 17904.92 | AI28: =ROUND(AH28*(1/(1-0.78%)-1),2) -> 140.76 | AJ28: =ROUND(SUM(AH28:AI28)*6%,2) -> 1082.74 | AK28: =ROUND(SUM(AH28:AJ28),2) -> 19128.42 | AM28: 610102198811072314 | AN28: 西安市 | AO28: 合杰区域分公司 | AP28: =U28 -> 1192.97 | AQ28: =V28+Z28 -> 299.84 | AR28: =W28 -> 44.74 | AS28: =AA28 -> 855
A29: 21 | B29: 王平 | C29: MNCN00424 | D29: 202606 | E29: 43244 | G29: 595 | H29: 9616.5 | I29: 11565.75 | J29: =ROUND(H29*16%,2) -> 1538.64 | K29: =ROUND(H29*7%,2) -> 673.16 | L29: =ROUND(H29*0.7%,2) -> 67.32 | M29: =ROUND(H29*0.32%,2) -> 30.77 | O29: 6.4 | P29: =ROUND(H29*1.5%,2) -> 144.25 | S29: =ROUND(I29*5%,0) -> 578 | T29: =ROUND(SUM(J29:S29),2) -> 3038.54 | U29: =ROUND(H29*8%,2) -> 769.32 | V29: =ROUND(H29*2%,2) -> 192.33 | W29: =ROUND(H29*0.3%,2) -> 28.85 | Z29: 1.6 | AA29: =S29 -> 578 | AB29: =ROUND(SUM(U29:AA29),2) -> 1570.1 | AC29: =VLOOKUP(AM:AM,工资明细!E:AP,38,0) -> 4914.25 | AD29: =VLOOKUP(AM:AM,工资明细!E:AH,30,0) -> 4960.16 | AH29: =ROUND(G29+T29+AB29+AD29+AF29+AG29+AE29,2) -> 10163.8 | AI29: =ROUND(AH29*(1/(1-0.78%)-1),2) -> 79.9 | AJ29: =ROUND(SUM(AH29:AI29)*6%,2) -> 614.62 | AK29: =ROUND(SUM(AH29:AJ29),2) -> 10858.32 | AM29: 610424199508080038 | AN29: 西安市 | AO29: 合杰区域分公司 | AP29: =U29 -> 769.32 | AQ29: =V29+Z29 -> 193.93 | AR29: =W29 -> 28.85 | AS29: =AA29 -> 578
A30: 22 | B30: 祝荣丹 | C30: MNCN00444 | D30: 202606 | E30: 43359 | G30: 595 | H30: 9436 | I30: 9436 | J30: =ROUND(H30*16%,2) -> 1509.76 | K30: =ROUND(H30*6.85%,2) -> 646.37 | L30: =ROUND(H30*0.8%,2) -> 75.49 | M30: =ROUND(H30*0.4%,2) -> 37.74 | P30: =ROUND(H30*1.5%,2) -> 141.54 | S30: =ROUND(I30*7%,0) -> 661 | T30: =ROUND(SUM(J30:S30),2) -> 3071.9 | U30: =ROUND(H30*8%,2) -> 754.88 | V30: =ROUND(H30*2%,2) -> 188.72 | W30: =ROUND(H30*0.2%,2) -> 18.87 | AA30: =S30 -> 661 | AB30: =ROUND(SUM(U30:AA30),2) -> 1623.47 | AC30: =VLOOKUP(AM:AM,工资明细!E:AP,38,0) -> 4449.13 | AD30: =VLOOKUP(AM:AM,工资明细!E:AH,30,0) -> 4449.13 | AH30: =ROUND(G30+T30+AB30+AD30+AF30+AG30+AE30,2) -> 9739.5 | AI30: =ROUND(AH30*(1/(1-0.78%)-1),2) -> 76.57 | AJ30: =ROUND(SUM(AH30:AI30)*6%,2) -> 588.96 | AK30: =ROUND(SUM(AH30:AJ30),2) -> 10405.03 | AM30: 440923199101235762 | AN30: 广州市 | AO30: 合杰区域分公司 | AP30: =U30 -> 754.88 | AQ30: =V30+Z30 -> 188.72 | AR30: =W30 -> 18.87 | AS30: =AA30 -> 661
A31: 23 | B31: 刘明杰 | C31: MNCN00447 | D31: 202606 | E31: 43360 | G31: 595 | H31: 17048 | I31: 18473 | J31: =ROUND($H31*16%,2) -> 2727.68 | K31: =ROUND($H31*8.5%,2) -> 1449.08 | L31: =ROUND($H31*0.5%,2) -> 85.24 | M31: =ROUND($H31*0.6%,2) -> 102.29 | O31: =ROUND(H31*1.5%,2) -> 255.72 | P31: =ROUND(H31*1.5%,2) -> 255.72 | S31: =ROUND(I31*5%,0) -> 924 | T31: =ROUND(SUM(J31:S31),2) -> 5799.73 | U31: =ROUND($H31*8%,2) -> 1363.84 | V31: =ROUND($H31*2%,2) -> 340.96 | W31: =ROUND($H31*0.5%,2) -> 85.24 | Z31: 5 | AA31: =S31 -> 924 | AB31: =ROUND(SUM(U31:AA31),2) -> 2719.04 | AC31: =VLOOKUP(AM:AM,工资明细!E:AP,38,0) -> 9565.04 | AD31: =VLOOKUP(AM:AM,工资明细!E:AH,30,0) -> 10374.38 | AH31: =ROUND(G31+T31+AB31+AD31+AF31+AG31+AE31,2) -> 19488.15 | AI31: =ROUND(AH31*(1/(1-0.78%)-1),2) -> 153.2 | AJ31: =ROUND(SUM(AH31:AI31)*6%,2) -> 1178.48 | AK31: =ROUND(SUM(AH31:AJ31),2) -> 20819.83 | AM31: 500108199010022613 | AN31: 重庆市 | AO31: 合杰区域分公司 | AP31: =U31 -> 1363.84 | AQ31: =V31+Z31 -> 345.96 | AR31: =W31 -> 85.24 | AS31: =AA31 -> 924
A32: 24 | B32: 王译 | C32: MNCN00448 | D32: 202606 | E32: 43360 | G32: 595 | H32: 5981 | I32: 7545 | J32: =ROUND($H32*16%,2) -> 956.96 | K32: =ROUND($H32*8.5%,2) -> 508.39 | L32: =ROUND($H32*0.5%,2) -> 29.91 | M32: =ROUND($H32*0.6%,2) -> 35.89 | O32: =ROUND(H32*1.5%,2) -> 89.72 | P32: =ROUND(H32*1.5%,2) -> 89.72 | S32: =ROUND(I32*5%,0) -> 377 | T32: =ROUND(SUM(J32:S32),2) -> 2087.59 | U32: =ROUND($H32*8%,2) -> 478.48 | V32: =ROUND($H32*2%,2) -> 119.62 | W32: =ROUND($H32*0.5%,2) -> 29.91 | Z32: 5 | AA32: =S32 -> 377 | AB32: =ROUND(SUM(U32:AA32),2) -> 1010.01 | AC32: =VLOOKUP(AM:AM,工资明细!E:AP,38,0) -> 3972.75 | AD32: =VLOOKUP(AM:AM,工资明细!E:AH,30,0) -> 3972.75 | AH32: =ROUND(G32+T32+AB32+AD32+AF32+AG32+AE32,2) -> 7665.35 | AI32: =ROUND(AH32*(1/(1-0.78%)-1),2) -> 60.26 | AJ32: =ROUND(SUM(AH32:AI32)*6%,2) -> 463.54 | AK32: =ROUND(SUM(AH32:AJ32),2) -> 8189.15 | AM32: 500109199008271924 | AN32: 重庆市 | AO32: 合杰区域分公司 | AP32: =U32 -> 478.48 | AQ32: =V32+Z32 -> 124.62 | AR32: =W32 -> 29.91 | AS32: =AA32 -> 377
A33: 25 | B33: 孙亮 | C33: MNCN00445 | D33: 202606 | E33: 43360 | G33: 595 | H33: 14540 | I33: 15170.08 | J33: =ROUND(H33*16%,2) -> 2326.4 | K33: =ROUND(H33*8%,2) -> 1163.2 | L33: =ROUND(H33*0.7%,2) -> 101.78 | M33: =ROUND(H33*0.16%,2) -> 23.26 | P33: =ROUND(H33*1.5%,2) -> 218.1 | S33: =ROUND(I33*5%,0) -> 759 | T33: =ROUND(SUM(J33:S33),2) -> 4591.74 | U33: =ROUND(H33*8%,2) -> 1163.2 | V33: =ROUND(H33*2%,2) -> 290.8 | W33: =ROUND(H33*0.3%,2) -> 43.62 | AA33: =S33 -> 759 | AB33: =ROUND(SUM(U33:AA33),2) -> 2256.62 | AC33: =VLOOKUP(AM:AM,工资明细!E:AP,38,0) -> 10665.99 | AD33: =VLOOKUP(AM:AM,工资明细!E:AH,30,0) -> 10705.76 | AH33: =ROUND(G33+T33+AB33+AD33+AF33+AG33+AE33,2) -> 18149.12 | AI33: =ROUND(AH33*(1/(1-0.78%)-1),2) -> 142.68 | AJ33: =ROUND(SUM(AH33:AI33)*6%,2) -> 1097.51 | AK33: =ROUND(SUM(AH33:AJ33),2) -> 19389.31 | AM33: 370205198604191016 | AN33: 青岛市 | AO33: 合杰区域分公司 | AP33: =U33 -> 1163.2 | AQ33: =V33+Z33 -> 290.8 | AR33: =W33 -> 43.62 | AS33: =AA33 -> 759
A34: 26 | B34: 胡蔷薇 | C34: MNCN00446 | D34: 202606 | E34: 43360 | G34: 595 | H34: 10007 | I34: 11152.91 | J34: =ROUND(H34*16%,2) -> 1601.12 | K34: =ROUND(H34*8%,2) -> 800.56 | L34: =ROUND(H34*0.7%,2) -> 70.05 | M34: =ROUND(H34*0.16%,2) -> 16.01 | P34: =ROUND(H34*1.5%,2) -> 150.11 | S34: =ROUND(I34*5%,0) -> 558 | T34: =ROUND(SUM(J34:S34),2) -> 3195.85 | U34: =ROUND(H34*8%,2) -> 800.56 | V34: =ROUND(H34*2%,2) -> 200.14 | W34: =ROUND(H34*0.3%,2) -> 30.02 | AA34: =S34 -> 558 | AB34: =ROUND(SUM(U34:AA34),2) -> 1588.72 | AC34: =VLOOKUP(AM:AM,工资明细!E:AP,38,0) -> 9198.87 | AD34: =VLOOKUP(AM:AM,工资明细!E:AH,30,0) -> 9198.87 | AH34: =ROUND(G34+T34+AB34+AD34+AF34+AG34+AE34,2) -> 14578.44 | AI34: =ROUND(AH34*(1/(1-0.78%)-1),2) -> 114.61 | AJ34: =ROUND(SUM(AH34:AI34)*6%,2) -> 881.58 | AK34: =ROUND(SUM(AH34:AJ34),2) -> 15574.63 | AM34: 420921198704155525 | AN34: 青岛市 | AO34: 合杰区域分公司 | AP34: =U34 -> 800.56 | AQ34: =V34+Z34 -> 200.14 | AR34: =W34 -> 30.02 | AS34: =AA34 -> 558
A35: 27 | B35: 沈鸿鹏 | C35: MNCN00450 | D35: 202606 | E35: 43372 | G35: 595 | H35: 10173 | I35: 10032.59 | J35: =ROUND(H35*16%,2) -> 1627.68 | K35: =ROUND(H35*8%,2) -> 813.84 | L35: =ROUND(H35*0.7%,2) -> 71.21 | M35: =ROUND(H35*0.16%,2) -> 16.28 | P35: =ROUND(H35*1.5%,2) -> 152.6 | S35: =ROUND(I35*5%,0) -> 502 | T35: =ROUND(SUM(J35:S35),2) -> 3183.61 | U35: =ROUND(H35*8%,2) -> 813.84 | V35: =ROUND(H35*2%,2) -> 203.46 | W35: =ROUND(H35*0.3%,2) -> 30.52 | AA35: =S35 -> 502 | AB35: =ROUND(SUM(U35:AA35),2) -> 1549.82 | AC35: =VLOOKUP(AM:AM,工资明细!E:AP,38,0) -> 5199.86 | AD35: =VLOOKUP(AM:AM,工资明细!E:AH,30,0) -> 5199.86 | AH35: =ROUND(G35+T35+AB35+AD35+AF35+AG35+AE35,2) -> 10528.29 | AI35: =ROUND(AH35*(1/(1-0.78%)-1),2) -> 82.77 | AJ35: =ROUND(SUM(AH35:AI35)*6%,2) -> 636.66 | AK35: =ROUND(SUM(AH35:AJ35),2) -> 11247.72 | AM35: 220284198807302313 | AN35: 青岛市 | AO35: 合杰区域分公司 | AP35: =U35 -> 813.84 | AQ35: =V35+Z35 -> 203.46 | AR35: =W35 -> 30.52 | AS35: =AA35 -> 502
A36: 28 | B36: 张洁 | C36: MNCN00452 | D36: 202606 | E36: 43382 | G36: 595 | H36: 14420 | I36: 13440 | J36: =ROUND($H36*16%,2) -> 2307.2 | K36: =ROUND($H36*7%,2) -> 1009.4 | L36: =ROUND($H36*0.5%,2) -> 72.1 | M36: =ROUND($H36*0.4%,2) -> 57.68 | N36: =ROUND($H36*0.8%,2) -> 115.36 | S36: =ROUND(I36*12%,0) -> 1613 | T36: =ROUND(SUM(J36:S36),2) -> 5174.74 | U36: =ROUND($H36*8%,2) -> 1153.6 | V36: =ROUND($H36*2%,2) -> 288.4 | W36: =ROUND($H36*0.5%,2) -> 72.1 | Z36: 10 | AA36: =S36 -> 1613 | AB36: =ROUND(SUM(U36:AA36),2) -> 3137.1 | AC36: =VLOOKUP(AM:AM,工资明细!E:AP,38,0) -> 6049.86 | AD36: =VLOOKUP(AM:AM,工资明细!E:AH,30,0) -> 6049.86 | AH36: =ROUND(G36+T36+AB36+AD36+AF36+AG36+AE36,2) -> 14956.7 | AI36: =ROUND(AH36*(1/(1-0.78%)-1),2) -> 117.58 | AJ36: =ROUND(SUM(AH36:AI36)*6%,2) -> 904.46 | AK36: =ROUND(SUM(AH36:AJ36),2) -> 15978.74 | AM36: 320106198205172442 | AN36: 南京市 | AO36: 上海合杰 | AP36: =U36 -> 1153.6 | AQ36: =V36+Z36 -> 298.4 | AR36: =W36 -> 72.1 | AS36: =AA36 -> 1613
A37: 29 | B37: 王广春 | C37: MNCN00459 | D37: 202606 | E37: 43524 | G37: 595 | H37: 15418 | I37: 16073 | J37: =ROUND($H37*16%,2) -> 2466.88 | K37: =ROUND($H37*7%,2) -> 1079.26 | L37: =ROUND($H37*0.5%,2) -> 77.09 | M37: =ROUND($H37*0.4%,2) -> 61.67 | N37: =ROUND($H37*0.8%,2) -> 123.34 | S37: =ROUND(I37*12%,0) -> 1929 | T37: =ROUND(SUM(J37:S37),2) -> 5737.24 | U37: =ROUND($H37*8%,2) -> 1233.44 | V37: =ROUND($H37*2%,2) -> 308.36 | W37: =ROUND($H37*0.5%,2) -> 77.09 | Z37: 10 | AA37: =S37 -> 1929 | AB37: =ROUND(SUM(U37:AA37),2) -> 3557.89 | AC37: =VLOOKUP(AM:AM,工资明细!E:AP,38,0) -> 21228.4 | AD37: =VLOOKUP(AM:AM,工资明细!E:AH,30,0) -> 21553.04 | AH37: =ROUND(G37+T37+AB37+AD37+AF37+AG37+AE37,2) -> 31443.17 | AI37: =ROUND(AH37*(1/(1-0.78%)-1),2) -> 247.18 | AJ37: =ROUND(SUM(AH37:AI37)*6%,2) -> 1901.42 | AK37: =ROUND(SUM(AH37:AJ37),2) -> 33591.77 | AM37: 320922199702083617 | AN37: 南京市 | AO37: 上海合杰 | AP37: =U37 -> 1233.44 | AQ37: =V37+Z37 -> 318.36 | AR37: =W37 -> 77.09 | AS37: =AA37 -> 1929
A38: 30 | B38: 王雪娇 | C38: MNCN00477 | D38: 202606 | E38: 43689 | G38: 595 | H38: 21253 | I38: 24921 | J38: =ROUND($H38*16%,2) -> 3400.48 | K38: =ROUND($H38*7%,2) -> 1487.71 | L38: =ROUND($H38*0.5%,2) -> 106.27 | M38: =ROUND($H38*1.1%,2) -> 233.78 | N38: =ROUND($H38*0.8%,2) -> 170.02 | S38: =ROUND(I38*8%,0) -> 1994 | T38: =ROUND(SUM(J38:S38),2) -> 7392.26 | U38: =ROUND($H38*8%,2) -> 1700.24 | V38: =ROUND($H38*2%,2) -> 425.06 | W38: =ROUND($H38*0.5%,2) -> 106.27 | Z38: 5 | AA38: =S38 -> 1994 | AB38: =ROUND(SUM(U38:AA38),2) -> 4230.57 | AC38: =VLOOKUP(AM:AM,工资明细!E:AP,38,0) -> 5065.42 | AD38: =VLOOKUP(AM:AM,工资明细!E:AH,30,0) -> 5198.29 | AH38: =ROUND(G38+T38+AB38+AD38+AF38+AG38+AE38,2) -> 17416.12 | AI38: =ROUND(AH38*(1/(1-0.78%)-1),2) -> 136.91 | AJ38: =ROUND(SUM(AH38:AI38)*6%,2) -> 1053.18 | AK38: =ROUND(SUM(AH38:AJ38),2) -> 18606.21 | AM38: 340823198402105888 | AN38: 张家港市 | AO38: 上海合杰 | AP38: =U38 -> 1700.24 | AQ38: =V38+Z38 -> 430.06 | AR38: =W38 -> 106.27 | AS38: =AA38 -> 1994
A39: 31 | B39: 赵徐 | C39: MNCN00478 | D39: 202606 | E39: 43690 | G39: 595 | H39: 24619 | I39: 26520 | J39: =ROUND($H39*16%,2) -> 3939.04 | K39: =ROUND($H39*7%,2) -> 1723.33 | L39: =ROUND($H39*0.5%,2) -> 123.1 | M39: =ROUND($H39*1.1%,2) -> 270.81 | N39: =ROUND($H39*0.8%,2) -> 196.95 | S39: =ROUND(I39*8%,0) -> 2122 | T39: =ROUND(SUM(J39:S39),2) -> 8375.23 | U39: =ROUND($H39*8%,2) -> 1969.52 | V39: =ROUND($H39*2%,2) -> 492.38 | W39: =ROUND($H39*0.5%,2) -> 123.1 | Z39: 5 | AA39: =S39 -> 2122 | AB39: =ROUND(SUM(U39:AA39),2) -> 4712 | AC39: =VLOOKUP(AM:AM,工资明细!E:AP,38,0) -> 5900.4 | AD39: =VLOOKUP(AM:AM,工资明细!E:AH,30,0) -> 6524 | AH39: =ROUND(G39+T39+AB39+AD39+AF39+AG39+AE39,2) -> 20206.23 | AI39: =ROUND(AH39*(1/(1-0.78%)-1),2) -> 158.85 | AJ39: =ROUND(SUM(AH39:AI39)*6%,2) -> 1221.9 | AK39: =ROUND(SUM(AH39:AJ39),2) -> 21586.98 | AM39: 340421198706282854 | AN39: 张家港市 | AO39: 上海合杰 | AP39: =U39 -> 1969.52 | AQ39: =V39+Z39 -> 497.38 | AR39: =W39 -> 123.1 | AS39: =AA39 -> 2122
A40: 32 | B40: 郭思玉 | C40: MNCN00479 | D40: 202606 | E40: 43697 | G40: 595 | H40: 11591.63 | I40: 11277.12 | J40: =ROUND(H40*16%,2) -> 1854.66 | K40: =ROUND(H40*7%,2) -> 811.41 | L40: =ROUND(H40*0.7%,2) -> 81.14 | M40: =ROUND(H40*0.32%,2) -> 37.09 | O40: 6.4 | P40: =ROUND(H40*1.5%,2) -> 173.87 | S40: =ROUND(I40*5%,0) -> 564 | T40: =ROUND(SUM(J40:S40),2) -> 3528.57 | U40: =ROUND(H40*8%,2) -> 927.33 | V40: =ROUND(H40*2%,2) -> 231.83 | W40: =ROUND(H40*0.3%,2) -> 34.77 | Z40: 1.6 | AA40: =S40 -> 564 | AB40: =ROUND(SUM(U40:AA40),2) -> 1759.53 | AC40: =VLOOKUP(AM:AM,工资明细!E:AP,38,0) -> 7511.03 | AD40: =VLOOKUP(AM:AM,工资明细!E:AH,30,0) -> 7643.11 | AH40: =ROUND(G40+T40+AB40+AD40+AF40+AG40+AE40,2) -> 13526.21 | AI40: =ROUND(AH40*(1/(1-0.78%)-1),2) -> 106.33 | AJ40: =ROUND(SUM(AH40:AI40)*6%,2) -> 817.95 | AK40: =ROUND(SUM(AH40:AJ40),2) -> 14450.49 | AM40: 622827199610250384 | AN40: 西安市 | AO40: 合杰区域分公司 | AP40: =U40 -> 927.33 | AQ40: =V40+Z40 -> 233.43 | AR40: =W40 -> 34.77 | AS40: =AA40 -> 564
A41: 33 | B41: 葛梦影 | C41: MNCN00480 | D41: 202606 | E41: 43697 | G41: 595 | H41: 7460 | I41: 6754.8 | J41: =ROUND($H41*16%,2) -> 1193.6 | K41: =ROUND(H41*9%,2) -> 671.4 | L41: =ROUND(H41*0.5%,2) -> 37.3 | M41: =ROUND(H41*0.32%,2) -> 23.87 | P41: =ROUND(H41*(1.5%*0.9),2) -> 100.71 | S41: =ROUND(I41*7%,0) -> 473 | T41: =ROUND(SUM(J41:S41),2) -> 2499.88 | U41: =ROUND(H41*8%,2) -> 596.8 | V41: =ROUND(H41*2%,2) -> 149.2 | W41: =ROUND(H41*0.5%,2) -> 37.3 | AA41: =ROUND(I41*7%,0) -> 473 | AB41: =ROUND(SUM(U41:AA41),2) -> 1256.3 | AC41: =VLOOKUP(AM:AM,工资明细!E:AP,38,0) -> 4736.77 | AD41: =VLOOKUP(AM:AM,工资明细!E:AH,30,0) -> 4743.7 | AH41: =ROUND(G41+T41+AB41+AD41+AF41+AG41+AE41,2) -> 9094.88 | AI41: =ROUND(AH41*(1/(1-0.78%)-1),2) -> 71.5 | AJ41: =ROUND(SUM(AH41:AI41)*6%,2) -> 549.98 | AK41: =ROUND(SUM(AH41:AJ41),2) -> 9716.36 | AM41: 320283199108137568 | AN41: 上海市 | AO41: 上海合杰 | AP41: =U41 -> 596.8 | AQ41: =V41+Z41 -> 149.2 | AR41: =W41 -> 37.3 | AS41: =AA41 -> 473
...

Sheet 工资明细
A1: 序号 | B1: 月份 | C1: 员工编码 | D1: 中文姓名 | E1: 身份证号码 | F1: 岗位 | G1: 工作地 | H1: 最低工资 | I1: 入职时间 | J1: 离职日期 | K1: 基本工资 | L1: 出勤工资调整 | M1: 职位津贴 | N1: 店员工龄津贴 | O1: 延时加班 | P1: 周末加班 | Q1: 节假日加班 | R1: 加班工资 | S1: 病假扣资 | T1: 事假扣资 | U1: 产假扣资 | V1: 月度销售提成 | W1: 绩效评估奖金 | X1: 税前调整 | Y1: 未休年假折算 | Z1: 公司垫付社保工资 | AA1: 公司承担税 | AB1: 最低工资标准 | AC1: 应发工资 | AD1: 个人养老 | AE1: 个人医疗 | AF1: 个人失业 | AG1: 个人公积金 | AH1: 税前工资 | AI1: 工资个税 | AJ1: 计税调整项 | AK1: 13薪奖金/年终奖 | AL1: 奖金个税 | AM1: 收入合计 | AN1: 离职补偿金 | AO1: 生育津贴/一次性伤残就业补助金 | AP1: 实发工资 | AQ1: 当年累计发放月数 | AR1: 当年累计收入 | AS1: 当年累计税 | AT1: 专项抵扣 | AU1: 备注
A2: 1 | B2: 202606 | C2: MNCN00246 | D2: 沈国伟 | E2: 330184198807080319 | F2: 高级销售顾问 | G2: 杭州 | H2: 2660 | I2: 42430 | K2: 5000 | N2: 1000 | O2: 0 | Q2: 16 | R2: =ROUND(K2/174*SUM(O2*1.5+P2*2+Q2*3),2) -> 1379.31 | V2: 2559.11 | AC2: =ROUND(SUM(SUM(K2:N2)+SUM(R2:AB2)),2) -> 9938.42 | AD2: 1359.83 | AE2: 339.96 | AF2: 84.99 | AG2: 1575 | AH2: =AC2-AD2-AE2-AF2-AG2 -> 6578.64 | AI2: =MAX(ROUND(MAX((AH2+AR2-5000*AQ2-AT2)*{0.03,0.1,0.2,0.25,0.3,0.35,0.45}-{0,2520,16920,31920,52920,85920,181920},0)-AS2,2),0) -> 0 | AL2: =ROUND(LOOKUP(MAX(0.0001,AK2/12),{0;6;24;50;70;110;160}*500+0.0001,5*MAX(0,AK2)*{0.6;2;4;5;6;7;9}%-10*{0;21;141;266;441;716;1516}),2) -> 0 | AM2: =AC2+AK2+AJ2 -> 9938.42 | AP2: =ROUND(AH2-AI2+AK2-AL2+AO2+AN2,2) -> 6578.64 | AQ2: 6 | AR2: 61678.95 | AS2: 491.4 | AT2: 42000 | AU2: 合杰区域分
A3: 2 | B3: 202606 | C3: MNCN00101 | D3: 傅禄杰 | E3: 310103198112094018 | F3: 高级销售顾问 | G3: 上海 | H3: 2740 | I3: 42430 | K3: 4600 | N3: 1000 | O3: 0 | Q3: 20 | R3: =ROUND(K3/174*SUM(O3*1.5+P3*2+Q3*3),2) -> 1586.21 | V3: 946.67 | AC3: =ROUND(SUM(SUM(K3:N3)+SUM(R3:AB3)),2) -> 8132.88 | AD3: 792.21 | AE3: 198.05 | AF3: 49.51 | AG3: 693 | AH3: =AC3-AD3-AE3-AF3-AG3 -> 6400.11 | AI3: =MAX(ROUND(MAX((AH3+AR3-5000*AQ3-AT3)*{0.03,0.1,0.2,0.25,0.3,0.35,0.45}-{0,2520,16920,31920,52920,85920,181920},0)-AS3,2),0) -> 93.99 | AL3: =ROUND(LOOKUP(MAX(0.0001,AK3/12),{0;6;24;50;70;110;160}*500+0.0001,5*MAX(0,AK3)*{0.6;2;4;5;6;7;9}%-10*{0;21;141;266;441;716;1516}),2) -> 0 | AM3: =AC3+AK3+AJ3 -> 8132.88 | AP3: =ROUND(AH3-AI3+AK3-AL3+AO3+AN3,2) -> 6306.12 | AQ3: 6 | AR3: 33002.48 | AS3: 188.09 | AT3: 0 | AU3: 上海合杰
A4: 3 | B4: 202606 | C4: MNCN00226 | D4: 韩英 | E4: 320123197712131022 | F4: 销售主管 | G4: 南京 | H4: 2660 | I4: 42430 | K4: 7300 | N4: 1000 | O4: 0 | Q4: 16 | R4: =ROUND(K4/174*SUM(O4*1.5+P4*2+Q4*3),2) -> 2013.79 | V4: 3582.89 | AC4: =ROUND(SUM(SUM(K4:N4)+SUM(R4:AB4)),2) -> 13896.68 | AD4: 1909.12 | AE4: 487.28 | AF4: 119.32 | AG4: 2604 | AH4: =AC4-AD4-AE4-AF4-AG4 -> 8776.96 | AI4: =MAX(ROUND(MAX((AH4+AR4-5000*AQ4-AT4)*{0.03,0.1,0.2,0.25,0.3,0.35,0.45}-{0,2520,16920,31920,52920,85920,181920},0)-AS4,2),0) -> 589.67 | AL4: =ROUND(LOOKUP(MAX(0.0001,AK4/12),{0;6;24;50;70;110;160}*500+0.0001,5*MAX(0,AK4)*{0.6;2;4;5;6;7;9}%-10*{0;21;141;266;441;716;1516}),2) -> 0 | AM4: =AC4+AK4+AJ4 -> 13896.68 | AP4: =ROUND(AH4-AI4+AK4-AL4+AO4+AN4,2) -> 8187.29 | AQ4: 6 | AR4: 83956.8 | AS4: 1363.71 | AT4: 18000 | AU4: 上海合杰
A5: 4 | B5: 202606 | C5: MNCN00163 | D5: 王金栋 | E5: 110223198702142714 | F5: 销售顾问 | G5: 北京 | H5: 2540 | I5: 42430 | K5: 3800 | N5: 1000 | O5: 0 | Q5: 12 | R5: =ROUND(K5/174*SUM(O5*1.5+P5*2+Q5*3),2) -> 786.21 | V5: 3374.34 | AB5: 185.99 | AC5: =ROUND(SUM(SUM(K5:N5)+SUM(R5:AB5)),2) -> 9146.54 | AD5: 2347.84 | AE5: 589.96 | AF5: 146.74 | AG5: 3522 | AH5: =AC5-AD5-AE5-AF5-AG5 -> 2540 | AI5: =MAX(ROUND(MAX((AH5+AR5-5000*AQ5-AT5)*{0.03,0.1,0.2,0.25,0.3,0.35,0.45}-{0,2520,16920,31920,52920,85920,181920},0)-AS5,2),0) -> 0 | AL5: =ROUND(LOOKUP(MAX(0.0001,AK5/12),{0;6;24;50;70;110;160}*500+0.0001,5*MAX(0,AK5)*{0.6;2;4;5;6;7;9}%-10*{0;21;141;266;441;716;1516}),2) -> 0 | AM5: =AC5+AK5+AJ5 -> 9146.54 | AP5: =ROUND(AH5-AI5+AK5-AL5+AO5+AN5,2) -> 2540 | AQ5: 6 | AR5: 50372.48 | AS5: 231.42 | AT5: 18000 | AU5: 北京合杰
A6: 5 | B6: 202606 | C6: MNCN00238 | D6: 徐乐 | E6: 110222198702056027 | F6: 高级销售顾问 | G6: 北京 | H6: 2540 | I6: 42430 | K6: 7300 | N6: 1000 | O6: 4 | Q6: 13 | R6: =ROUND(K6/174*SUM(O6*1.5+P6*2+Q6*3),2) -> 1887.93 | V6: 1999.29 | AC6: =ROUND(SUM(SUM(K6:N6)+SUM(R6:AB6)),2) -> 12187.22 | AD6: 2187.68 | AE6: 549.92 | AF6: 136.73 | AG6: 3282 | AH6: =AC6-AD6-AE6-AF6-AG6 -> 6030.89 | AI6: =MAX(ROUND(MAX((AH6+AR6-5000*AQ6-AT6)*{0.03,0.1,0.2,0.25,0.3,0.35,0.45}-{0,2520,16920,31920,52920,85920,181920},0)-AS6,2),0) -> 265.87 | AL6: =ROUND(LOOKUP(MAX(0.0001,AK6/12),{0;6;24;50;70;110;160}*500+0.0001,5*MAX(0,AK6)*{0.6;2;4;5;6;7;9}%-10*{0;21;141;266;441;716;1516}),2) -> 0 | AM6: =AC6+AK6+AJ6 -> 12187.22 | AP6: =ROUND(AH6-AI6+AK6-AL6+AO6+AN6,2) -> 5765.02 | AQ6: 6 | AR6: 60687.03 | AS6: 885.92 | AT6: 0 | AU6: 北京合杰
A7: 6 | B7: 202606 | C7: MNCN00263 | D7: 刘星全 | E7: 37292519890401691X | F7: 销售顾问 | G7: 上海 | H7: 2740 | I7: 42473 | K7: 3800 | N7: 1000 | O7: 7.5 | Q7: 11.5 | R7: =ROUND(K7/174*SUM(O7*1.5+P7*2+Q7*3),2) -> 999.14 | V7: 6080.83 | AC7: =ROUND(SUM(SUM(K7:N7)+SUM(R7:AB7)),2) -> 11879.97 | AD7: 1171.98 | AE7: 293 | AF7: 73.25 | AG7: 1025 | AH7: =AC7-AD7-AE7-AF7-AG7 -> 9316.74 | AI7: =MAX(ROUND(MAX((AH7+AR7-5000*AQ7-AT7)*{0.03,0.1,0.2,0.25,0.3,0.35,0.45}-{0,2520,16920,31920,52920,85920,181920},0)-AS7,2),0) -> 0 | AL7: =ROUND(LOOKUP(MAX(0.0001,AK7/12),{0;6;24;50;70;110;160}*500+0.0001,5*MAX(0,AK7)*{0.6;2;4;5;6;7;9}%-10*{0;21;141;266;441;716;1516}),2) -> 0 | AM7: =AC7+AK7+AJ7 -> 11879.97 | AP7: =ROUND(AH7-AI7+AK7-AL7+AO7+AN7,2) -> 9316.74 | AQ7: 6 | AR7: 42215.24 | AS7: 192.23 | AT7: 27000 | AU7: 上海合杰
A8: 7 | B8: 202606 | C8: MNCN00281 | D8: 周华荣 | E8: 420822198801105563 | F8: 销售顾问 | G8: 天津 | H8: 2510 | I8: 42552 | K8: 4000 | N8: 900 | O8: 0 | Q8: 15.5 | R8: =ROUND(K8/174*SUM(O8*1.5+P8*2+Q8*3),2) -> 1068.97 | V8: 1254.9 | AC8: =ROUND(SUM(SUM(K8:N8)+SUM(R8:AB8)),2) -> 7223.87 | AD8: 597.12 | AE8: 170.28 | AF8: 37.32 | AG8: 873 | AH8: =AC8-AD8-AE8-AF8-AG8 -> 5546.15 | AI8: =MAX(ROUND(MAX((AH8+AR8-5000*AQ8-AT8)*{0.03,0.1,0.2,0.25,0.3,0.35,0.45}-{0,2520,16920,31920,52920,85920,181920},0)-AS8,2),0) -> 0 | AL8: =ROUND(LOOKUP(MAX(0.0001,AK8/12),{0;6;24;50;70;110;160}*500+0.0001,5*MAX(0,AK8)*{0.6;2;4;5;6;7;9}%-10*{0;21;141;266;441;716;1516}),2) -> 0 | AM8: =AC8+AK8+AJ8 -> 7223.87 | AP8: =ROUND(AH8-AI8+AK8-AL8+AO8+AN8,2) -> 5546.15 | AQ8: 6 | AR8: 25771.34 | AS8: 47.01 | AT8: 0 | AU8: 合杰区域分
A9: 8 | B9: 202606 | C9: MNCN00300 | D9: 李爱芳 | E9: 320981197710083482 | F9: 销售顾问 | G9: 苏州 | H9: 2660 | I9: 42721 | K9: 3600 | N9: 900 | O9: 0 | Q9: 20 | R9: =ROUND(K9/174*SUM(O9*1.5+P9*2+Q9*3),2) -> 1241.38 | V9: 3447.46 | W9: 1500 | AC9: =ROUND(SUM(SUM(K9:N9)+SUM(R9:AB9)),2) -> 10688.84 | AD9: 759.04 | AE9: 194.76 | AF9: 47.44 | AG9: 576.29 | AH9: =AC9-AD9-AE9-AF9-AG9 -> 9111.31 | AI9: =MAX(ROUND(MAX((AH9+AR9-5000*AQ9-AT9)*{0.03,0.1,0.2,0.25,0.3,0.35,0.45}-{0,2520,16920,31920,52920,85920,181920},0)-AS9,2),0) -> 141.75 | AL9: =ROUND(LOOKUP(MAX(0.0001,AK9/12),{0;6;24;50;70;110;160}*500+0.0001,5*MAX(0,AK9)*{0.6;2;4;5;6;7;9}%-10*{0;21;141;266;441;716;1516}),2) -> 0 | AM9: =AC9+AK9+AJ9 -> 10688.84 | AP9: =ROUND(AH9-AI9+AK9-AL9+AO9+AN9,2) -> 8969.56 | AQ9: 6 | AR9: 33121.89 | AS9: 225.25 | AT9: 0 | AU9: 上海合杰
A10: 9 | B10: 202606 | C10: MNCN00355 | D10: 程琪 | E10: 42010219880908082X | F10: 高级销售顾问 | G10: 武汉 | H10: 2400 | I10: 42963 | K10: 5000 | N10: 800 | O10: 0 | Q10: 11.5 | R10: =ROUND(K10/174*SUM(O10*1.5+P10*2+Q10*3),2) -> 991.38 | V10: 3208.9 | AC10: =ROUND(SUM(SUM(K10:N10)+SUM(R10:AB10)),2) -> 10000.28 | AD10: 933.28 | AE10: 240.32 | AF10: 35 | AG10: 933.29 | AH10: =AC10-AD10-AE10-AF10-AG10 -> 7858.39 | AI10: =MAX(ROUND(MAX((AH10+AR10-5000*AQ10-AT10)*{0.03,0.1,0.2,0.25,0.3,0.35,0.45}-{0,2520,16920,31920,52920,85920,181920},0)-AS10,2),0) -> 140.26 | AL10: =ROUND(LOOKUP(MAX(0.0001,AK10/12),{0;6;24;50;70;110;160}*500+0.0001,5*MAX(0,AK10)*{0.6;2;4;5;6;7;9}%-10*{0;21;141;266;441;716;1516}),2) -> 0 | AM10: =AC10+AK10+AJ10 -> 10000.28 | AP10: =ROUND(AH10-AI10+AK10-AL10+AO10+AN10,2) -> 7718.13 | AQ10: 6 | AR10: 29504.24 | AS10: 80.62 | AT10: 0 | AU10: 合杰区域分
A11: 10 | B11: 202606 | C11: MNCN00369 | D11: 秦懿 | E11: 310105198108060045 | F11: 高级销售顾问 | G11: 上海 | H11: 2740 | I11: 43017 | K11: 4600 | N11: 800 | O11: 11 | Q11: 11 | R11: =ROUND(K11/174*SUM(O11*1.5+P11*2+Q11*3),2) -> 1308.62 | V11: 385.9 | AC11: =ROUND(SUM(SUM(K11:N11)+SUM(R11:AB11)),2) -> 7094.52 | AD11: 784.25 | AE11: 196.06 | AF11: 49.02 | AG11: 686 | AH11: =AC11-AD11-AE11-AF11-AG11 -> 5379.19 | AI11: =MAX(ROUND(MAX((AH11+AR11-5000*AQ11-AT11)*{0.03,0.1,0.2,0.25,0.3,0.35,0.45}-{0,2520,16920,31920,52920,85920,181920},0)-AS11,2),0) -> 0 | AL11: =ROUND(LOOKUP(MAX(0.0001,AK11/12),{0;6;24;50;70;110;160}*500+0.0001,5*MAX(0,AK11)*{0.6;2;4;5;6;7;9}%-10*{0;21;141;266;441;716;1516}),2) -> 0 | AM11: =AC11+AK11+AJ11 -> 7094.52 | AP11: =ROUND(AH11-AI11+AK11-AL11+AO11+AN11,2) -> 5379.19 | AQ11: 6 | AR11: 38053.44 | AS11: 276.67 | AT11: 18000 | AU11: 上海合杰
A12: 11 | B12: 202606 | C12: MNCN00381 | D12: 贾锐 | E12: 510104198710260016 | F12: 销售顾问 | G12: 成都 | H12: 2330 | I12: 43103 | K12: 3600 | N12: 800 | O12: 8 | Q12: 16 | R12: =ROUND(K12/174*SUM(O12*1.5+P12*2+Q12*3),2) -> 1241.38 | V12: 718.53 | W12: 1500 | AC12: =ROUND(SUM(SUM(K12:N12)+SUM(R12:AB12)),2) -> 7859.91 | AD12: 765.6 | AE12: 191.4 | AF12: 38.28 | AG12: 639 | AH12: =AC12-AD12-AE12-AF12-AG12 -> 6225.63 | AI12: =MAX(ROUND(MAX((AH12+AR12-5000*AQ12-AT12)*{0.03,0.1,0.2,0.25,0.3,0.35,0.45}-{0,2520,16920,31920,52920,85920,181920},0)-AS12,2),0) -> 72.26 | AL12: =ROUND(LOOKUP(MAX(0.0001,AK12/12),{0;6;24;50;70;110;160}*500+0.0001,5*MAX(0,AK12)*{0.6;2;4;5;6;7;9}%-10*{0;21;141;266;441;716;1516}),2) -> 0 | AM12: =AC12+AK12+AJ12 -> 7859.91 | AP12: =ROUND(AH12-AI12+AK12-AL12+AO12+AN12,2) -> 6153.37 | AQ12: 6 | AR12: 31788.12 | AS12: 168.15 | AT12: 0 | AU12: 成都合杰
A13: 12 | B13: 202606 | C13: MNCN00390 | D13: 周之绮 | E13: 310107198302217221 | F13: 销售顾问 | G13: 上海 | H13: 2740 | I13: 43136 | K13: 3800 | N13: 800 | O13: 6.5 | Q13: 11.5 | R13: =ROUND(K13/174*SUM(O13*1.5+P13*2+Q13*3),2) -> 966.38 | V13: 11809.55 | AC13: =ROUND(SUM(SUM(K13:N13)+SUM(R13:AB13)),2) -> 17375.93 | AD13: 1405.78 | AE13: 351.45 | AF13: 87.86 | AG13: 1230 | AH13: =AC13-AD13-AE13-AF13-AG13 -> 14300.84 | AI13: =MAX(ROUND(MAX((AH13+AR13-5000*AQ13-AT13)*{0.03,0.1,0.2,0.25,0.3,0.35,0.45}-{0,2520,16920,31920,52920,85920,181920},0)-AS13,2),0) -> 6.96 | AL13: =ROUND(LOOKUP(MAX(0.0001,AK13/12),{0;6;24;50;70;110;160}*500+0.0001,5*MAX(0,AK13)*{0.6;2;4;5;6;7;9}%-10*{0;21;141;266;441;716;1516}),2) -> 0 | AM13: =AC13+AK13+AJ13 -> 17375.93 | AP13: =ROUND(AH13-AI13+AK13-AL13+AO13+AN13,2) -> 14293.88 | AQ13: 6 | AR13: 48857.89 | AS13: 447.8 | AT13: 18000 | AU13: 上海合杰
A14: 13 | B14: 202606 | C14: MNCN00391 | D14: 卢晓香 | E14: 422324198009156823 | F14: 高级销售顾问 | G14: 上海 | H14: 2740 | I14: 43138 | K14: 4600 | N14: 800 | O14: 0 | Q14: 10 | R14: =ROUND(K14/174*SUM(O14*1.5+P14*2+Q14*3),2) -> 793.1 | V14: 1682.67 | AC14: =ROUND(SUM(SUM(K14:N14)+SUM(R14:AB14)),2) -> 7875.77 | AD14: 893.39 | AE14: 223.35 | AF14: 55.84 | AG14: 782 | AH14: =AC14-AD14-AE14-AF14-AG14 -> 5921.19 | AI14: =MAX(ROUND(MAX((AH14+AR14-5000*AQ14-AT14)*{0.03,0.1,0.2,0.25,0.3,0.35,0.45}-{0,2520,16920,31920,52920,85920,181920},0)-AS14,2),0) -> 0 | AL14: =ROUND(LOOKUP(MAX(0.0001,AK14/12),{0;6;24;50;70;110;160}*500+0.0001,5*MAX(0,AK14)*{0.6;2;4;5;6;7;9}%-10*{0;21;141;266;441;716;1516}),2) -> 0 | AM14: =AC14+AK14+AJ14 -> 7875.77 | AP14: =ROUND(AH14-AI14+AK14-AL14+AO14+AN14,2) -> 5921.19 | AQ14: 6 | AR14: 37345.62 | AS14: 115.66 | AT14: 15000 | AU14: 上海合杰
A15: 14 | B15: 202606 | C15: MNCN00399 | D15: 李旻天 | E15: 310107198503120944 | F15: 资深销售主管 | G15: 上海 | H15: 2740 | I15: 43189 | K15: 7800 | N15: 800 | O15: 0 | Q15: 9 | R15: =ROUND(K15/174*SUM(O15*1.5+P15*2+Q15*3),2) -> 1210.34 | V15: 4936.8 | AC15: =ROUND(SUM(SUM(K15:N15)+SUM(R15:AB15)),2) -> 14747.14 | AD15: 1288.96 | AE15: 322.24 | AF15: 80.56 | AG15: 1128 | AH15: =AC15-AD15-AE15-AF15-AG15 -> 11927.38 | AI15: =MAX(ROUND(MAX((AH15+AR15-5000*AQ15-AT15)*{0.03,0.1,0.2,0.25,0.3,0.35,0.45}-{0,2520,16920,31920,52920,85920,181920},0)-AS15,2),0) -> 269.5 | AL15: =ROUND(LOOKUP(MAX(0.0001,AK15/12),{0;6;24;50;70;110;160}*500+0.0001,5*MAX(0,AK15)*{0.6;2;4;5;6;7;9}%-10*{0;21;141;266;441;716;1516}),2) -> 0 | AM15: =AC15+AK15+AJ15 -> 14747.14 | AP15: =ROUND(AH15-AI15+AK15-AL15+AO15+AN15,2) -> 11657.88 | AQ15: 6 | AR15: 73031.01 | AS15: 906.34 | AT15: 18000 | AU15: 上海合杰
A16: 15 | B16: 202606 | C16: MNCN00400 | D16: 胡伟 | E16: 513029198606282471 | F16: 销售顾问 | G16: 重庆 | H16: 2330 | I16: 43199 | K16: 4000 | N16: 800 | O16: 0 | Q16: 11 | R16: =ROUND(K16/174*SUM(O16*1.5+P16*2+Q16*3),2) -> 758.62 | V16: 400.38 | AC16: =ROUND(SUM(SUM(K16:N16)+SUM(R16:AB16)),2) -> 5959 | AD16: 719.52 | AE16: 184.88 | AF16: 44.97 | AG16: 498 | AH16: =AC16-AD16-AE16-AF16-AG16 -> 4511.63 | AI16: =MAX(ROUND(MAX((AH16+AR16-5000*AQ16-AT16)*{0.03,0.1,0.2,0.25,0.3,0.35,0.45}-{0,2520,16920,31920,52920,85920,181920},0)-AS16,2),0) -> 0 | AL16: =ROUND(LOOKUP(MAX(0.0001,AK16/12),{0;6;24;50;70;110;160}*500+0.0001,5*MAX(0,AK16)*{0.6;2;4;5;6;7;9}%-10*{0;21;141;266;441;716;1516}),2) -> 0 | AM16: =AC16+AK16+AJ16 -> 5959 | AP16: =ROUND(AH16-AI16+AK16-AL16+AO16+AN16,2) -> 4511.63 | AQ16: 6 | AR16: 34298.4 | AS16: 277.93 | AT16: 27000 | AU16: 合杰区域分
A17: 16 | B17: 202606 | C17: MNCN00412 | D17: 王李赫 | E17: 610102198811072314 | F17: 销售主管 | G17: 西安 | H17: 2376 | I17: 43224 | K17: 7800 | N17: 800 | O17: 0 | Q17: 0 | R17: =ROUND(K17/174*SUM(O17*1.5+P17*2+Q17*3),2) -> 0 | V17: 4042.97 | AC17: =ROUND(SUM(SUM(K17:N17)+SUM(R17:AB17)),2) -> 12642.97 | AD17: 1192.97 | AE17: 299.84 | AF17: 44.74 | AG17: 855 | AH17: =AC17-AD17-AE17-AF17-AG17 -> 10250.42 | AI17: =MAX(ROUND(MAX((AH17+AR17-5000*AQ17-AT17)*{0.03,0.1,0.2,0.25,0.3,0.35,0.45}-{0,2520,16920,31920,52920,85920,181920},0)-AS17,2),0) -> 48.06 | AL17: =ROUND(LOOKUP(MAX(0.0001,AK17/12),{0;6;24;50;70;110;160}*500+0.0001,5*MAX(0,AK17)*{0.6;2;4;5;6;7;9}%-10*{0;21;141;266;441;716;1516}),2) -> 0 | AM17: =AC17+AK17+AJ17 -> 12642.97 | AP17: =ROUND(AH17-AI17+AK17-AL17+AO17+AN17,2) -> 10202.36 | AQ17: 6 | AR17: 58109.85 | AS17: 22.75 | AT17: 36000 | AU17: 合杰区域分
A18: 17 | B18: 202606 | C18: MNCN00414 | D18: 陆立琴 | E18: 320924198001065721 | F18: 销售顾问 | G18: 上海 | H18: 2740 | I18: 43236 | K18: 3800 | N18: 800 | O18: 3 | Q18: 11 | R18: =ROUND(K18/174*SUM(O18*1.5+P18*2+Q18*3),2) -> 818.97 | V18: 1398.34 | AC18: =ROUND(SUM(SUM(K18:N18)+SUM(R18:AB18)),2) -> 6817.31 | AD18: 596.8 | AE18: 149.2 | AF18: 37.3 | AG18: 518 | AH18: =AC18-AD18-AE18-AF18-AG18 -> 5516.01 | AI18: =MAX(ROUND(MAX((AH18+AR18-5000*AQ18-AT18)*{0.03,0.1,0.2,0.25,0.3,0.35,0.45}-{0,2520,16920,31920,52920,85920,181920},0)-AS18,2),0) -> 0 | AL18: =ROUND(LOOKUP(MAX(0.0001,AK18/12),{0;6;24;50;70;110;160}*500+0.0001,5*MAX(0,AK18)*{0.6;2;4;5;6;7;9}%-10*{0;21;141;266;441;716;1516}),2) -> 0 | AM18: =AC18+AK18+AJ18 -> 6817.31 | AP18: =ROUND(AH18-AI18+AK18-AL18+AO18+AN18,2) -> 5516.01 | AQ18: 6 | AR18: 28188.33 | AS18: 184.52 | AT18: 0 | AU18: 上海合杰
A19: 18 | B19: 202606 | C19: MNCN00424 | D19: 王平 | E19: 610424199508080038 | F19: 销售顾问 | G19: 西安 | H19: 2376 | I19: 43244 | K19: 4000 | N19: 800 | O19: 0 | Q19: 0 | R19: =ROUND(K19/174*SUM(O19*1.5+P19*2+Q19*3),2) -> 0 | V19: 1730.26 | AC19: =ROUND(SUM(SUM(K19:N19)+SUM(R19:AB19)),2) -> 6530.26 | AD19: 769.32 | AE19: 193.93 | AF19: 28.85 | AG19: 578 | AH19: =AC19-AD19-AE19-AF19-AG19 -> 4960.16 | AI19: =MAX(ROUND(MAX((AH19+AR19-5000*AQ19-AT19)*{0.03,0.1,0.2,0.25,0.3,0.35,0.45}-{0,2520,16920,31920,52920,85920,181920},0)-AS19,2),0) -> 45.91 | AL19: =ROUND(LOOKUP(MAX(0.0001,AK19/12),{0;6;24;50;70;110;160}*500+0.0001,5*MAX(0,AK19)*{0.6;2;4;5;6;7;9}%-10*{0;21;141;266;441;716;1516}),2) -> 0 | AM19: =AC19+AK19+AJ19 -> 6530.26 | AP19: =ROUND(AH19-AI19+AK19-AL19+AO19+AN19,2) -> 4914.25 | AQ19: 6 | AR19: 32518.8 | AS19: 178.46 | AT19: 0 | AU19: 合杰区域分
A20: 19 | B20: 202606 | C20: MNCN00444 | D20: 祝荣丹 | E20: 440923199101235762 | F20: 销售顾问 | G20: 广州 | H20: 2500 | I20: 43359 | K20: 4200 | N20: 700 | O20: 0 | Q20: 16 | R20: =ROUND(K20/174*SUM(O20*1.5+P20*2+Q20*3),2) -> 1158.62 | V20: 13.98 | AC20: =ROUND(SUM(SUM(K20:N20)+SUM(R20:AB20)),2) -> 6072.6 | AD20: 754.88 | AE20: 188.72 | AF20: 18.87 | AG20: 661 | AH20: =AC20-AD20-AE20-AF20-AG20 -> 4449.13 | AI20: =MAX(ROUND(MAX((AH20+AR20-5000*AQ20-AT20)*{0.03,0.1,0.2,0.25,0.3,0.35,0.45}-{0,2520,16920,31920,52920,85920,181920},0)-AS20,2),0) -> 0 | AL20: =ROUND(LOOKUP(MAX(0.0001,AK20/12),{0;6;24;50;70;110;160}*500+0.0001,5*MAX(0,AK20)*{0.6;2;4;5;6;7;9}%-10*{0;21;141;266;441;716;1516}),2) -> 0 | AM20: =AC20+AK20+AJ20 -> 6072.6 | AP20: =ROUND(AH20-AI20+AK20-AL20+AO20+AN20,2) -> 4449.13 | AQ20: 6 | AR20: 35228.93 | AS20: 314.67 | AT20: 0 | AU20: 合杰区域分
A21: 20 | B21: 202606 | C21: MNCN00447 | D21: 刘明杰 | E21: 500108199010022613 | F21: 资深销售主管 | G21: 重庆 | H21: 2330 | I21: 43360 | K21: 7900 | N21: 700 | O21: 33 | Q21: 16 | R21: =ROUND(K21/174*SUM(O21*1.5+P21*2+Q21*3),2) -> 4426.72 | V21: 66.7 | AC21: =ROUND(SUM(SUM(K21:N21)+SUM(R21:AB21)),2) -> 13093.42 | AD21: 1363.84 | AE21: 345.96 | AF21: 85.24 | AG21: 924 | AH21: =AC21-AD21-AE21-AF21-AG21 -> 10374.38 | AI21: =MAX(ROUND(MAX((AH21+AR21-5000*AQ21-AT21)*{0.03,0.1,0.2,0.25,0.3,0.35,0.45}-{0,2520,16920,31920,52920,85920,181920},0)-AS21,2),0) -> 809.34 | AL21: =ROUND(LOOKUP(MAX(0.0001,AK21/12),{0;6;24;50;70;110;160}*500+0.0001,5*MAX(0,AK21)*{0.6;2;4;5;6;7;9}%-10*{0;21;141;266;441;716;1516}),2) -> 0 | AM21: =AC21+AK21+AJ21 -> 13093.42 | AP21: =ROUND(AH21-AI21+AK21-AL21+AO21+AN21,2) -> 9565.04 | AQ21: 6 | AR21: 65262.66 | AS21: 1234.36 | AT21: 0 | AU21: 合杰区域分
A22: 21 | B22: 202606 | C22: MNCN00448 | D22: 王译 | E22: 500109199008271924 | F22: 销售顾问 | G22: 重庆 | H22: 2330 | I22: 43360 | K22: 3600 | N22: 700 | O22: 0 | Q22: 11 | R22: =ROUND(K22/174*SUM(O22*1.5+P22*2+Q22*3),2) -> 682.76 | AC22: =ROUND(SUM(SUM(K22:N22)+SUM(R22:AB22)),2) -> 4982.76 | AD22: 478.48 | AE22: 124.62 | AF22: 29.91 | AG22: 377 | AH22: =AC22-AD22-AE22-AF22-AG22 -> 3972.75 | AI22: =MAX(ROUND(MAX((AH22+AR22-5000*AQ22-AT22)*{0.03,0.1,0.2,0.25,0.3,0.35,0.45}-{0,2520,16920,31920,52920,85920,181920},0)-AS22,2),0) -> 0 | AL22: =ROUND(LOOKUP(MAX(0.0001,AK22/12),{0;6;24;50;70;110;160}*500+0.0001,5*MAX(0,AK22)*{0.6;2;4;5;6;7;9}%-10*{0;21;141;266;441;716;1516}),2) -> 0 | AM22: =AC22+AK22+AJ22 -> 4982.76 | AP22: =ROUND(AH22-AI22+AK22-AL22+AO22+AN22,2) -> 3972.75 | AQ22: 6 | AR22: 23913.74 | AS22: 84.65 | AT22: 0 | AU22: 合杰区域分
A23: 22 | B23: 202606 | C23: MNCN00445 | D23: 孙亮 | E23: 370205198604191016 | F23: 资深销售主管 | G23: 青岛 | H23: 2400 | I23: 43360 | K23: 8800 | N23: 700 | O23: 4 | Q23: 13 | R23: =ROUND(K23/174*SUM(O23*1.5+P23*2+Q23*3),2) -> 2275.86 | V23: 1186.52 | AC23: =ROUND(SUM(SUM(K23:N23)+SUM(R23:AB23)),2) -> 12962.38 | AD23: 1163.2 | AE23: 290.8 | AF23: 43.62 | AG23: 759 | AH23: =AC23-AD23-AE23-AF23-AG23 -> 10705.76 | AI23: =MAX(ROUND(MAX((AH23+AR23-5000*AQ23-AT23)*{0.03,0.1,0.2,0.25,0.3,0.35,0.45}-{0,2520,16920,31920,52920,85920,181920},0)-AS23,2),0) -> 39.77 | AL23: =ROUND(LOOKUP(MAX(0.0001,AK23/12),{0;6;24;50;70;110;160}*500+0.0001,5*MAX(0,AK23)*{0.6;2;4;5;6;7;9}%-10*{0;21;141;266;441;716;1516}),2) -> 0 | AM23: =AC23+AK23+AJ23 -> 12962.38 | AP23: =ROUND(AH23-AI23+AK23-AL23+AO23+AN23,2) -> 10665.99 | AQ23: 6 | AR23: 61445.77 | AS23: 324.78 | AT23: 30000 | AU23: 合杰区域分
A24: 23 | B24: 202606 | C24: MNCN00446 | D24: 胡蔷薇 | E24: 420921198704155525 | F24: 高级销售顾问 | G24: 青岛 | H24: 2400 | I24: 43360 | K24: 4400 | N24: 700 | O24: 0 | Q24: 13 | R24: =ROUND(K24/174*SUM(O24*1.5+P24*2+Q24*3),2) -> 986.21 | V24: 4701.38 | AC24: =ROUND(SUM(SUM(K24:N24)+SUM(R24:AB24)),2) -> 10787.59 | AD24: 800.56 | AE24: 200.14 | AF24: 30.02 | AG24: 558 | AH24: =AC24-AD24-AE24-AF24-AG24 -> 9198.87 | AI24: =MAX(ROUND(MAX((AH24+AR24-5000*AQ24-AT24)*{0.03,0.1,0.2,0.25,0.3,0.35,0.45}-{0,2520,16920,31920,52920,85920,181920},0)-AS24,2),0) -> 0 | AL24: =ROUND(LOOKUP(MAX(0.0001,AK24/12),{0;6;24;50;70;110;160}*500+0.0001,5*MAX(0,AK24)*{0.6;2;4;5;6;7;9}%-10*{0;21;141;266;441;716;1516}),2) -> 0 | AM24: =AC24+AK24+AJ24 -> 10787.59 | AP24: =ROUND(AH24-AI24+AK24-AL24+AO24+AN24,2) -> 9198.87 | AQ24: 6 | AR24: 40918.77 | AS24: 172.26 | AT24: 15000 | AU24: 合杰区域分
A25: 24 | B25: 202606 | C25: MNCN00450 | D25: 沈鸿鹏 | E25: 220284198807302313 | F25: 销售顾问 | G25: 青岛 | H25: 2400 | I25: 43372 | K25: 4000 | N25: 700 | O25: 0 | Q25: 13 | R25: =ROUND(K25/174*SUM(O25*1.5+P25*2+Q25*3),2) -> 896.55 | V25: 1153.13 | AC25: =ROUND(SUM(SUM(K25:N25)+SUM(R25:AB25)),2) -> 6749.68 | AD25: 813.84 | AE25: 203.46 | AF25: 30.52 | AG25: 502 | AH25: =AC25-AD25-AE25-AF25-AG25 -> 5199.86 | AI25: =MAX(ROUND(MAX((AH25+AR25-5000*AQ25-AT25)*{0.03,0.1,0.2,0.25,0.3,0.35,0.45}-{0,2520,16920,31920,52920,85920,181920},0)-AS25,2),0) -> 0 | AL25: =ROUND(LOOKUP(MAX(0.0001,AK25/12),{0;6;24;50;70;110;160}*500+0.0001,5*MAX(0,AK25)*{0.6;2;4;5;6;7;9}%-10*{0;21;141;266;441;716;1516}),2) -> 0 | AM25: =AC25+AK25+AJ25 -> 6749.68 | AP25: =ROUND(AH25-AI25+AK25-AL25+AO25+AN25,2) -> 5199.86 | AQ25: 6 | AR25: 34362.27 | AS25: 94.55 | AT25: 18000 | AU25: 合杰区域分
A26: 25 | B26: 202606 | C26: MNCN00452 | D26: 张洁 | E26: 320106198205172442 | F26: 销售顾问 | G26: 南京 | H26: 2660 | I26: 43382 | K26: 3600 | N26: 700 | O26: 0 | Q26: 8.5 | R26: =ROUND(K26/174*SUM(O26*1.5+P26*2+Q26*3),2) -> 527.59 | V26: 4359.37 | AC26: =ROUND(SUM(SUM(K26:N26)+SUM(R26:AB26)),2) -> 9186.96 | AD26: 1153.6 | AE26: 298.4 | AF26: 72.1 | AG26: 1613 | AH26: =AC26-AD26-AE26-AF26-AG26 -> 6049.86 | AI26: =MAX(ROUND(MAX((AH26+AR26-5000*AQ26-AT26)*{0.03,0.1,0.2,0.25,0.3,0.35,0.45}-{0,2520,16920,31920,52920,85920,181920},0)-AS26,2),0) -> 0 | AL26: =ROUND(LOOKUP(MAX(0.0001,AK26/12),{0;6;24;50;70;110;160}*500+0.0001,5*MAX(0,AK26)*{0.6;2;4;5;6;7;9}%-10*{0;21;141;266;441;716;1516}),2) -> 0 | AM26: =AC26+AK26+AJ26 -> 9186.96 | AP26: =ROUND(AH26-AI26+AK26-AL26+AO26+AN26,2) -> 6049.86 | AQ26: 6 | AR26: 43757.2 | AS26: 413.88 | AT26: 21000 | AU26: 上海合杰
A27: 26 | B27: 202606 | C27: MNCN00459 | D27: 王广春 | E27: 320922199702083617 | F27: 销售顾问 | G27: 南京 | H27: 2660 | I27: 43524 | K27: 3600 | N27: 700 | O27: 0 | Q27: 16.5 | R27: =ROUND(K27/174*SUM(O27*1.5+P27*2+Q27*3),2) -> 1024.14 | V27: 19786.79 | AC27: =ROUND(SUM(SUM(K27:N27)+SUM(R27:AB27)),2) -> 25110.93 | AD27: 1233.44 | AE27: 318.36 | AF27: 77.09 | AG27: 1929 | AH27: =AC27-AD27-AE27-AF27-AG27 -> 21553.04 | AI27: =MAX(ROUND(MAX((AH27+AR27-5000*AQ27-AT27)*{0.03,0.1,0.2,0.25,0.3,0.35,0.45}-{0,2520,16920,31920,52920,85920,181920},0)-AS27,2),0) -> 324.64 | AL27: =ROUND(LOOKUP(MAX(0.0001,AK27/12),{0;6;24;50;70;110;160}*500+0.0001,5*MAX(0,AK27)*{0.6;2;4;5;6;7;9}%-10*{0;21;141;266;441;716;1516}),2) -> 0 | AM27: =AC27+AK27+AJ27 -> 25110.93 | AP27: =ROUND(AH27-AI27+AK27-AL27+AO27+AN27,2) -> 21228.4 | AQ27: 6 | AR27: 50537 | AS27: 398.06 | AT27: 18000 | AU27: 上海合杰
A28: 27 | B28: 202606 | C28: MNCN00461 | D28: 吕静雯 | E28: 130181198905025229 | F28: 高级销售顾问 | G28: 北京 | H28: 2540 | I28: 43542 | K28: 4600 | N28: 700 | O28: 0 | Q28: 12 | R28: =ROUND(K28/174*SUM(O28*1.5+P28*2+Q28*3),2) -> 951.72 | V28: 5079.65 | AC28: =ROUND(SUM(SUM(K28:N28)+SUM(R28:AB28)),2) -> 11331.37 | AD28: 2374.24 | AE28: 596.56 | AF28: 148.39 | AG28: 3561 | AH28: =AC28-AD28-AE28-AF28-AG28 -> 4651.18 | AI28: =MAX(ROUND(MAX((AH28+AR28-5000*AQ28-AT28)*{0.03,0.1,0.2,0.25,0.3,0.35,0.45}-{0,2520,16920,31920,52920,85920,181920},0)-AS28,2),0) -> 340.66 | AL28: =ROUND(LOOKUP(MAX(0.0001,AK28/12),{0;6;24;50;70;110;160}*500+0.0001,5*MAX(0,AK28)*{0.6;2;4;5;6;7;9}%-10*{0;21;141;266;441;716;1516}),2) -> 0 | AM28: =AC28+AK28+AJ28 -> 11331.37 | AP28: =ROUND(AH28-AI28+AK28-AL28+AO28+AN28,2) -> 4310.52 | AQ28: 6 | AR28: 63501.95 | AS28: 954.65 | AT28: 0 | AU28: 北京合杰
A29: 28 | B29: 202606 | C29: MNCN00477 | D29: 王雪娇 | E29: 340823198402105888 | F29: 销售顾问 | G29: 张家港 | H29: 2660 | I29: 43689 | K29: 4000 | N29: 600 | O29: 40 | Q29: 24 | R29: =ROUND(K29/174*SUM(O29*1.5+P29*2+Q29*3),2) -> 3034.48 | V29: 1794.38 | AC29: =ROUND(SUM(SUM(K29:N29)+SUM(R29:AB29)),2) -> 9428.86 | AD29: 1700.24 | AE29: 430.06 | AF29: 106.27 | AG29: 1994 | AH29: =AC29-AD29-AE29-AF29-AG29 -> 5198.29 | AI29: =MAX(ROUND(MAX((AH29+AR29-5000*AQ29-AT29)*{0.03,0.1,0.2,0.25,0.3,0.35,0.45}-{0,2520,16920,31920,52920,85920,181920},0)-AS29,2),0) -> 132.87 | AL29: =ROUND(LOOKUP(MAX(0.0001,AK29/12),{0;6;24;50;70;110;160}*500+0.0001,5*MAX(0,AK29)*{0.6;2;4;5;6;7;9}%-10*{0;21;141;266;441;716;1516}),2) -> 0 | AM29: =AC29+AK29+AJ29 -> 9428.86 | AP29: =ROUND(AH29-AI29+AK29-AL29+AO29+AN29,2) -> 5065.42 | AQ29: 6 | AR29: 53801.9 | AS29: 737.14 | AT29: 0 | AU29: 上海合杰
A30: 29 | B30: 202606 | C30: MNCN00478 | D30: 赵徐 | E30: 340421198706282854 | F30: 销售顾问 | G30: 张家港 | H30: 2660 | I30: 43690 | K30: 4000 | N30: 600 | O30: 40 | Q30: 24 | R30: =ROUND(K30/174*SUM(O30*1.5+P30*2+Q30*3),2) -> 3034.48 | V30: 3601.52 | AC30: =ROUND(SUM(SUM(K30:N30)+SUM(R30:AB30)),2) -> 11236 | AD30: 1969.52 | AE30: 497.38 | AF30: 123.1 | AG30: 2122 | AH30: =AC30-AD30-AE30-AF30-AG30 -> 6524 | AI30: =MAX(ROUND(MAX((AH30+AR30-5000*AQ30-AT30)*{0.03,0.1,0.2,0.25,0.3,0.35,0.45}-{0,2520,16920,31920,52920,85920,181920},0)-AS30,2),0) -> 623.6 | AL30: =ROUND(LOOKUP(MAX(0.0001,AK30/12),{0;6;24;50;70;110;160}*500+0.0001,5*MAX(0,AK30)*{0.6;2;4;5;6;7;9}%-10*{0;21;141;266;441;716;1516}),2) -> 0 | AM30: =AC30+AK30+AJ30 -> 11236 | AP30: =ROUND(AH30-AI30+AK30-AL30+AO30+AN30,2) -> 5900.4 | AQ30: 6 | AR30: 65756.18 | AS30: 1084.42 | AT30: 0 | AU30: 上海合杰
