Workbook

Sheet Sheet1
A1: 顺序 | B1: 工号 | C1: 应发工资 | D1: 医疗保险 报销 | E1: 其他补发 (非课税) | F1: 其他代扣 (非课税) | G1: 个人所得税 | H1: 年终奖金 个人所得税 | I1: 工会费 | J1: 存款制 度代扣 | K1: 养老保险 | L1: 医疗保险 | M1: 失业保险 | N1: 大病基金 | O1: 养老保险 补缴 | P1: 医疗保险 补缴 | Q1: 失业保险 补缴 | R1: 大病基金 补缴 | S1: 住房公积金 | T1: 实发工资
A2: 1 | B2: A1107001 | C2: =IFERROR(VLOOKUP(B2,工资明细202401_Sheet1!$B:$BC,37,FALSE),0) -> 16397.08 | D2: =IFERROR(VLOOKUP(B2,工资明细202401_Sheet1!$B:$BC,38,FALSE),0) -> 0 | E2: =IFERROR(VLOOKUP(B2,工资明细202401_Sheet1!$B:$BC,39,FALSE),0) -> 0 | F2: =IFERROR(VLOOKUP(B2,工资明细202401_Sheet1!$B:$BC,40,FALSE),0) -> 0 | G2: =IFERROR(VLOOKUP(B2,工资明细202401_Sheet1!$B:$BC,41,FALSE),0) -> -174.11 | H2: =IFERROR(VLOOKUP(B2,工资明细202401_Sheet1!$B:$BC,42,FALSE),0) -> 0 | I2: =IFERROR(VLOOKUP(B2,工资明细202401_Sheet1!$B:$BC,43,FALSE),0) -> -30 | J2: =IFERROR(VLOOKUP(B2,工资明细202401_Sheet1!$B:$BC,44,FALSE),0) -> 0 | K2: =IFERROR(VLOOKUP(B2,工资明细202401_Sheet1!$B:$BC,45,FALSE),0) -> -1211.92 | L2: =IFERROR(VLOOKUP(B2,工资明细202401_Sheet1!$B:$BC,46,FALSE),0) -> -302.98 | M2: =IFERROR(VLOOKUP(B2,工资明细202401_Sheet1!$B:$BC,47,FALSE),0) -> -75.75 | N2: =IFERROR(VLOOKUP(B2,工资明细202401_Sheet1!$B:$BC,48,FALSE),0) -> -5 | O2: =IFERROR(VLOOKUP(B2,工资明细202401_Sheet1!$B:$BC,49,FALSE),0) -> -94.8 | P2: =IFERROR(VLOOKUP(B2,工资明细202401_Sheet1!$B:$BC,50,FALSE),0) -> 0 | Q2: =IFERROR(VLOOKUP(B2,工资明细202401_Sheet1!$B:$BC,51,FALSE),0) -> -5.93 | R2: =IFERROR(VLOOKUP(B2,工资明细202401_Sheet1!$B:$BC,52,FALSE),0) -> 0 | S2: =IFERROR(VLOOKUP(B2,工资明细202401_Sheet1!$B:$BC,53,FALSE),0) -> -1397 | T2: =IFERROR(VLOOKUP(B2,工资明细202401_Sheet1!$B:$BC,54,FALSE),0) -> 13099.59
A3: 2 | B3: A1107022 | C3: =IFERROR(VLOOKUP(B3,工资明细202401_Sheet1!$B:$BC,37,FALSE),0) -> 13856.36 | D3: =IFERROR(VLOOKUP(B3,工资明细202401_Sheet1!$B:$BC,38,FALSE),0) -> 0 | E3: =IFERROR(VLOOKUP(B3,工资明细202401_Sheet1!$B:$BC,39,FALSE),0) -> 0 | F3: =IFERROR(VLOOKUP(B3,工资明细202401_Sheet1!$B:$BC,40,FALSE),0) -> 0 | G3: =IFERROR(VLOOKUP(B3,工资明细202401_Sheet1!$B:$BC,41,FALSE),0) -> -81.21 | H3: =IFERROR(VLOOKUP(B3,工资明细202401_Sheet1!$B:$BC,42,FALSE),0) -> 0 | I3: =IFERROR(VLOOKUP(B3,工资明细202401_Sheet1!$B:$BC,43,FALSE),0) -> -30 | J3: =IFERROR(VLOOKUP(B3,工资明细202401_Sheet1!$B:$BC,44,FALSE),0) -> 0 | K3: =IFERROR(VLOOKUP(B3,工资明细202401_Sheet1!$B:$BC,45,FALSE),0) -> -1248.72 | L3: =IFERROR(VLOOKUP(B3,工资明细202401_Sheet1!$B:$BC,46,FALSE),0) -> -312.18 | M3: =IFERROR(VLOOKUP(B3,工资明细202401_Sheet1!$B:$BC,47,FALSE),0) -> -78.05 | N3: =IFERROR(VLOOKUP(B3,工资明细202401_Sheet1!$B:$BC,48,FALSE),0) -> -5 | O3: =IFERROR(VLOOKUP(B3,工资明细202401_Sheet1!$B:$BC,49,FALSE),0) -> -299.68 | P3: =IFERROR(VLOOKUP(B3,工资明细202401_Sheet1!$B:$BC,50,FALSE),0) -> 0 | Q3: =IFERROR(VLOOKUP(B3,工资明细202401_Sheet1!$B:$BC,51,FALSE),0) -> -18.73 | R3: =IFERROR(VLOOKUP(B3,工资明细202401_Sheet1!$B:$BC,52,FALSE),0) -> 0 | S3: =IFERROR(VLOOKUP(B3,工资明细202401_Sheet1!$B:$BC,53,FALSE),0) -> -1187 | T3: =IFERROR(VLOOKUP(B3,工资明细202401_Sheet1!$B:$BC,54,FALSE),0) -> 10595.79
A4: 3 | B4: A1110002 | C4: =IFERROR(VLOOKUP(B4,工资明细202401_Sheet1!$B:$BC,37,FALSE),0) -> 10307.83 | D4: =IFERROR(VLOOKUP(B4,工资明细202401_Sheet1!$B:$BC,38,FALSE),0) -> 0 | E4: =IFERROR(VLOOKUP(B4,工资明细202401_Sheet1!$B:$BC,39,FALSE),0) -> 0 | F4: =IFERROR(VLOOKUP(B4,工资明细202401_Sheet1!$B:$BC,40,FALSE),0) -> 0 | G4: =IFERROR(VLOOKUP(B4,工资明细202401_Sheet1!$B:$BC,41,FALSE),0) -> -9.91 | H4: =IFERROR(VLOOKUP(B4,工资明细202401_Sheet1!$B:$BC,42,FALSE),0) -> 0 | I4: =IFERROR(VLOOKUP(B4,工资明细202401_Sheet1!$B:$BC,43,FALSE),0) -> -30 | J4: =IFERROR(VLOOKUP(B4,工资明细202401_Sheet1!$B:$BC,44,FALSE),0) -> 0 | K4: =IFERROR(VLOOKUP(B4,工资明细202401_Sheet1!$B:$BC,45,FALSE),0) -> -971.92 | L4: =IFERROR(VLOOKUP(B4,工资明细202401_Sheet1!$B:$BC,46,FALSE),0) -> -242.98 | M4: =IFERROR(VLOOKUP(B4,工资明细202401_Sheet1!$B:$BC,47,FALSE),0) -> -60.75 | N4: =IFERROR(VLOOKUP(B4,工资明细202401_Sheet1!$B:$BC,48,FALSE),0) -> -5 | O4: =IFERROR(VLOOKUP(B4,工资明细202401_Sheet1!$B:$BC,49,FALSE),0) -> -99.84 | P4: =IFERROR(VLOOKUP(B4,工资明细202401_Sheet1!$B:$BC,50,FALSE),0) -> 0 | Q4: =IFERROR(VLOOKUP(B4,工资明细202401_Sheet1!$B:$BC,51,FALSE),0) -> -6.24 | R4: =IFERROR(VLOOKUP(B4,工资明细202401_Sheet1!$B:$BC,52,FALSE),0) -> 0 | S4: =IFERROR(VLOOKUP(B4,工资明细202401_Sheet1!$B:$BC,53,FALSE),0) -> -1091 | T4: =IFERROR(VLOOKUP(B4,工资明细202401_Sheet1!$B:$BC,54,FALSE),0) -> 7790.19
A5: 4 | B5: A1207016 | C5: =IFERROR(VLOOKUP(B5,工资明细202401_Sheet1!$B:$BC,37,FALSE),0) -> 13519.48 | D5: =IFERROR(VLOOKUP(B5,工资明细202401_Sheet1!$B:$BC,38,FALSE),0) -> 0 | E5: =IFERROR(VLOOKUP(B5,工资明细202401_Sheet1!$B:$BC,39,FALSE),0) -> 0 | F5: =IFERROR(VLOOKUP(B5,工资明细202401_Sheet1!$B:$BC,40,FALSE),0) -> 0 | G5: =IFERROR(VLOOKUP(B5,工资明细202401_Sheet1!$B:$BC,41,FALSE),0) -> -169.88 | H5: =IFERROR(VLOOKUP(B5,工资明细202401_Sheet1!$B:$BC,42,FALSE),0) -> 0 | I5: =IFERROR(VLOOKUP(B5,工资明细202401_Sheet1!$B:$BC,43,FALSE),0) -> -30 | J5: =IFERROR(VLOOKUP(B5,工资明细202401_Sheet1!$B:$BC,44,FALSE),0) -> 0 | K5: =IFERROR(VLOOKUP(B5,工资明细202401_Sheet1!$B:$BC,45,FALSE),0) -> -1119.36 | L5: =IFERROR(VLOOKUP(B5,工资明细202401_Sheet1!$B:$BC,46,FALSE),0) -> -279.84 | M5: =IFERROR(VLOOKUP(B5,工资明细202401_Sheet1!$B:$BC,47,FALSE),0) -> -69.96 | N5: =IFERROR(VLOOKUP(B5,工资明细202401_Sheet1!$B:$BC,48,FALSE),0) -> -5 | O5: =IFERROR(VLOOKUP(B5,工资明细202401_Sheet1!$B:$BC,49,FALSE),0) -> -93.6 | P5: =IFERROR(VLOOKUP(B5,工资明细202401_Sheet1!$B:$BC,50,FALSE),0) -> 0 | Q5: =IFERROR(VLOOKUP(B5,工资明细202401_Sheet1!$B:$BC,51,FALSE),0) -> -5.85 | R5: =IFERROR(VLOOKUP(B5,工资明细202401_Sheet1!$B:$BC,52,FALSE),0) -> 0 | S5: =IFERROR(VLOOKUP(B5,工资明细202401_Sheet1!$B:$BC,53,FALSE),0) -> -1283 | T5: =IFERROR(VLOOKUP(B5,工资明细202401_Sheet1!$B:$BC,54,FALSE),0) -> 10462.99
A6: 5 | B6: A1207024 | C6: =IFERROR(VLOOKUP(B6,工资明细202401_Sheet1!$B:$BC,37,FALSE),0) -> 18456.89 | D6: =IFERROR(VLOOKUP(B6,工资明细202401_Sheet1!$B:$BC,38,FALSE),0) -> 0 | E6: =IFERROR(VLOOKUP(B6,工资明细202401_Sheet1!$B:$BC,39,FALSE),0) -> 0 | F6: =IFERROR(VLOOKUP(B6,工资明细202401_Sheet1!$B:$BC,40,FALSE),0) -> 0 | G6: =IFERROR(VLOOKUP(B6,工资明细202401_Sheet1!$B:$BC,41,FALSE),0) -> -216.88 | H6: =IFERROR(VLOOKUP(B6,工资明细202401_Sheet1!$B:$BC,42,FALSE),0) -> 0 | I6: =IFERROR(VLOOKUP(B6,工资明细202401_Sheet1!$B:$BC,43,FALSE),0) -> -30 | J6: =IFERROR(VLOOKUP(B6,工资明细202401_Sheet1!$B:$BC,44,FALSE),0) -> -1000 | K6: =IFERROR(VLOOKUP(B6,工资明细202401_Sheet1!$B:$BC,45,FALSE),0) -> -1461.68 | L6: =IFERROR(VLOOKUP(B6,工资明细202401_Sheet1!$B:$BC,46,FALSE),0) -> -365.42 | M6: =IFERROR(VLOOKUP(B6,工资明细202401_Sheet1!$B:$BC,47,FALSE),0) -> -91.36 | N6: =IFERROR(VLOOKUP(B6,工资明细202401_Sheet1!$B:$BC,48,FALSE),0) -> -5 | O6: =IFERROR(VLOOKUP(B6,工资明细202401_Sheet1!$B:$BC,49,FALSE),0) -> -127.2 | P6: =IFERROR(VLOOKUP(B6,工资明细202401_Sheet1!$B:$BC,50,FALSE),0) -> 0 | Q6: =IFERROR(VLOOKUP(B6,工资明细202401_Sheet1!$B:$BC,51,FALSE),0) -> -7.95 | R6: =IFERROR(VLOOKUP(B6,工资明细202401_Sheet1!$B:$BC,52,FALSE),0) -> 0 | S6: =IFERROR(VLOOKUP(B6,工资明细202401_Sheet1!$B:$BC,53,FALSE),0) -> -1669 | T6: =IFERROR(VLOOKUP(B6,工资明细202401_Sheet1!$B:$BC,54,FALSE),0) -> 13482.4
A7: 6 | B7: A1211001 | C7: =IFERROR(VLOOKUP(B7,工资明细202401_Sheet1!$B:$BC,37,FALSE),0) -> 16250.68 | D7: =IFERROR(VLOOKUP(B7,工资明细202401_Sheet1!$B:$BC,38,FALSE),0) -> 0 | E7: =IFERROR(VLOOKUP(B7,工资明细202401_Sheet1!$B:$BC,39,FALSE),0) -> 0 | F7: =IFERROR(VLOOKUP(B7,工资明细202401_Sheet1!$B:$BC,40,FALSE),0) -> 0 | G7: =IFERROR(VLOOKUP(B7,工资明细202401_Sheet1!$B:$BC,41,FALSE),0) -> -87.9 | H7: =IFERROR(VLOOKUP(B7,工资明细202401_Sheet1!$B:$BC,42,FALSE),0) -> 0 | I7: =IFERROR(VLOOKUP(B7,工资明细202401_Sheet1!$B:$BC,43,FALSE),0) -> -30 | J7: =IFERROR(VLOOKUP(B7,工资明细202401_Sheet1!$B:$BC,44,FALSE),0) -> 0 | K7: =IFERROR(VLOOKUP(B7,工资明细202401_Sheet1!$B:$BC,45,FALSE),0) -> -1505.52 | L7: =IFERROR(VLOOKUP(B7,工资明细202401_Sheet1!$B:$BC,46,FALSE),0) -> -376.38 | M7: =IFERROR(VLOOKUP(B7,工资明细202401_Sheet1!$B:$BC,47,FALSE),0) -> -94.1 | N7: =IFERROR(VLOOKUP(B7,工资明细202401_Sheet1!$B:$BC,48,FALSE),0) -> -5 | O7: =IFERROR(VLOOKUP(B7,工资明细202401_Sheet1!$B:$BC,49,FALSE),0) -> -229.12 | P7: =IFERROR(VLOOKUP(B7,工资明细202401_Sheet1!$B:$BC,50,FALSE),0) -> 0 | Q7: =IFERROR(VLOOKUP(B7,工资明细202401_Sheet1!$B:$BC,51,FALSE),0) -> -14.32 | R7: =IFERROR(VLOOKUP(B7,工资明细202401_Sheet1!$B:$BC,52,FALSE),0) -> 0 | S7: =IFERROR(VLOOKUP(B7,工资明细202401_Sheet1!$B:$BC,53,FALSE),0) -> -1596 | T7: =IFERROR(VLOOKUP(B7,工资明细202401_Sheet1!$B:$BC,54,FALSE),0) -> 12312.34
A8: 7 | B8: A1304009 | C8: =IFERROR(VLOOKUP(B8,工资明细202401_Sheet1!$B:$BC,37,FALSE),0) -> 13109.31 | D8: =IFERROR(VLOOKUP(B8,工资明细202401_Sheet1!$B:$BC,38,FALSE),0) -> 0 | E8: =IFERROR(VLOOKUP(B8,工资明细202401_Sheet1!$B:$BC,39,FALSE),0) -> 0 | F8: =IFERROR(VLOOKUP(B8,工资明细202401_Sheet1!$B:$BC,40,FALSE),0) -> 0 | G8: =IFERROR(VLOOKUP(B8,工资明细202401_Sheet1!$B:$BC,41,FALSE),0) -> -81.82 | H8: =IFERROR(VLOOKUP(B8,工资明细202401_Sheet1!$B:$BC,42,FALSE),0) -> 0 | I8: =IFERROR(VLOOKUP(B8,工资明细202401_Sheet1!$B:$BC,43,FALSE),0) -> -30 | J8: =IFERROR(VLOOKUP(B8,工资明细202401_Sheet1!$B:$BC,44,FALSE),0) -> -1000 | K8: =IFERROR(VLOOKUP(B8,工资明细202401_Sheet1!$B:$BC,45,FALSE),0) -> -1172.56 | L8: =IFERROR(VLOOKUP(B8,工资明细202401_Sheet1!$B:$BC,46,FALSE),0) -> -293.14 | M8: =IFERROR(VLOOKUP(B8,工资明细202401_Sheet1!$B:$BC,47,FALSE),0) -> -73.29 | N8: =IFERROR(VLOOKUP(B8,工资明细202401_Sheet1!$B:$BC,48,FALSE),0) -> -5 | O8: =IFERROR(VLOOKUP(B8,工资明细202401_Sheet1!$B:$BC,49,FALSE),0) -> -151.36 | P8: =IFERROR(VLOOKUP(B8,工资明细202401_Sheet1!$B:$BC,50,FALSE),0) -> 0 | Q8: =IFERROR(VLOOKUP(B8,工资明细202401_Sheet1!$B:$BC,51,FALSE),0) -> -9.46 | R8: =IFERROR(VLOOKUP(B8,工资明细202401_Sheet1!$B:$BC,52,FALSE),0) -> 0 | S8: =IFERROR(VLOOKUP(B8,工资明细202401_Sheet1!$B:$BC,53,FALSE),0) -> -1277 | T8: =IFERROR(VLOOKUP(B8,工资明细202401_Sheet1!$B:$BC,54,FALSE),0) -> 9015.68
A9: 8 | B9: A1306003 | C9: =IFERROR(VLOOKUP(B9,工资明细202401_Sheet1!$B:$BC,37,FALSE),0) -> 15598.04 | D9: =IFERROR(VLOOKUP(B9,工资明细202401_Sheet1!$B:$BC,38,FALSE),0) -> 0 | E9: =IFERROR(VLOOKUP(B9,工资明细202401_Sheet1!$B:$BC,39,FALSE),0) -> 0 | F9: =IFERROR(VLOOKUP(B9,工资明细202401_Sheet1!$B:$BC,40,FALSE),0) -> 0 | G9: =IFERROR(VLOOKUP(B9,工资明细202401_Sheet1!$B:$BC,41,FALSE),0) -> -58.44 | H9: =IFERROR(VLOOKUP(B9,工资明细202401_Sheet1!$B:$BC,42,FALSE),0) -> 0 | I9: =IFERROR(VLOOKUP(B9,工资明细202401_Sheet1!$B:$BC,43,FALSE),0) -> -30 | J9: =IFERROR(VLOOKUP(B9,工资明细202401_Sheet1!$B:$BC,44,FALSE),0) -> 0 | K9: =IFERROR(VLOOKUP(B9,工资明细202401_Sheet1!$B:$BC,45,FALSE),0) -> -1439.04 | L9: =IFERROR(VLOOKUP(B9,工资明细202401_Sheet1!$B:$BC,46,FALSE),0) -> -359.76 | M9: =IFERROR(VLOOKUP(B9,工资明细202401_Sheet1!$B:$BC,47,FALSE),0) -> -89.94 | N9: =IFERROR(VLOOKUP(B9,工资明细202401_Sheet1!$B:$BC,48,FALSE),0) -> -5 | O9: =IFERROR(VLOOKUP(B9,工资明细202401_Sheet1!$B:$BC,49,FALSE),0) -> -228 | P9: =IFERROR(VLOOKUP(B9,工资明细202401_Sheet1!$B:$BC,50,FALSE),0) -> 0 | Q9: =IFERROR(VLOOKUP(B9,工资明细202401_Sheet1!$B:$BC,51,FALSE),0) -> -14.25 | R9: =IFERROR(VLOOKUP(B9,工资明细202401_Sheet1!$B:$BC,52,FALSE),0) -> 0 | S9: =IFERROR(VLOOKUP(B9,工资明细202401_Sheet1!$B:$BC,53,FALSE),0) -> -1514 | T9: =IFERROR(VLOOKUP(B9,工资明细202401_Sheet1!$B:$BC,54,FALSE),0) -> 11859.61
A10: 9 | B10: A1307001 | C10: =IFERROR(VLOOKUP(B10,工资明细202401_Sheet1!$B:$BC,37,FALSE),0) -> 15097.96 | D10: =IFERROR(VLOOKUP(B10,工资明细202401_Sheet1!$B:$BC,38,FALSE),0) -> 0 | E10: =IFERROR(VLOOKUP(B10,工资明细202401_Sheet1!$B:$BC,39,FALSE),0) -> 0 | F10: =IFERROR(VLOOKUP(B10,工资明细202401_Sheet1!$B:$BC,40,FALSE),0) -> 0 | G10: =IFERROR(VLOOKUP(B10,工资明细202401_Sheet1!$B:$BC,41,FALSE),0) -> -181 | H10: =IFERROR(VLOOKUP(B10,工资明细202401_Sheet1!$B:$BC,42,FALSE),0) -> 0 | I10: =IFERROR(VLOOKUP(B10,工资明细202401_Sheet1!$B:$BC,43,FALSE),0) -> -30 | J10: =IFERROR(VLOOKUP(B10,工资明细202401_Sheet1!$B:$BC,44,FALSE),0) -> 0 | K10: =IFERROR(VLOOKUP(B10,工资明细202401_Sheet1!$B:$BC,45,FALSE),0) -> -1208.24 | L10: =IFERROR(VLOOKUP(B10,工资明细202401_Sheet1!$B:$BC,46,FALSE),0) -> -302.06 | M10: =IFERROR(VLOOKUP(B10,工资明细202401_Sheet1!$B:$BC,47,FALSE),0) -> -75.52 | N10: =IFERROR(VLOOKUP(B10,工资明细202401_Sheet1!$B:$BC,48,FALSE),0) -> -5 | O10: =IFERROR(VLOOKUP(B10,工资明细202401_Sheet1!$B:$BC,49,FALSE),0) -> -198.24 | P10: =IFERROR(VLOOKUP(B10,工资明细202401_Sheet1!$B:$BC,50,FALSE),0) -> 0 | Q10: =IFERROR(VLOOKUP(B10,工资明细202401_Sheet1!$B:$BC,51,FALSE),0) -> -12.39 | R10: =IFERROR(VLOOKUP(B10,工资明细202401_Sheet1!$B:$BC,52,FALSE),0) -> 0 | S10: =IFERROR(VLOOKUP(B10,工资明细202401_Sheet1!$B:$BC,53,FALSE),0) -> -1263 | T10: =IFERROR(VLOOKUP(B10,工资明细202401_Sheet1!$B:$BC,54,FALSE),0) -> 11822.51
A11: 10 | B11: A1307003 | C11: =IFERROR(VLOOKUP(B11,工资明细202401_Sheet1!$B:$BC,37,FALSE),0) -> 12636.14 | D11: =IFERROR(VLOOKUP(B11,工资明细202401_Sheet1!$B:$BC,38,FALSE),0) -> 0 | E11: =IFERROR(VLOOKUP(B11,工资明细202401_Sheet1!$B:$BC,39,FALSE),0) -> 0 | F11: =IFERROR(VLOOKUP(B11,工资明细202401_Sheet1!$B:$BC,40,FALSE),0) -> 0 | G11: =IFERROR(VLOOKUP(B11,工资明细202401_Sheet1!$B:$BC,41,FALSE),0) -> -144.25 | H11: =IFERROR(VLOOKUP(B11,工资明细202401_Sheet1!$B:$BC,42,FALSE),0) -> 0 | I11: =IFERROR(VLOOKUP(B11,工资明细202401_Sheet1!$B:$BC,43,FALSE),0) -> -30 | J11: =IFERROR(VLOOKUP(B11,工资明细202401_Sheet1!$B:$BC,44,FALSE),0) -> 0 | K11: =IFERROR(VLOOKUP(B11,工资明细202401_Sheet1!$B:$BC,45,FALSE),0) -> -1123.68 | L11: =IFERROR(VLOOKUP(B11,工资明细202401_Sheet1!$B:$BC,46,FALSE),0) -> -280.92 | M11: =IFERROR(VLOOKUP(B11,工资明细202401_Sheet1!$B:$BC,47,FALSE),0) -> -70.23 | N11: =IFERROR(VLOOKUP(B11,工资明细202401_Sheet1!$B:$BC,48,FALSE),0) -> -5 | O11: =IFERROR(VLOOKUP(B11,工资明细202401_Sheet1!$B:$BC,49,FALSE),0) -> -303.2 | P11: =IFERROR(VLOOKUP(B11,工资明细202401_Sheet1!$B:$BC,50,FALSE),0) -> 0 | Q11: =IFERROR(VLOOKUP(B11,工资明细202401_Sheet1!$B:$BC,51,FALSE),0) -> -18.95 | R11: =IFERROR(VLOOKUP(B11,工资明细202401_Sheet1!$B:$BC,52,FALSE),0) -> 0 | S11: =IFERROR(VLOOKUP(B11,工资明细202401_Sheet1!$B:$BC,53,FALSE),0) -> -1026 | T11: =IFERROR(VLOOKUP(B11,工资明细202401_Sheet1!$B:$BC,54,FALSE),0) -> 9633.91
A12: 11 | B12: A1308001 | C12: =IFERROR(VLOOKUP(B12,工资明细202401_Sheet1!$B:$BC,37,FALSE),0) -> 16238.67 | D12: =IFERROR(VLOOKUP(B12,工资明细202401_Sheet1!$B:$BC,38,FALSE),0) -> 0 | E12: =IFERROR(VLOOKUP(B12,工资明细202401_Sheet1!$B:$BC,39,FALSE),0) -> 0 | F12: =IFERROR(VLOOKUP(B12,工资明细202401_Sheet1!$B:$BC,40,FALSE),0) -> 0 | G12: =IFERROR(VLOOKUP(B12,工资明细202401_Sheet1!$B:$BC,41,FALSE),0) -> -22.98 | H12: =IFERROR(VLOOKUP(B12,工资明细202401_Sheet1!$B:$BC,42,FALSE),0) -> 0 | I12: =IFERROR(VLOOKUP(B12,工资明细202401_Sheet1!$B:$BC,43,FALSE),0) -> -30 | J12: =IFERROR(VLOOKUP(B12,工资明细202401_Sheet1!$B:$BC,44,FALSE),0) -> 0 | K12: =IFERROR(VLOOKUP(B12,工资明细202401_Sheet1!$B:$BC,45,FALSE),0) -> -1535.2 | L12: =IFERROR(VLOOKUP(B12,工资明细202401_Sheet1!$B:$BC,46,FALSE),0) -> -383.8 | M12: =IFERROR(VLOOKUP(B12,工资明细202401_Sheet1!$B:$BC,47,FALSE),0) -> -95.95 | N12: =IFERROR(VLOOKUP(B12,工资明细202401_Sheet1!$B:$BC,48,FALSE),0) -> -5 | O12: =IFERROR(VLOOKUP(B12,工资明细202401_Sheet1!$B:$BC,49,FALSE),0) -> -356.56 | P12: =IFERROR(VLOOKUP(B12,工资明细202401_Sheet1!$B:$BC,50,FALSE),0) -> 0 | Q12: =IFERROR(VLOOKUP(B12,工资明细202401_Sheet1!$B:$BC,51,FALSE),0) -> -22.28 | R12: =IFERROR(VLOOKUP(B12,工资明细202401_Sheet1!$B:$BC,52,FALSE),0) -> 0 | S12: =IFERROR(VLOOKUP(B12,工资明细202401_Sheet1!$B:$BC,53,FALSE),0) -> -1474 | T12: =IFERROR(VLOOKUP(B12,工资明细202401_Sheet1!$B:$BC,54,FALSE),0) -> 12312.9
A13: 12 | B13: A1308002 | C13: =IFERROR(VLOOKUP(B13,工资明细202401_Sheet1!$B:$BC,37,FALSE),0) -> 16288.63 | D13: =IFERROR(VLOOKUP(B13,工资明细202401_Sheet1!$B:$BC,38,FALSE),0) -> 0 | E13: =IFERROR(VLOOKUP(B13,工资明细202401_Sheet1!$B:$BC,39,FALSE),0) -> 0 | F13: =IFERROR(VLOOKUP(B13,工资明细202401_Sheet1!$B:$BC,40,FALSE),0) -> 0 | G13: =IFERROR(VLOOKUP(B13,工资明细202401_Sheet1!$B:$BC,41,FALSE),0) -> -197.2 | H13: =IFERROR(VLOOKUP(B13,工资明细202401_Sheet1!$B:$BC,42,FALSE),0) -> 0 | I13: =IFERROR(VLOOKUP(B13,工资明细202401_Sheet1!$B:$BC,43,FALSE),0) -> -30 | J13: =IFERROR(VLOOKUP(B13,工资明细202401_Sheet1!$B:$BC,44,FALSE),0) -> -1000 | K13: =IFERROR(VLOOKUP(B13,工资明细202401_Sheet1!$B:$BC,45,FALSE),0) -> -1469.52 | L13: =IFERROR(VLOOKUP(B13,工资明细202401_Sheet1!$B:$BC,46,FALSE),0) -> -367.38 | M13: =IFERROR(VLOOKUP(B13,工资明细202401_Sheet1!$B:$BC,47,FALSE),0) -> -91.85 | N13: =IFERROR(VLOOKUP(B13,工资明细202401_Sheet1!$B:$BC,48,FALSE),0) -> -5 | O13: =IFERROR(VLOOKUP(B13,工资明细202401_Sheet1!$B:$BC,49,FALSE),0) -> -300.56 | P13: =IFERROR(VLOOKUP(B13,工资明细202401_Sheet1!$B:$BC,50,FALSE),0) -> 0 | Q13: =IFERROR(VLOOKUP(B13,工资明细202401_Sheet1!$B:$BC,51,FALSE),0) -> -18.79 | R13: =IFERROR(VLOOKUP(B13,工资明细202401_Sheet1!$B:$BC,52,FALSE),0) -> 0 | S13: =IFERROR(VLOOKUP(B13,工资明细202401_Sheet1!$B:$BC,53,FALSE),0) -> -1462 | T13: =IFERROR(VLOOKUP(B13,工资明细202401_Sheet1!$B:$BC,54,FALSE),0) -> 11346.33
... A125: 124 | B125: A1107046 | C125: =IFERROR(VLOOKUP(B125,工资明细202401_Sheet1!$B:$BC,37,FALSE),0) -> 56136.36 | D125: =IFERROR(VLOOKUP(B125,工资明细202401_Sheet1!$B:$BC,38,FALSE),0) -> 0 | E125: =IFERROR(VLOOKUP(B125,工资明细202401_Sheet1!$B:$BC,39,FALSE),0) -> 0 | F125: =IFERROR(VLOOKUP(B125,工资明细202401_Sheet1!$B:$BC,40,FALSE),0) -> 0 | G125: =IFERROR(VLOOKUP(B125,工资明细202401_Sheet1!$B:$BC,41,FALSE),0) -> -5113.64 | H125: =IFERROR(VLOOKUP(B125,工资明细202401_Sheet1!$B:$BC,42,FALSE),0) -> 0 | I125: =IFERROR(VLOOKUP(B125,工资明细202401_Sheet1!$B:$BC,43,FALSE),0) -> -30 | J125: =IFERROR(VLOOKUP(B125,工资明细202401_Sheet1!$B:$BC,44,FALSE),0) -> 0 | K125: =IFERROR(VLOOKUP(B125,工资明细202401_Sheet1!$B:$BC,45,FALSE),0) -> 0 | L125: =IFERROR(VLOOKUP(B125,工资明细202401_Sheet1!$B:$BC,46,FALSE),0) -> 0 | M125: =IFERROR(VLOOKUP(B125,工资明细202401_Sheet1!$B:$BC,47,FALSE),0) -> 0 | N125: =IFERROR(VLOOKUP(B125,工资明细202401_Sheet1!$B:$BC,48,FALSE),0) -> 0 | O125: =IFERROR(VLOOKUP(B125,工资明细202401_Sheet1!$B:$BC,49,FALSE),0) -> 0 | P125: =IFERROR(VLOOKUP(B125,工资明细202401_Sheet1!$B:$BC,50,FALSE),0) -> 0 | Q125: =IFERROR(VLOOKUP(B125,工资明细202401_Sheet1!$B:$BC,51,FALSE),0) -> 0 | R125: =IFERROR(VLOOKUP(B125,工资明细202401_Sheet1!$B:$BC,52,FALSE),0) -> 0 | S125: =IFERROR(VLOOKUP(B125,工资明细202401_Sheet1!$B:$BC,53,FALSE),0) -> 0 | T125: =IFERROR(VLOOKUP(B125,工资明细202401_Sheet1!$B:$BC,54,FALSE),0) -> 50992.72

Sheet 员工信息(202401)_202401
A1: 员工编号 | B1: 用工类别 | C1: 入职日期 | D1: 在职员工 | E1: 在职员工_E | F1: 在职员工_F | G1: 离职员工 | H1: 离职员工_H | I1: Column_I
D2: 劳动合同起始日 | E2: 用工起始日 | F2: 参保起始月 | G2: 离职/退工日期 | H2: 参保终止月
A3: A1107001 | B3: 直接雇用 | C3: 2011-07-01 | D3: 2017-07-01 | E3: 2011-07-01 | F3: 2011年7月 | G3: / | H3: / | I3: 在职
A4: A1107011 | B4: 直接雇用 | C4: 2011-07-01 | D4: 2017-07-01 | E4: 2011-07-01 | F4: 2011年7月 | G4: / | H4: / | I4: 在职
A5: A1107012 | B5: 直接雇用 | C5: 2011-07-01 | D5: 2017-07-01 | E5: 2011-07-01 | F5: 2011年7月 | G5: / | H5: / | I5: 在职
A6: A1107015 | B6: 直接雇用 | C6: 2011-07-01 | D6: 2017-07-01 | E6: 2011-07-01 | F6: 2011年7月 | G6: / | H6: / | I6: 在职
A7: A1107017 | B7: 直接雇用 | C7: 2011-07-01 | D7: 2017-07-01 | E7: 2011-07-01 | F7: 2011年7月 | G7: / | H7: / | I7: 在职
A8: A1107018 | B8: 直接雇用 | C8: 2011-07-01 | D8: 2017-07-01 | E8: 2011-07-01 | F8: 2011年7月 | G8: / | H8: / | I8: 在职
A9: A1107021 | B9: 直接雇用 | C9: 2011-07-01 | D9: 2017-07-01 | E9: 2011-07-01 | F9: 2011年7月 | G9: / | H9: / | I9: 在职
A10: A1107022 | B10: 直接雇用 | C10: 2011-07-01 | D10: 2017-07-01 | E10: 2011-07-01 | F10: 2011年7月 | G10: / | H10: / | I10: 在职
A11: A1107027 | B11: 直接雇用 | C11: 2011-07-01 | D11: 2017-07-01 | E11: 2011-07-01 | F11: 2011年7月 | G11: / | H11: / | I11: 在职
A12: A1107029 | B12: 直接雇用 | C12: 2011-07-01 | D12: 2017-07-01 | E12: 2011-07-01 | F12: 2011年7月 | G12: / | H12: / | I12: 在职
A13: A1107031 | B13: 直接雇用 | C13: 2011-07-01 | D13: 2017-07-01 | E13: 2011-07-01 | F13: 2011年7月 | G13: / | H13: / | I13: 在职
A14: A1107035 | B14: 直接雇用 | C14: 2011-07-01 | D14: 2017-07-01 | E14: 2011-07-01 | F14: 2011年7月 | G14: / | H14: / | I14: 在职
... A128: A1107046 | B128: 直接雇用 | C128: 2011-07-01 | D128: 2021-01-26 | E128: 2011-07-01 | F128: 2011年7月 | G128: 2024-01-25 | H128: 2024年1月 | I128: 已离职

Sheet 工资明细202401_Sheet1
A1: 顺序 | B1: 工号 | C1: 入职日 | D1: 工数 | E1: 月度固定扣除 | F1: 病假 （H） | G1: 事假 （H) | H1: 早班 次数 | I1: 中班 次数 | J1: 夜班 次数 | K1: 平日加班 | L1: 休日加班 | M1: 国假加班 | N1: 时给 | O1: 基本给 | P1: 職能給 | Q1: 調整給 | R1: 职务津贴 | S1: 期待給 | T1: 成果給 | U1: 伙食津贴 | V1: 住房津贴 | W1: 交通津贴 | X1: 非整月调整 | Y1: 休假扣薪 | Z1: 月度奖金 | AA1: 改善提案+未然防止+小集团 | AB1: 轮班津贴1 | AC1: 轮班津贴2 | AD1: 加班费 | AE1: 日語津贴 | AF1: 其他补发 | AG1: 其他扣除 | AH1: 年终奖 | AI1: 高温津贴 | AJ1: 节日礼金 | AK1: 年度工时调整 | AL1: 应发工资 | AM1: 医疗保险 报销 | AN1: 其他补发 （非课税） | AO1: 其他代扣 (非课税) | AP1: 个人所得税 | AQ1: 年终奖金 个人所得税 | AR1: 工会费 | AS1: 存款制 度代扣 | AT1: 养老保险 | AU1: 医疗保险 | AV1: 失业保险 | AW1: 大病基金 | AX1: 养老保险 补缴 | AY1: 医疗保险 补缴 | AZ1: 失业保险 补缴 | BA1: 大病基金 补缴 | BB1: 住房公积金 | BC1: 实发工资
A2: 1 | B2: A1107001 | C2: 2011-07-01 | D2: 165 | E2: -4.2 | H2: 7 | I2: 6 | J2: 7 | K2: 36 | L2: 6.5 | M2: 7.5 | N2: 45.13 | O2: 7852 | R2: 1000 | U2: 150 | V2: 350 | W2: 250 | Y2: 0 | Z2: 488 | AB2: 530 | AC2: 1427.49 | AD2: 4039.14 | AE2: 300 | AF2: 0 | AG2: -189.55 | AJ2: 200 | AL2: 16397.08 | AP2: -174.11 | AQ2: 0 | AR2: -30 | AT2: -1211.92 | AU2: -302.98 | AV2: -75.75 | AW2: -5 | AX2: -94.8 | AZ2: -5.93 | BB2: -1397 | BC2: 13099.59
A3: 2 | B3: A1107022 | C3: 2011-07-01 | D3: 180 | E3: -3.6 | H3: 7.5 | I3: 8.5 | J3: 8 | K3: 44.5 | L3: 4 | M3: 0 | N3: 37.45 | O3: 6517 | R3: 1000 | U3: 150 | V3: 350 | W3: 250 | Y3: 0 | Z3: 560 | AB3: 650 | AC3: 1184.79 | AD3: 2799.39 | AE3: 300 | AF3: 30 | AG3: -134.82 | AJ3: 200 | AL3: 13856.36 | AP3: -81.21 | AQ3: 0 | AR3: -30 | AT3: -1248.72 | AU3: -312.18 | AV3: -78.05 | AW3: -5 | AX3: -299.68 | AZ3: -18.73 | BB3: -1187 | BC3: 10595.79
A4: 3 | B4: A1110002 | C4: 2011-10-24 | D4: 176 | H4: 0 | I4: 0 | J4: 0 | K4: 0 | L4: 8.5 | M4: 0 | N4: 48.99 | O4: 8525 | U4: 150 | V4: 350 | W4: 250 | Y4: 0 | AB4: 0 | AD4: 832.83 | AF4: 0 | AG4: 0 | AJ4: 200 | AL4: 10307.83 | AP4: -9.91 | AQ4: 0 | AR4: -30 | AT4: -971.92 | AU4: -242.98 | AV4: -60.75 | AW4: -5 | AX4: -99.84 | AZ4: -6.24 | BB4: -1091 | BC4: 7790.19
A5: 4 | B5: A1207016 | C5: 2012-07-01 | D5: 165 | E5: -4.2 | H5: 8 | I5: 7 | J5: 6 | K5: 44.5 | L5: 4.5 | M5: 7.5 | N5: 37.44 | O5: 6514 | U5: 150 | V5: 350 | W5: 250 | Y5: 0 | Z5: 760 | AB5: 530 | AC5: 1184.25 | AD5: 3678.48 | AF5: 60 | AG5: -157.25 | AJ5: 200 | AL5: 13519.48 | AP5: -169.88 | AQ5: 0 | AR5: -30 | AT5: -1119.36 | AU5: -279.84 | AV5: -69.96 | AW5: -5 | AX5: -93.6 | AZ5: -5.85 | BB5: -1283 | BC5: 10462.99
A6: 5 | B6: A1207024 | C6: 2012-07-01 | D6: 165 | E6: -4.2 | H6: 10 | I6: 8 | J6: 7.5 | K6: 45.5 | L6: 14 | M6: 7.5 | N6: 45.9 | O6: 7987 | R6: 1500 | U6: 150 | V6: 350 | W6: 250 | Y6: 0 | Z6: 610 | AB6: 640 | AC6: 1452.04 | AD6: 5450.63 | AF6: 60 | AG6: -192.78 | AJ6: 200 | AL6: 18456.89 | AP6: -216.88 | AQ6: 0 | AR6: -30 | AS6: -1000 | AT6: -1461.68 | AU6: -365.42 | AV6: -91.36 | AW6: -5 | AX6: -127.2 | AZ6: -7.95 | BB6: -1669 | BC6: 13482.4
A7: 6 | B7: A1211001 | C7: 2012-11-01 | D7: 180 | E7: -3.6 | H7: 8 | I7: 8 | J7: 7 | K7: 39.5 | L7: 9.5 | M7: 0 | N7: 44.21 | O7: 7692 | R7: 1500 | U7: 150 | V7: 350 | W7: 250 | Y7: 0 | Z7: 610 | AB7: 600 | AC7: 1398.41 | AD7: 3459.43 | AE7: 200 | AF7: 0 | AG7: -159.16 | AJ7: 200 | AL7: 16250.68 | AP7: -87.9 | AQ7: 0 | AR7: -30 | AT7: -1505.52 | AU7: -376.38 | AV7: -94.1 | AW7: -5 | AX7: -229.12 | AZ7: -14.32 | BB7: -1596 | BC7: 12312.34
A8: 7 | B8: A1304009 | C8: 2013-04-10 | D8: 180 | E8: -3.6 | H8: 8 | I8: 8 | J8: 8.5 | K8: 42.5 | L8: 8 | M8: 0 | N8: 37.44 | O8: 6514 | U8: 150 | V8: 350 | W8: 250 | Y8: 0 | Z8: 870 | AB8: 660 | AC8: 1184.25 | AD8: 2985.84 | AF8: 80 | AG8: -134.78 | AJ8: 200 | AL8: 13109.31 | AP8: -81.82 | AQ8: 0 | AR8: -30 | AS8: -1000 | AT8: -1172.56 | AU8: -293.14 | AV8: -73.29 | AW8: -5 | AX8: -151.36 | AZ8: -9.46 | BB8: -1277 | BC8: 9015.68
A9: 8 | B9: A1306003 | C9: 2013-06-17 | D9: 172.5 | E9: -1.7 | H9: 6.5 | I9: 8 | J9: 7 | K9: 39.5 | L9: 5.5 | M9: 0 | N9: 44.18 | O9: 7687 | R9: 1000 | U9: 150 | V9: 350 | W9: 250 | Y9: 0 | Z9: 950 | AB9: 585 | AC9: 1397.5 | AD9: 3103.65 | AF9: 0 | AG9: -75.11 | AJ9: 200 | AL9: 15598.04 | AP9: -58.44 | AQ9: 0 | AR9: -30 | AT9: -1439.04 | AU9: -359.76 | AV9: -89.94 | AW9: -5 | AX9: -228 | AZ9: -14.25 | BB9: -1514 | BC9: 11859.61
A10: 9 | B10: A1307001 | C10: 2013-07-01 | D10: 165 | E10: -4.2 | H10: 5.5 | I10: 8.5 | J10: 9.5 | K10: 44 | L10: 3 | M10: 11 | N10: 38.63 | O10: 6722 | R10: 1000 | U10: 150 | V10: 350 | W10: 250 | Y10: 0 | Z10: 560 | AB10: 690 | AC10: 1222.06 | AD10: 4056.15 | AF10: 60 | AG10: -162.25 | AJ10: 200 | AL10: 15097.96 | AP10: -181 | AQ10: 0 | AR10: -30 | AT10: -1208.24 | AU10: -302.06 | AV10: -75.52 | AW10: -5 | AX10: -198.24 | AZ10: -12.39 | BB10: -1263 | BC10: 11822.51
A11: 10 | B11: A1307003 | C11: 2013-07-01 | D11: 176 | H11: 0 | I11: 0 | J11: 0 | K11: 10.5 | L11: 34 | M11: 0 | N11: 39.13 | O11: 6809 | R11: 1000 | U11: 150 | V11: 350 | W11: 250 | Y11: 0 | Z11: 600 | AB11: 0 | AD11: 3277.14 | AF11: 0 | AG11: 0 | AJ11: 200 | AL11: 12636.14 | AP11: -144.25 | AQ11: 0 | AR11: -30 | AT11: -1123.68 | AU11: -280.92 | AV11: -70.23 | AW11: -5 | AX11: -303.2 | AZ11: -18.95 | BB11: -1026 | BC11: 9633.91
A12: 11 | B12: A1308001 | C12: 2013-08-01 | D12: 172.5 | E12: -1.7 | H12: 8 | I12: 8 | J12: 7 | K12: 39 | L12: 16.5 | M12: 0 | N12: 43.37 | O12: 7547 | R12: 1000 | U12: 150 | V12: 350 | W12: 250 | Y12: 0 | Z12: 845 | AB12: 600 | AC12: 1372.04 | AD12: 3968.36 | AF12: 30 | AG12: -73.73 | AJ12: 200 | AL12: 16238.67 | AP12: -22.98 | AQ12: 0 | AR12: -30 | AT12: -1535.2 | AU12: -383.8 | AV12: -95.95 | AW12: -5 | AX12: -356.56 | AZ12: -22.28 | BB12: -1474 | BC12: 12312.9
A13: 12 | B13: A1308002 | C13: 2013-08-01 | D13: 165 | E13: -4.2 | H13: 8 | I13: 6.5 | J13: 8 | K13: 31 | L13: 14 | M13: 7.5 | N13: 43.29 | O13: 7532 | R13: 1000 | U13: 150 | V13: 350 | W13: 250 | Y13: 0 | Z13: 795 | AB13: 595 | AC13: 1369.32 | AD13: 4199.13 | AF13: 30 | AG13: -181.82 | AJ13: 200 | AL13: 16288.63 | AP13: -197.2 | AQ13: 0 | AR13: -30 | AS13: -1000 | AT13: -1469.52 | AU13: -367.38 | AV13: -91.85 | AW13: -5 | AX13: -300.56 | AZ13: -18.79 | BB13: -1462 | BC13: 11346.33
A14: 13 | B14: A1309001 | C14: 2013-09-01 | D14: 165 | E14: -4.2 | H14: 6.5 | I14: 8 | J14: 7.5 | K14: 35 | L14: 7 | M14: 11 | N14: 38.79 | O14: 6750 | U14: 150 | V14: 350 | W14: 250 | Y14: 0 | Z14: 860 | AB14: 605 | AC14: 1227.15 | AD14: 3859.61 | AF14: 0 | AG14: -162.92 | AJ14: 200 | AL14: 14088.84 | AP14: -4.9 | AQ14: 0 | AR14: -30 | AT14: -1236.48 | AU14: -309.12 | AV14: -77.28 | AW14: -5 | AX14: -157.52 | AZ14: -9.84 | BB14: -1349 | BC14: 10909.7
A15: 14 | B15: A1311003 | C15: 2013-11-01 | D15: 176 | H15: 0 | I15: 0 | J15: 0 | K15: 1 | L15: 8 | M15: 8 | N15: 41.36 | O15: 7196 | U15: 150 | V15: 350 | W15: 250 | Y15: 0 | AB15: 0 | AD15: 1716.44 | AF15: 0 | AG15: 0 | AJ15: 200 | AL15: 9862.44 | AP15: 0 | AQ15: 0 | AR15: -30 | AT15: -865.28 | AU15: -216.32 | AV15: -54.08 | AW15: -5 | AX15: -154.8 | AZ15: -9.67 | BB15: -889 | BC15: 7638.29
A16: 15 | B16: A1311004 | C16: 2013-11-01 | D16: 180 | E16: -3.6 | H16: 9 | I16: 6.5 | J16: 7.5 | K16: 43 | L16: 8 | M16: 0 | N16: 43.75 | O16: 7612 | R16: 1000 | U16: 150 | V16: 350 | W16: 250 | Y16: 0 | Z16: 720 | AB16: 585 | AC16: 1383.86 | AD16: 3521.88 | AF16: 0 | AG16: -157.5 | AJ16: 200 | AL16: 15615.24 | AP16: -40.46 | AQ16: 0 | AR16: -30 | AS16: -1000 | AT16: -1375.36 | AU16: -343.84 | AV16: -85.96 | AW16: -5 | AX16: -173.84 | AZ16: -10.86 | BB16: -1502 | BC16: 11047.92
A17: 16 | B17: A1409003 | C17: 2014-09-10 | D17: 176 | H17: 0 | I17: 0 | J17: 0 | K17: 10.5 | L17: 32 | M17: 9 | N17: 38.92 | O17: 6772 | U17: 150 | V17: 350 | W17: 250 | Y17: 0 | Z17: 800 | AB17: 0 | AD17: 4154.71 | AF17: 30 | AG17: 0 | AJ17: 200 | AL17: 12706.71 | AP17: -27.13 | AQ17: 0 | AR17: -30 | AT17: -997.04 | AU17: -249.26 | AV17: -62.32 | AW17: -5 | AX17: -82.72 | AZ17: -5.17 | BB17: -1143 | BC17: 10105.07
A18: 17 | B18: A1409005 | C18: 2014-09-10 | D18: 172.5 | E18: -1.7 | H18: 8.5 | I18: 7.5 | J18: 6.5 | K18: 40 | L18: 4 | M18: 0 | N18: 31 | O18: 5394 | U18: 150 | V18: 350 | W18: 250 | Y18: 0 | Z18: 1400 | AB18: 570 | AC18: 980.63 | AD18: 2108 | AF18: 0 | AG18: -52.7 | AJ18: 200 | AL18: 11349.93 | AP18: -113.83 | AQ18: 0 | AR18: -30 | AT18: -1001.92 | AU18: -250.48 | AV18: -62.62 | AW18: -5 | AX18: -95.36 | AZ18: -5.96 | BB18: -1134 | BC18: 8650.76
A19: 18 | B19: A1412002 | C19: 2014-12-01 | D19: 176 | H19: 0 | I19: 0 | J19: 0 | K19: 7 | L19: 4 | M19: 0 | N19: 32.77 | O19: 5702 | U19: 150 | V19: 350 | W19: 250 | Y19: 0 | AB19: 0 | AD19: 606.25 | AF19: 0 | AG19: 0 | AJ19: 200 | AL19: 7258.25 | AP19: -8.39 | AQ19: 0 | AR19: -30 | AT19: -630.08 | AU19: -157.52 | AV19: -39.38 | AW19: -5 | AX19: -64.08 | AZ19: -4 | BB19: -708 | BC19: 5611.8
A20: 19 | B20: A1503001 | C20: 2015-03-02 | D20: 176 | H20: 0 | I20: 0 | J20: 0 | K20: 0 | L20: 0 | M20: 0 | N20: 25.66 | O20: 4464 | U20: 150 | V20: 350 | W20: 250 | Y20: 0 | AB20: 0 | AD20: 0 | AF20: 0 | AG20: 0 | AJ20: 200 | AL20: 5414 | AP20: 0 | AQ20: 0 | AR20: -30 | AS20: -1000 | AT20: -492.72 | AU20: -123.18 | AV20: -30.8 | AW20: -5 | AX20: -49.84 | AZ20: -3.12 | BB20: -554 | BC20: 3125.34
A21: 20 | B21: A1603001 | C21: 2016-03-01 | D21: 172.5 | E21: -1.7 | H21: 8.5 | I21: 8 | J21: 7 | K21: 31.5 | L21: 14.5 | M21: 0 | N21: 28.7 | O21: 4994 | U21: 150 | V21: 350 | W21: 250 | Y21: 0 | Z21: 770 | AB21: 605 | AC21: 907.91 | AD21: 2188.38 | AF21: 0 | AG21: -48.79 | AJ21: 200 | AL21: 10366.5 | AP21: 0 | AQ21: 0 | AR21: -30 | AS21: -1000 | AT21: -967.6 | AU21: -241.9 | AV21: -60.48 | AW21: -5 | AX21: -172.4 | AZ21: -10.78 | BB21: -994 | BC21: 6884.34
A22: 21 | B22: A1603003 | C22: 2016-03-01 | D22: 172.5 | E22: -1.7 | H22: 8.5 | I22: 8 | J22: 7 | K22: 37.5 | L22: 5.5 | M22: 0 | N22: 29.03 | O22: 5052 | U22: 150 | V22: 350 | W22: 250 | Y22: 0 | Z22: 1250 | AB22: 605 | AC22: 918.45 | AD22: 1952.27 | AF22: 60 | AG22: -49.35 | AJ22: 200 | AL22: 10738.37 | AP22: -10.98 | AQ22: 0 | AR22: -30 | AT22: -932.88 | AU22: -233.22 | AV22: -58.31 | AW22: -5 | AX22: -128.72 | AZ22: -8.05 | BB22: -1006 | BC22: 8325.21
A23: 22 | B23: A1603004 | C23: 2016-03-09 | D23: 165 | E23: -4.2 | H23: 6.5 | I23: 8 | J23: 8.5 | K23: 37 | L23: 4 | M23: 11 | N23: 27.45 | O23: 4776 | U23: 150 | V23: 350 | W23: 250 | Y23: 0 | Z23: 1010 | AB23: 645 | AC23: 868.28 | AD23: 2648.93 | AF23: 0 | AG23: -115.29 | AJ23: 200 | AL23: 10782.92 | AP23: -75.18 | AQ23: 0 | AR23: -30 | AT23: -852 | AU23: -213 | AV23: -53.25 | AW23: -5 | AX23: -60.08 | AZ23: -3.75 | BB23: -990 | BC23: 8500.66
A24: 23 | B24: A1604001 | C24: 2016-04-01 | D24: 176 | H24: 0 | I24: 0 | J24: 0 | K24: 3 | L24: 24 | M24: 0 | N24: 35.63 | O24: 6200 | U24: 150 | V24: 350 | W24: 250 | Y24: 0 | Z24: 300 | AB24: 0 | AD24: 1870.58 | AF24: 0 | AG24: 0 | AJ24: 200 | AL24: 9320.58 | AP24: 0 | AQ24: 0 | AR24: -30 | AT24: -679.68 | AU24: -169.92 | AV24: -42.48 | AW24: -5 | AX24: -25.12 | AZ24: -1.57 | BB24: -819 | BC24: 7547.81
A25: 24 | B25: A1605002 | C25: 2016-05-24 | D25: 176 | H25: 0 | I25: 0 | J25: 0 | K25: 8 | L25: 13 | M25: 8 | N25: 32.2 | O25: 5602 | U25: 150 | V25: 350 | W25: 250 | Y25: 0 | AB25: 0 | AD25: 1996.4 | AF25: 0 | AG25: 0 | AJ25: 200 | AL25: 8548.4 | AP25: -54.34 | AQ25: 0 | AR25: -30 | AS25: -1000 | AT25: -682.4 | AU25: -170.6 | AV25: -42.65 | AW25: -5 | AX25: -92.56 | AZ25: -5.78 | BB25: -738 | BC25: 5727.07
A26: 25 | B26: A1611001 | C26: 2016-11-08 | D26: 176 | H26: 0 | I26: 0 | J26: 0 | K26: 8.5 | L26: 35.5 | M26: 8.5 | N26: 35.63 | O26: 6200 | U26: 150 | V26: 350 | W26: 250 | Y26: 0 | Z26: 805 | AB26: 0 | AD26: 3892.58 | AF26: 0 | AG26: 0 | AJ26: 200 | AL26: 11847.58 | AP26: 0 | AQ26: 0 | AR26: -30 | AT26: -734.4 | AU26: -183.6 | AV26: -45.9 | AW26: -5 | AX26: -32.48 | AZ26: -2.03 | BB26: -878 | BC26: 9936.17
A27: 26 | B27: A1703004 | C27: 2017-03-20 | D27: 176 | H27: 0 | I27: 0 | J27: 0 | K27: 12.5 | L27: 0 | M27: 8 | N27: 42.73 | O27: 7435 | U27: 150 | V27: 350 | W27: 250 | Y27: 0 | AB27: 0 | AD27: 1826.71 | AF27: 0 | AG27: 0 | AJ27: 200 | AL27: 10211.71 | AP27: 0 | AQ27: 0 | AR27: -30 | AT27: -913.44 | AU27: -228.36 | AV27: -57.09 | AW27: -5 | AX27: -44.48 | AZ27: -2.78 | BB27: -1087 | BC27: 7843.56
A28: 27 | B28: A1703006 | C28: 2017-03-27 | D28: 176 | H28: 0 | I28: 0 | J28: 0 | K28: 8 | L28: 8 | M28: 8.5 | N28: 32.97 | O28: 5737 | U28: 150 | V28: 350 | W28: 250 | Y28: 0 | AB28: 0 | AD28: 1763.9 | AF28: 0 | AG28: 0 | AJ28: 200 | AL28: 8450.9 | AP28: -50.85 | AQ28: 0 | AR28: -30 | AS28: -1000 | AT28: -687.84 | AU28: -171.96 | AV28: -42.99 | AW28: -5 | AX28: -64.96 | AZ28: -4.06 | BB28: -779 | BC28: 5614.24
A29: 28 | B29: A1704002 | C29: 2017-04-13 | D29: 176 | H29: 0 | I29: 0 | J29: 0 | K29: 10 | L29: 0 | M29: 8 | N29: 40.11 | O29: 6980 | U29: 150 | V29: 350 | W29: 250 | Y29: 0 | AB29: 0 | AD29: 1564.29 | AF29: 0 | AG29: 0 | AJ29: 200 | AL29: 9494.29 | AP29: 0 | AQ29: 0 | AR29: -30 | AT29: -768 | AU29: -192 | AV29: -48 | AW29: -5 | AX29: -38.8 | AZ29: -2.42 | BB29: -912 | BC29: 7498.07
A30: 29 | B30: A1707001 | C30: 2017-07-03 | D30: 176 | H30: 0 | I30: 0 | J30: 0 | K30: 13 | L30: 16.5 | M30: 0 | N30: 32.2 | O30: 5602 | U30: 150 | V30: 350 | W30: 250 | Y30: 0 | AB30: 0 | AD30: 1690.5 | AE30: 200 | AF30: 0 | AG30: 0 | AJ30: 200 | AL30: 8442.5 | AP30: -2.48 | AQ30: 0 | AR30: -30 | AT30: -736 | AU30: -184 | AV30: -46 | AW30: -5 | AX30: -26.24 | AZ30: -1.64 | BB30: -888 | BC30: 6523.14
A31: 30 | B31: A1708001 | C31: 2017-08-22 | D31: 172.5 | E31: -1.7 | H31: 8 | I31: 8 | J31: 7.5 | K31: 35 | L31: 4 | M31: 0 | N31: 26.91 | O31: 4683 | U31: 150 | V31: 350 | W31: 250 | Y31: 0 | Z31: 1045 | AB31: 620 | AC31: 851.37 | AD31: 1628.06 | AF31: 0 | AG31: -45.75 | AJ31: 200 | AL31: 9731.68 | AP31: -76.96 | AQ31: 0 | AR31: -30 | AS31: -1000 | AT31: -850.88 | AU31: -212.72 | AV31: -53.18 | AW31: -5 | AX31: -106 | AZ31: -6.62 | BB31: -932 | BC31: 6458.32
A32: 31 | B32: A1803005 | C32: 2018-03-13 | D32: 172.5 | E32: -1.7 | H32: 8 | I32: 9 | J32: 7 | K32: 37 | L32: 4 | M32: 4 | N32: 27.48 | O32: 4782 | U32: 150 | V32: 350 | W32: 250 | Y32: 0 | Z32: 1400 | AB32: 630 | AC32: 869.37 | AD32: 2074.74 | AF32: 60 | AG32: -46.72 | AJ32: 200 | AL32: 10719.39 | AP32: 0 | AQ32: 0 | AR32: -30 | AT32: -883.44 | AU32: -220.86 | AV32: -55.22 | AW32: -5 | AX32: -78.64 | AZ32: -4.92 | BB32: -1006 | BC32: 8435.31
A33: 32 | B33: A1803006 | C33: 2018-03-27 | D33: 172.5 | E33: -1.7 | H33: 8.5 | I33: 7 | J33: 7 | K33: 33.5 | L33: 14 | M33: 0 | N33: 27.41 | O33: 4770 | U33: 150 | V33: 350 | W33: 250 | Y33: 0 | Z33: 1145 | AB33: 575 | AC33: 867.19 | AD33: 2144.83 | AF33: 30 | AG33: -46.6 | AJ33: 200 | AL33: 10435.42 | AP33: -95.05 | AQ33: 0 | AR33: -30 | AT33: -894.32 | AU33: -223.58 | AV33: -55.9 | AW33: -5 | AX33: -158.32 | AZ33: -9.9 | BB33: -920 | BC33: 8043.35
A34: 33 | B34: A1806001 | C34: 2018-06-21 | D34: 180 | E34: -3.6 | H34: 7 | I34: 8 | J34: 8 | K34: 42.5 | L34: 3.5 | M34: 0 | N34: 26.23 | O34: 4564 | U34: 150 | V34: 350 | W34: 250 | Y34: 0 | Z34: 885 | AB34: 630 | AC34: 829.74 | AD34: 1855.77 | AF34: 0 | AG34: -94.43 | AJ34: 200 | AL34: 9620.08 | AP34: -27.93 | AQ34: 0 | AR34: -30 | AT34: -870.08 | AU34: -217.52 | AV34: -54.38 | AW34: -5 | AX34: -243.76 | AZ34: -15.23 | BB34: -783 | BC34: 7373.18
A35: 34 | B35: A1808001 | C35: 2018-08-21 | D35: 176 | H35: 0 | I35: 0 | J35: 0 | K35: 0 | L35: 8.5 | M35: 0 | N35: 43.94 | O35: 7646 | U35: 150 | V35: 350 | W35: 250 | Y35: 0 | AB35: 0 | AD35: 746.98 | AF35: 0 | AG35: 0 | AJ35: 200 | AL35: 9342.98 | AP35: 0 | AQ35: 0 | AR35: -30 | AT35: -818.16 | AU35: -204.54 | AV35: -51.14 | AW35: -5 | AX35: -102.56 | AZ35: -6.41 | BB35: -895 | BC35: 7230.17
A36: 35 | B36: A1808005 | C36: 2018-08-27 | D36: 165 | E36: -4.2 | H36: 7 | I36: 8 | J36: 8 | K36: 41.5 | L36: 5.5 | M36: 11 | N36: 35.63 | O36: 6200 | R36: 1000 | U36: 150 | V36: 350 | W36: 250 | Y36: 0 | Z36: 665 | AB36: 630 | AC36: 1127.16 | AD36: 3785.69 | AF36: 0 | AG36: -149.65 | AJ36: 200 | AL36: 14208.2 | AP36: -206.06 | AQ36: 0 | AR36: -30 | AS36: -1000 | AT36: -921.28 | AU36: -230.32 | AV36: -57.58 | AW36: -5 | AX36: -145.12 | AZ36: -9.07 | BB36: -971 | BC36: 10632.77
A37: 36 | B37: A1903002 | C37: 2019-03-01 | D37: 165 | E37: -4.2 | H37: 7.5 | I37: 7.5 | J37: 8 | K37: 42.5 | L37: 7 | M37: 11 | N37: 27.02 | O37: 4702 | U37: 150 | V37: 350 | W37: 250 | Y37: 0 | Z37: 940 | AB37: 620 | AC37: 854.82 | AD37: 2992.47 | AF37: 0 | AG37: -113.48 | AJ37: 200 | AL37: 10945.81 | AP37: -111.24 | AQ37: 0 | AR37: -30 | AS37: -1000 | AT37: -881.84 | AU37: -220.46 | AV37: -55.12 | AW37: -5 | AX37: -143.6 | AZ37: -8.98 | BB37: -923 | BC37: 7566.57
A38: 37 | B38: A1903003 | C38: 2019-03-01 | D38: 165 | E38: -4.2 | G38: 2 | H38: 8 | I38: 7 | J38: 8.5 | K38: 34.5 | L38: 15 | M38: 7.5 | N38: 26.23 | O38: 4564 | U38: 150 | V38: 350 | W38: 250 | Y38: -52.46 | Z38: 1045 | AB38: 630 | AC38: 819.68 | AD38: 2734.48 | AF38: 0 | AG38: -110.17 | AJ38: 200 | AL38: 10580.53 | AP38: -100.29 | AQ38: 0 | AR38: -30 | AT38: -889.76 | AU38: -222.44 | AV38: -55.61 | AW38: -5 | AX38: -255.76 | AZ38: -15.98 | BB38: -793 | BC38: 8212.69
A39: 38 | B39: A1903004 | C39: 2019-03-01 | D39: 176 | H39: 0 | I39: 0 | J39: 0 | K39: 2 | L39: 6.5 | M39: 0 | N39: 31.51 | O39: 5482 | U39: 150 | V39: 350 | W39: 250 | Y39: 0 | Z39: 300 | AB39: 0 | AD39: 504.16 | AF39: 252.5 | AG39: 0 | AJ39: 200 | AL39: 7488.66 | AP39: -19.18 | AQ39: 0 | AR39: -30 | AT39: -726 | AU39: -181.5 | AV39: -45.38 | AW39: -5 | AX39: -87.92 | AZ39: -5.5 | BB39: -798 | BC39: 5590.18
A40: 39 | B40: A1903005 | C40: 2019-03-05 | D40: 176 | H40: 0 | I40: 0 | J40: 0 | K40: 11.5 | L40: 9 | M40: 0 | N40: 31.59 | O40: 5497 | U40: 150 | V40: 350 | W40: 250 | Y40: 0 | AB40: 0 | AD40: 1113.55 | AF40: 32.5 | AG40: 0 | AJ40: 200 | AL40: 7593.05 | AP40: 0 | AQ40: 0 | AR40: -30 | AT40: -690.96 | AU40: -172.74 | AV40: -43.19 | AW40: -5 | AX40: -94.88 | AZ40: -5.93 | BB40: -746 | BC40: 5804.35
...

Sheet 考勤信息2401_2401
A1: Column_A | B1: 社員番号 | C1: 标准工时 | D1: A | E1: B | F1: C | G1: D | H1: 平日 | I1: 平日补勤 | J1: 平日残業总计(HOUR) | K1: 休日残業(HOUR) | L1: 休日补勤加1 | M1: 休日残業总计(HOUR) | N1: 年度调整时数 | O1: 振替済み | P1: 休日小计(HOUR) | Q1: 法定 | R1: 法补 | S1: 法定残業(HOUR) | T1: 早班(TIME) | U1: 中班(TIME) | V1: 夜班(TIME) | W1: 4级以上人员休日加班津贴 | X1: 4级以上人员休日加班津贴_X | Y1: 呼出津贴 | Z1: 深夜津贴 | AA1: 勤务调整津贴 | AB1: 餐补 | AC1: 4级以上人员 加班调休时数 | AD1: 4级以上人员 加班调休时数_AD | AE1: Column_AE | AF1: Column_AF | AG1: Column_AG | AH1: Column_AH | AI1: Column_AI
D2: 遅刻/早退(TIME) | E2: 其他(DAY) | F2: 病欠(HOUR) | G2: 欠勤(HOUR) | W2: 加班时数 | X2: 津贴 | AC2: 平日时数 | AD2: 休日时数
A3: 1 | B3: A1107001 | C3: 165 | H3: 36 | J3: 36 | K3: 6.5 | M3: 6.5 | N3: -4.2 | P3: 6.5 | Q3: 7.5 | S3: 7.5 | T3: 7 | U3: 6 | V3: 7
A4: 2 | B4: A1107011 | C4: 176 | J4: 0 | M4: 0 | P4: 0 | Q4: 4 | S4: 4 | W4: 5 | X4: 500 | Y4: 30 | AC4: 7.5
A5: 3 | B5: A1107012 | C5: 176 | H5: 18 | J5: 18 | M5: 0 | P5: 0 | Q5: 8 | S5: 8 | W5: 7 | X5: 800 | Y5: 80 | Z5: 15
A6: 4 | B6: A1107015 | C6: 176 | H6: 20 | J6: 20 | M6: 0 | P6: 0 | S6: 0 | W6: 11.5 | X6: 600
A7: 5 | B7: A1107017 | C7: 176 | J7: 0 | M7: 0 | P7: 0 | S7: 0 | AC7: 4.5
A8: 6 | B8: A1107018 | C8: 176 | J8: 0 | M8: 0 | P8: 0 | S8: 0 | X8: 800 | AC8: 1
A9: 7 | B9: A1107021 | C9: 176 | J9: 0 | M9: 0 | P9: 0 | S9: 0 | AC9: 8
A10: 8 | B10: A1107022 | C10: 180 | H10: 36.5 | I10: 8 | J10: 44.5 | K10: 4 | M10: 4 | N10: -3.6 | P10: 4 | S10: 0 | T10: 7.5 | U10: 8.5 | V10: 8 | Y10: 30
A11: 9 | B11: A1107027 | C11: 176 | J11: 0 | M11: 0 | P11: 0 | S11: 0 | W11: 9.5 | X11: 1300 | AC11: 20
A12: 10 | B12: A1107029 | C12: 176 | H12: 13 | J12: 13 | M12: 0 | P12: 0 | S12: 0 | W12: 5.5 | X12: 800 | Y12: 100 | Z12: 40
A13: 11 | B13: A1107031 | C13: 176 | J13: 0 | M13: 0 | P13: 0 | S13: 0 | W13: 10 | X13: 1300 | AC13: 10.5
A14: 12 | B14: A1107035 | C14: 176 | J14: 0 | M14: 0 | P14: 0 | S14: 0 | AC14: 8.5
A15: 13 | B15: A1107037 | C15: 176 | H15: 20 | J15: 20 | M15: 0 | P15: 0 | S15: 0
A16: 14 | B16: A1107038 | C16: 176 | J16: 0 | M16: 0 | P16: 0 | S16: 0 | X16: 800 | AC16: 8
A17: 15 | B17: A1107043 | C17: 176 | H17: 2.5 | J17: 2.5 | M17: 0 | P17: 0 | S17: 0
A18: 16 | B18: A1109001 | C18: 176 | J18: 0 | M18: 0 | P18: 0 | S18: 0 | AC18: 5.5
A19: 17 | B19: A1110002 | C19: 176 | J19: 0 | K19: 8.5 | M19: 8.5 | P19: 8.5 | S19: 0
A20: 18 | B20: A1207016 | C20: 165 | H20: 36.5 | I20: 8 | J20: 44.5 | K20: 4.5 | M20: 4.5 | N20: -4.2 | P20: 4.5 | Q20: 7.5 | S20: 7.5 | T20: 8 | U20: 7 | V20: 6 | Y20: 60
A21: 19 | B21: A1207023 | C21: 176 | H21: 19 | J21: 19 | M21: 0 | P21: 0 | S21: 0 | W21: 4.5 | X21: 300 | Z21: 70 | AA21: 60
A22: 20 | B22: A1207024 | C22: 165 | H22: 28 | I22: 17.5 | J22: 45.5 | K22: 5.5 | L22: 8.5 | M22: 14 | N22: -4.2 | P22: 14 | Q22: 7.5 | S22: 7.5 | T22: 10 | U22: 8 | V22: 7.5 | Y22: 60
A23: 21 | B23: A1208008 | C23: 176 | J23: 0 | M23: 0 | P23: 0 | S23: 0 | AC23: 0.5
A24: 22 | B24: A1210001 | C24: 176 | J24: 0 | M24: 0 | P24: 0 | Q24: 7.5 | S24: 7.5
A25: 23 | B25: A1211001 | C25: 180 | H25: 39.5 | J25: 39.5 | K25: 9.5 | M25: 9.5 | N25: -3.6 | P25: 9.5 | S25: 0 | T25: 8 | U25: 8 | V25: 7
A26: 24 | B26: A1211002 | C26: 176 | H26: 20 | J26: 20 | M26: 0 | P26: 0 | S26: 0
A27: 25 | B27: A1212001 | C27: 176 | J27: 0 | M27: 0 | P27: 0 | S27: 0 | W27: 9 | X27: 1000 | AC27: 1.5
A28: 26 | B28: A1212003 | C28: 176 | H28: 5 | J28: 5 | M28: 0 | P28: 0 | Q28: 9 | S28: 9
A29: 27 | B29: A1304001 | C29: 176 | J29: 0 | M29: 0 | P29: 0 | Q29: 9.5 | S29: 9.5 | AC29: 5
A30: 28 | B30: A1304002 | C30: 176 | J30: 0 | M30: 0 | P30: 0 | S30: 0 | AC30: 3 | AD30: 2
A31: 29 | B31: A1304004 | C31: 176 | J31: 0 | M31: 0 | P31: 0 | S31: 0 | AC31: 3.5
A32: 30 | B32: A1304009 | C32: 180 | H32: 30 | I32: 12.5 | J32: 42.5 | K32: 3.5 | L32: 4.5 | M32: 8 | N32: -3.6 | P32: 8 | S32: 0 | T32: 8 | U32: 8 | V32: 8.5 | Y32: 80
A33: 31 | B33: A1305005 | C33: 176 | J33: 0 | M33: 0 | P33: 0 | S33: 0
A34: 32 | B34: A1306002 | C34: 176 | H34: 20 | J34: 20 | M34: 0 | P34: 0 | S34: 0
A35: 33 | B35: A1306003 | C35: 172.5 | H35: 35 | I35: 4.5 | J35: 39.5 | K35: 5.5 | M35: 5.5 | N35: -1.7 | P35: 5.5 | S35: 0 | T35: 6.5 | U35: 8 | V35: 7
A36: 34 | B36: A1307001 | C36: 165 | H36: 23 | I36: 21 | J36: 44 | K36: 3 | M36: 3 | N36: -4.2 | P36: 3 | Q36: 11 | S36: 11 | T36: 5.5 | U36: 8.5 | V36: 9.5 | Y36: 60
A37: 35 | B37: A1307003 | C37: 176 | H37: 10.5 | J37: 10.5 | K37: 34 | M37: 34 | P37: 34 | S37: 0
A38: 36 | B38: A1308001 | C38: 172.5 | H38: 35 | I38: 4 | J38: 39 | K38: 16.5 | M38: 16.5 | N38: -1.7 | P38: 16.5 | S38: 0 | T38: 8 | U38: 8 | V38: 7 | Y38: 30
A39: 37 | B39: A1308002 | C39: 165 | H39: 27 | I39: 4 | J39: 31 | K39: 14 | M39: 14 | N39: -4.2 | P39: 14 | Q39: 7.5 | S39: 7.5 | T39: 8 | U39: 6.5 | V39: 8 | Y39: 30
A40: 38 | B40: A1309001 | C40: 165 | H40: 30.5 | I40: 4.5 | J40: 35 | K40: 2 | L40: 5 | M40: 7 | N40: -4.2 | P40: 7 | Q40: 11 | S40: 11 | T40: 6.5 | U40: 8 | V40: 7.5
...

Sheet 参数
A1: 参数名 | B1: 参数值
A2: 薪资年份
A3: 薪资月份
A4: 月标准工时 | B4: 174
