Workbook
Name 证件类型: [1]填表说明!$A$6:$A$17

Sheet 付款通知书
A2: 上海外服合杰企业服务有限公司
A3: 收款通知书
A4: ADVISE ON COLLECTION
A5: 46082
A7: 公司名称：中粮福临门食品营销有限公司上海分公司
A8: 纳税人识别号： | B8: 91310104MA1FR47R6D
A9: 客户开户银行： | B9: 中信银行北京中粮广场支行
A10: 费用详情 长促KA
A11: 工资人数 | D11: =长促工资明细!A39 -> 34 | E11: NKA | F11: LKA | G11: DT
A12: HC | D12: =D11 -> 34 | E12: =COUNTIFS(长促工资明细!$J:$J,付款通知书!$E$11) -> 34 | F12: =COUNTIFS(长促工资明细!$J:$J,付款通知书!$F$11) -> 0 | G12: =COUNTIFS(长促工资明细!$J:$J,付款通知书!$G$11) -> 0
A13: 2026年3月工资 | D13: =长促工资明细!BO40 -> 114589.63 | E13: =SUMIFS(长促工资明细!$BO:$BO,长促工资明细!$J:$J,付款通知书!$E$11) -> 114589.63 | F13: =SUMIFS(长促工资明细!$BO:$BO,长促工资明细!$J:$J,付款通知书!$F$11) -> 0 | G13: =SUMIFS(长促工资明细!$BO:$BO,长促工资明细!$J:$J,付款通知书!$G$11) -> 0
A14: 2026年4月社保 | D14: =社保公积金账单!CH40+社保公积金账单!CI40 -> 92121.98 | E14: =SUMIFS(社保公积金账单!$CL:$CL,社保公积金账单!$E:$E,付款通知书!$E$11) -> 89412.51 | F14: =SUMIFS(社保公积金账单!$CL:$CL,社保公积金账单!$E:$E,付款通知书!$F$11) -> 0 | G14: =SUMIFS(社保公积金账单!$CL:$CL,社保公积金账单!$E:$E,付款通知书!$G$11) -> 0
A15: 2026年4月公积金 | D15: =社保公积金账单!CJ40+社保公积金账单!CK40 -> 12808 | E15: =SUMIFS(社保公积金账单!$CM:$CM,社保公积金账单!$E:$E,$E$11) -> 12424 | F15: =SUMIFS(社保公积金账单!$CM:$CM,社保公积金账单!$E:$E,$F$11) -> 0 | G15: =SUMIFS(社保公积金账单!$CM:$CM,社保公积金账单!$E:$E,G11) -> 0
A16: 管理费 | D16: =ROUND((D13+D14+D15)*0.02,2) -> 4390.39 | E16: =ROUND((E13+E14+E15)*0.02,2) -> 4328.52 | F16: =ROUND((F13+F14+F15)*0.02,2) -> 0 | G16: =ROUND((G13+G14+G15)*0.02,2) -> 0
A17: 2026年3月雇主责任险 | D17: =社保公积金账单!G40 -> 649.11 | E17: =SUMIFS(社保公积金账单!$G:$G,社保公积金账单!$E:$E,付款通知书!$E$11) -> 629.44 | F17: =SUMIFS(社保公积金账单!$G:$G,社保公积金账单!$E:$E,付款通知书!$F$11) -> 0 | G17: =SUMIFS(社保公积金账单!$G:$G,社保公积金账单!$E:$E,付款通知书!$G$11) -> 0
A18: 发票税金 | D18: =ROUND(SUM(D13:D17)*6.78%,2) -> 15225.11 | E18: =ROUND(SUM(E13:E17)*6.78%,2) -> 15009.84 | F18: =ROUND(SUM(F13:F17)*6.78%,2) -> 0 | G18: =ROUND(SUM(G13:G17)*6.78%,2) -> 0
A19: 请款金额 | D19: =ROUND(D13+D14+D15+D16+D17+D18,2) -> 239784.22 | E19: =ROUND(E13+E14+E15+E16+E17+E18,2) -> 236393.94 | F19: =ROUND(F13+F14+F15+F16+F17+F18,2) -> 0 | G19: =ROUND(G13+G14+G15+G16+G17+G18,2) -> 0
A20: Total | D20: =D19 -> 239784.22
D21: =D20/1.06 -> 226211.53
D22: =D20/1.06 -> 226211.53
D23: =ROUND(D20/1.06,2) -> 226211.53
A24: 大写金额： | B24: =IF(D20<=0,,"人民币"&IF(INT(D20)=0,,TEXT(INT(D20),"[dbnum2]")&"圆")&IF(INT(D20*10)-INT(D20)*10=0,IF(INT(D20)*(INT(D20*100)-INT(D20*10)*10)=0,"","零"),TEXT(INT(D20*10)-INT(D20)*10,"[dbnum2]")&"角")&IF((INT(D20*100)-INT(D20*10)*10)=0,"整",TEXT((INT(D20*100)-INT(D20*10)*10),"[dbnum2]")&"分")) -> 人民币贰拾叁万玖仟柒佰捌拾肆圆贰角贰分 | E24: =E19/1.06 -> 223013.15 | F24: =F19/1.06 -> 0 | G24: =G19/1.06 -> 0
D25: =D20/1.06 -> 226211.53
A26: 户名：上海外服合杰企业服务有限公司 | D26: =D19/1.06 -> 226211.53
A27: 开户银行：中国工商银行上海市金钟支行
A28: 人民币银行帐号：RMB 1001199409006536383

Sheet 长促工资明细
A4: 序号 | B4: 大区 | C4: 省区 | D4: 城市群 | E4: 城市 | F4: 导购类型 | G4: 姓名 | H4: 身份证号 | I4: 联系电话 | J4: 渠道 （NKA/LKA/DT） | K4: 系统性质 （直营/经销） | L4: 门店系统 | M4: SFA编码 | N4: 门店名称 | O4: 入职时间 | P4: 离职时间 | Q4: 基本工资 | AB4: 销售提成 | AI4: 月度补贴 | AL4: 其它补贴 | AQ4: 其它奖金 | AT4: 报销费用 | AU4: 其他费用 | AV4: 薪资补差 | AW4: 应发工资合计 | AX4: 备注 （最低工资标准） | AY4: 第三方公司名称 | AZ4: 社保个人 | BA4: 公积金个人 | BB4: 其他收入 | BC4: 四金后合计（不包含交通补贴/餐补/加班费/报销） | BD4: 工资调整 | BE4: 税前工资合计 | BF4: 截止上月合并计税工资 | BG4: 截止上月个税 | BH4: 累计专项抵扣 | BI4: 专项扣除 | BJ4: 截止本月合计计税工资 | BK4: 个税 | BL4: 累计个税 | BM4: 实发工资 | BN4: 经济补偿金 | BO4: 请款工资
Q5: 基本工资 | R5: 入职年限 | S5: 工龄补贴 | T5: 应上班天数 | U5: 实际上班天数 | V5: 病假（天） | W5: 事假（天） | X5: 补扣款 | Y5: 本月应发工资 | Z5: 加班（天） | AA5: 加班工资 | AB5: 总体目标销量（箱） | AC5: 总体实际销量（箱） | AD5: 总体产品销量达成率 | AE5: 提成金额 | AF5: 扣除提成金额 | AG5: 扣除OTO提成金额 | AH5: 本月实际提成金额 | AI5: 话费补贴基数 | AJ5: 交通补贴基数 | AK5: 月度补贴合计 | AL5: 生日补贴 | AM5: 餐补 | AN5: 大店补贴 | AO5: 其他补贴类型 | AP5: 其他补贴金额 | AQ5: 白糖奖金 | AR5: 激励名称 | AS5: 激励奖金 | BH5: 累计专项抵扣
A6: 1 | B6: 江沪 | C6: 上海KA | D6: 上海 | E6: 上海 | F6: 单导长促 | G6: 赵志炜 | H6: 340826197611081813 | I6: 13062613935 | J6: NKA | K6: 直营 | L6: 欧发 | M6: 238976848 | N6: 大润发曹安店 | O6: 43539 | Q6: 2690 | R6: 6 | S6: 0 | T6: 15 | U6: 15 | V6: 0 | W6: 0 | X6: 0 | Y6: 2690 | Z6: 0 | AA6: 0 | AB6: 172.39 | AC6: 245.83333 | AD6: 1.4260301 | AE6: 1761.5833 | AF6: 0 | AG6: 235.75 | AH6: 1525.8333 | AI6: 0 | AJ6: 80 | AK6: 80 | AL6: 0 | AM6: 150 | AQ6: 0 | AW6: 4445.83 | AX6: 2740 | AY6: 上海合杰 | AZ6: 783.3 | BA6: 188 | BB6: 0 | BC6: =ROUND(AW6-AZ6-BA6+BB6-AA6-AK6-AT6-AM6,2) -> 3244.53 | BD6: =ROUND(IF(T6=U6,IF((BC6-BB6)<AX6,AX6-(BC6-BB6),0)),2) -> 0 | BE6: =ROUND(AW6-AZ6-BA6+BB6+BD6,2) -> 3474.53 | BF6: -13371.5 | BG6: 0 | BH6: 14000 | BI6: 10500 | BJ6: =ROUND(BF6+BE6-5000-(BH6-BI6),2) -> -18396.97 | BK6: =ROUND(MAX(BJ6*{0.03,0.1,0.2,0.25,0.3,0.35,0.45}-{0,2520,16920,31920,52920,85920,181920}-BG6,0),2) -> 0 | BL6: =BG6+BK6 -> 0 | BM6: =ROUND(BE6-BK6,2) -> 3474.53 | BN6: 0 | BO6: =BE6+BN6 -> 3474.53 | BP6: =AZ6+BA6 -> 971.3 | BQ6: =AS6+AU6 -> 0 | BR6: =VLOOKUP(H6,社保公积金账单!D:D,1,0) -> 340826197611081813 | BS6: =T6-U6 -> 0
A7: 2 | B7: 江沪 | C7: 上海KA | D7: 上海 | E7: 上海 | F7: 单导长促 | G7: 周汝娜 | H7: 342422198208101764 | I7: 15821656046 | J7: NKA | K7: 直营 | L7: 欧发 | M7: 238976840 | N7: 大润发春申店 | O7: 45174 | Q7: 2690 | R7: 2 | S7: 0 | T7: 16 | U7: 16 | V7: 0 | W7: 0 | X7: 0 | Y7: 2690 | Z7: 0 | AA7: 0 | AB7: 301.66 | AC7: 365.77778 | AD7: 1.2125498 | AE7: 3026.3333 | AF7: 0 | AG7: 558.54167 | AH7: 1233.8958 | AI7: 0 | AJ7: 80 | AK7: 80 | AL7: 0 | AM7: 160 | AQ7: 0 | AW7: 4163.9 | AX7: 2740 | AY7: 上海合杰 | AZ7: 783.3 | BA7: 188 | BB7: 0 | BC7: =ROUND(AW7-AZ7-BA7+BB7-AA7-AK7-AT7-AM7,2) -> 2952.6 | BD7: =ROUND(IF(T7=U7,IF((BC7-BB7)<AX7,AX7-(BC7-BB7),0)),2) -> 0 | BE7: =ROUND(AW7-AZ7-BA7+BB7+BD7,2) -> 3192.6 | BF7: -4303.27 | BG7: 0 | BH7: 0 | BI7: 0 | BJ7: =ROUND(BF7+BE7-5000-(BH7-BI7),2) -> -6110.67 | BK7: =ROUND(MAX(BJ7*{0.03,0.1,0.2,0.25,0.3,0.35,0.45}-{0,2520,16920,31920,52920,85920,181920}-BG7,0),2) -> 0 | BL7: =BG7+BK7 -> 0 | BM7: =ROUND(BE7-BK7,2) -> 3192.6 | BN7: 0 | BO7: =BE7+BN7 -> 3192.6 | BP7: =AZ7+BA7 -> 971.3 | BQ7: =AS7+AU7 -> 0 | BR7: =VLOOKUP(H7,社保公积金账单!D:D,1,0) -> 342422198208101764 | BS7: =T7-U7 -> 0
A8: 3 | B8: 江沪 | C8: 上海KA | D8: 上海 | E8: 上海 | F8: 单导长促 | G8: 余应红 | H8: 342423197801132301 | I8: 13482821470 | J8: NKA | K8: 直营 | L8: 欧发 | M8: 238976840 | N8: 大润发春申店 | O8: 44386 | Q8: 2690 | R8: 4 | S8: 0 | T8: 22 | U8: 22 | V8: 0 | W8: 0 | X8: 0 | Y8: 2690 | Z8: 0 | AA8: 0 | AB8: 301.66 | AC8: 365.77778 | AD8: 1.2125498 | AE8: 3026.3333 | AF8: 0 | AG8: 558.54167 | AH8: 1233.8958 | AI8: 0 | AJ8: 80 | AK8: 80 | AL8: 0 | AM8: 220 | AQ8: 0 | AW8: 4223.9 | AX8: 2740 | AY8: 上海合杰 | AZ8: 783.3 | BA8: 188 | BB8: 0 | BC8: =ROUND(AW8-AZ8-BA8+BB8-AA8-AK8-AT8-AM8,2) -> 2952.6 | BD8: =ROUND(IF(T8=U8,IF((BC8-BB8)<AX8,AX8-(BC8-BB8),0)),2) -> 0 | BE8: =ROUND(AW8-AZ8-BA8+BB8+BD8,2) -> 3252.6 | BF8: -4603.25 | BG8: 0 | BH8: 0 | BI8: 0 | BJ8: =ROUND(BF8+BE8-5000-(BH8-BI8),2) -> -6350.65 | BK8: =ROUND(MAX(BJ8*{0.03,0.1,0.2,0.25,0.3,0.35,0.45}-{0,2520,16920,31920,52920,85920,181920}-BG8,0),2) -> 0 | BL8: =BG8+BK8 -> 0 | BM8: =ROUND(BE8-BK8,2) -> 3252.6 | BN8: 0 | BO8: =BE8+BN8 -> 3252.6 | BP8: =AZ8+BA8 -> 971.3 | BQ8: =AS8+AU8 -> 0 | BR8: =VLOOKUP(H8,社保公积金账单!D:D,1,0) -> 342423197801132301 | BS8: =T8-U8 -> 0
A9: 4 | B9: 江沪 | C9: 上海KA | D9: 上海 | E9: 上海 | F9: 单导长促 | G9: 姚玉环 | H9: 342422198302204882 | I9: 15000908642 | J9: NKA | K9: 直营 | L9: 欧发 | M9: 238976842 | N9: 大润发奉贤店 | O9: 45931 | Q9: 2740 | R9: 0 | S9: 0 | T9: 16 | U9: 16 | V9: 0 | W9: 0 | X9: 0 | Y9: 2740 | Z9: 0 | AA9: 0 | AB9: 463.73 | AC9: 601.86111 | AD9: 1.2978697 | AE9: 4168.1667 | AF9: 0 | AG9: 764.375 | AH9: 1701.8958 | AI9: 0 | AJ9: 80 | AK9: 80 | AL9: 0 | AM9: 160 | AQ9: 0 | AW9: 4681.9 | AX9: 2740 | AY9: 上海合杰 | AZ9: 783.3 | BA9: 192 | BB9: 0 | BC9: =ROUND(AW9-AZ9-BA9+BB9-AA9-AK9-AT9-AM9,2) -> 3466.6 | BD9: =ROUND(IF(T9=U9,IF((BC9-BB9)<AX9,AX9-(BC9-BB9),0)),2) -> 0 | BE9: =ROUND(AW9-AZ9-BA9+BB9+BD9,2) -> 3706.6 | BF9: -1638.15 | BG9: 0 | BH9: 0 | BI9: 0 | BJ9: =ROUND(BF9+BE9-5000-(BH9-BI9),2) -> -2931.55 | BK9: =ROUND(MAX(BJ9*{0.03,0.1,0.2,0.25,0.3,0.35,0.45}-{0,2520,16920,31920,52920,85920,181920}-BG9,0),2) -> 0 | BL9: =BG9+BK9 -> 0 | BM9: =ROUND(BE9-BK9,2) -> 3706.6 | BN9: 0 | BO9: =BE9+BN9 -> 3706.6 | BP9: =AZ9+BA9 -> 975.3 | BQ9: =AS9+AU9 -> 0 | BR9: =VLOOKUP(H9,社保公积金账单!D:D,1,0) -> 342422198302204882 | BS9: =T9-U9 -> 0
A10: 5 | B10: 江沪 | C10: 上海KA | D10: 上海 | E10: 上海 | F10: 单导长促 | G10: 雷年枝 | H10: 342501198810062263 | I10: 17701878392 | J10: NKA | K10: 直营 | L10: 欧发 | M10: 238976842 | N10: 大润发奉贤店 | O10: 45200 | Q10: 2690 | R10: 2 | S10: 0 | T10: 22 | U10: 22 | V10: 0 | W10: 0 | X10: 0 | Y10: 2690 | Z10: 0 | AA10: 0 | AB10: 463.73 | AC10: 601.86111 | AD10: 1.2978697 | AE10: 4168.1667 | AF10: 0 | AG10: 764.375 | AH10: 1701.8958 | AI10: 0 | AJ10: 80 | AK10: 80 | AL10: 0 | AM10: 210 | AQ10: 0 | AW10: 4681.9 | AX10: 2740 | AY10: 上海合杰 | AZ10: 783.3 | BA10: 188 | BB10: 0 | BC10: =ROUND(AW10-AZ10-BA10+BB10-AA10-AK10-AT10-AM10,2) -> 3420.6 | BD10: =ROUND(IF(T10=U10,IF((BC10-BB10)<AX10,AX10-(BC10-BB10),0)),2) -> 0 | BE10: =ROUND(AW10-AZ10-BA10+BB10+BD10,2) -> 3710.6 | BF10: -1457.41 | BG10: 0 | BH10: 0 | BI10: 0 | BJ10: =ROUND(BF10+BE10-5000-(BH10-BI10),2) -> -2746.81 | BK10: =ROUND(MAX(BJ10*{0.03,0.1,0.2,0.25,0.3,0.35,0.45}-{0,2520,16920,31920,52920,85920,181920}-BG10,0),2) -> 0 | BL10: =BG10+BK10 -> 0 | BM10: =ROUND(BE10-BK10,2) -> 3710.6 | BN10: 0 | BO10: =BE10+BN10 -> 3710.6 | BP10: =AZ10+BA10 -> 971.3 | BQ10: =AS10+AU10 -> 0 | BR10: =VLOOKUP(H10,社保公积金账单!D:D,1,0) -> 342501198810062263 | BS10: =T10-U10 -> 0
A11: 6 | B11: 江沪 | C11: 上海KA | D11: 上海 | E11: 上海 | F11: 单导长促 | G11: 张孝娟 | H11: 341226198305202763 | I11: 18221607434 | J11: NKA | K11: 直营 | L11: 欧发 | M11: 238976846 | N11: 大润发华漕店 | O11: 44568 | Q11: 2690 | R11: 4 | S11: 0 | T11: 16 | U11: 16 | V11: 0 | W11: 0 | X11: 0 | Y11: 2690 | Z11: 0 | AA11: 0 | AB11: 228.74 | AC11: 364.55556 | AD11: 1.5937552 | AE11: 2338.6667 | AF11: 382.125 | AG11: 391.66667 | AH11: 782.4375 | AI11: 0 | AJ11: 80 | AK11: 80 | AL11: 0 | AM11: 160 | AQ11: 0 | AW11: 3712.44 | AX11: 2740 | AY11: 上海合杰 | AZ11: 783.3 | BA11: 188 | BB11: 0 | BC11: =ROUND(AW11-AZ11-BA11+BB11-AA11-AK11-AT11-AM11,2) -> 2501.14 | BD11: =ROUND(IF(T11=U11,IF((BC11-BB11)<AX11,AX11-(BC11-BB11),0)),2) -> 238.86 | BE11: =ROUND(AW11-AZ11-BA11+BB11+BD11,2) -> 2980 | BF11: -5107.34 | BG11: 0 | BH11: 0 | BI11: 0 | BJ11: =ROUND(BF11+BE11-5000-(BH11-BI11),2) -> -7127.34 | BK11: =ROUND(MAX(BJ11*{0.03,0.1,0.2,0.25,0.3,0.35,0.45}-{0,2520,16920,31920,52920,85920,181920}-BG11,0),2) -> 0 | BL11: =BG11+BK11 -> 0 | BM11: =ROUND(BE11-BK11,2) -> 2980 | BN11: 0 | BO11: =BE11+BN11 -> 2980 | BP11: =AZ11+BA11 -> 971.3 | BQ11: =AS11+AU11 -> 0 | BR11: =VLOOKUP(H11,社保公积金账单!D:D,1,0) -> 341226198305202763 | BS11: =T11-U11 -> 0
A12: 7 | B12: 江沪 | C12: 上海KA | D12: 上海 | E12: 上海 | F12: 单导长促 | G12: 郭胜霞 | H12: 320925197905205821 | I12: 13764138280 | J12: NKA | K12: 直营 | L12: 欧发 | M12: 238976854 | N12: 大润发华漕店 | O12: 42736 | Q12: 2690 | R12: 9 | S12: 0 | T12: 22 | U12: 22 | V12: 0 | W12: 0 | X12: 0 | Y12: 2690 | Z12: 0 | AA12: 0 | AB12: 228.74 | AC12: 364.55556 | AD12: 1.5937552 | AE12: 2338.6667 | AF12: 382.125 | AG12: 391.66667 | AH12: 782.4375 | AI12: 0 | AJ12: 80 | AK12: 80 | AL12: 0 | AM12: 220 | AQ12: 0 | AW12: 3772.44 | AX12: 2740 | AY12: 上海合杰 | AZ12: 783.3 | BA12: 188 | BB12: 0 | BC12: =ROUND(AW12-AZ12-BA12+BB12-AA12-AK12-AT12-AM12,2) -> 2501.14 | BD12: =ROUND(IF(T12=U12,IF((BC12-BB12)<AX12,AX12-(BC12-BB12),0)),2) -> 238.86 | BE12: =ROUND(AW12-AZ12-BA12+BB12+BD12,2) -> 3040 | BF12: -4407.32 | BG12: 0 | BH12: 0 | BI12: 0 | BJ12: =ROUND(BF12+BE12-5000-(BH12-BI12),2) -> -6367.32 | BK12: =ROUND(MAX(BJ12*{0.03,0.1,0.2,0.25,0.3,0.35,0.45}-{0,2520,16920,31920,52920,85920,181920}-BG12,0),2) -> 0 | BL12: =BG12+BK12 -> 0 | BM12: =ROUND(BE12-BK12,2) -> 3040 | BN12: 0 | BO12: =BE12+BN12 -> 3040 | BP12: =AZ12+BA12 -> 971.3 | BQ12: =AS12+AU12 -> 0 | BR12: =VLOOKUP(H12,社保公积金账单!D:D,1,0) -> 320925197905205821 | BS12: =T12-U12 -> 0
A13: 8 | B13: 江沪 | C13: 上海KA | D13: 上海 | E13: 上海 | F13: 单导长促 | G13: 施美花 | H13: 310230198305175169 | I13: 13795364351 | J13: NKA | K13: 直营 | L13: 欧发 | M13: 238976864 | N13: 大润发康桥店 | O13: 43611 | Q13: 2690 | R13: 6 | S13: 0 | T13: 22 | U13: 22 | V13: 0 | W13: 0 | X13: 0 | Y13: 2690 | Z13: 0 | AA13: 0 | AB13: 286.2 | AC13: 347.08333 | AD13: 1.21273 | AE13: 2799.6667 | AF13: 0 | AG13: 529.20833 | AH13: 1135.2292 | AI13: 0 | AJ13: 80 | AK13: 80 | AL13: 0 | AM13: 220 | AQ13: 0 | AW13: 4125.23 | AX13: 2740 | AY13: 上海合杰 | AZ13: 783.3 | BA13: 188 | BB13: 0 | BC13: =ROUND(AW13-AZ13-BA13+BB13-AA13-AK13-AT13-AM13,2) -> 2853.93 | BD13: =ROUND(IF(T13=U13,IF((BC13-BB13)<AX13,AX13-(BC13-BB13),0)),2) -> 0 | BE13: =ROUND(AW13-AZ13-BA13+BB13+BD13,2) -> 3153.93 | BF13: -4474.9 | BG13: 0 | BH13: 0 | BI13: 0 | BJ13: =ROUND(BF13+BE13-5000-(BH13-BI13),2) -> -6320.97 | BK13: =ROUND(MAX(BJ13*{0.03,0.1,0.2,0.25,0.3,0.35,0.45}-{0,2520,16920,31920,52920,85920,181920}-BG13,0),2) -> 0 | BL13: =BG13+BK13 -> 0 | BM13: =ROUND(BE13-BK13,2) -> 3153.93 | BN13: 0 | BO13: =BE13+BN13 -> 3153.93 | BP13: =AZ13+BA13 -> 971.3 | BQ13: =AS13+AU13 -> 0 | BR13: =VLOOKUP(H13,社保公积金账单!D:D,1,0) -> 310230198305175169 | BS13: =T13-U13 -> 0
A14: 9 | B14: 江沪 | C14: 上海KA | D14: 上海 | E14: 上海 | F14: 单导长促 | G14: 孙艳 | H14: 34120319890120316X | I14: 15021248502 | J14: NKA | K14: 直营 | L14: 欧发 | M14: 238976864 | N14: 大润发康桥店 | O14: 44721 | Q14: 2690 | R14: 3 | S14: 0 | T14: 16 | U14: 16 | V14: 0 | W14: 0 | X14: 0 | Y14: 2690 | Z14: 0 | AA14: 0 | AB14: 286.2 | AC14: 347.08333 | AD14: 1.21273 | AE14: 2799.6667 | AF14: 0 | AG14: 529.20833 | AH14: 1135.2292 | AI14: 0 | AJ14: 80 | AK14: 80 | AL14: 0 | AM14: 160 | AQ14: 0 | AW14: 4065.23 | AX14: 2740 | AY14: 上海合杰 | AZ14: 783.3 | BA14: 188 | BB14: 0 | BC14: =ROUND(AW14-AZ14-BA14+BB14-AA14-AK14-AT14-AM14,2) -> 2853.93 | BD14: =ROUND(IF(T14=U14,IF((BC14-BB14)<AX14,AX14-(BC14-BB14),0)),2) -> 0 | BE14: =ROUND(AW14-AZ14-BA14+BB14+BD14,2) -> 3093.93 | BF14: -4192.85 | BG14: 0 | BH14: 0 | BI14: 0 | BJ14: =ROUND(BF14+BE14-5000-(BH14-BI14),2) -> -6098.92 | BK14: =ROUND(MAX(BJ14*{0.03,0.1,0.2,0.25,0.3,0.35,0.45}-{0,2520,16920,31920,52920,85920,181920}-BG14,0),2) -> 0 | BL14: =BG14+BK14 -> 0 | BM14: =ROUND(BE14-BK14,2) -> 3093.93 | BN14: 0 | BO14: =BE14+BN14 -> 3093.93 | BP14: =AZ14+BA14 -> 971.3 | BQ14: =AS14+AU14 -> 0 | BR14: =VLOOKUP(H14,社保公积金账单!D:D,1,0) -> 34120319890120316X | BS14: =T14-U14 -> 0
A15: 10 | B15: 江沪 | C15: 上海KA | D15: 上海 | E15: 上海 | F15: 单导长促 | G15: 董燕芳 | H15: 31022519780512504X | I15: 13917656516 | J15: NKA | K15: 直营 | L15: 欧发 | M15: 238976870 | N15: 大润发泥城店 | O15: 44958 | Q15: 2690 | R15: 3 | S15: 0 | T15: 16 | U15: 16 | V15: 0 | W15: 0 | X15: 0 | Y15: 2690 | Z15: 0 | AA15: 0 | AB15: 164.93 | AC15: 151.61111 | AD15: 0.9192452 | AE15: 1023.3333 | AF15: 0 | AG15: 161.125 | AH15: 862.20833 | AI15: 0 | AJ15: 80 | AK15: 80 | AL15: 0 | AM15: 160 | AQ15: 0 | AW15: 3792.21 | AX15: 2740 | AY15: 上海合杰 | AZ15: 783.3 | BA15: 188 | BB15: 0 | BC15: =ROUND(AW15-AZ15-BA15+BB15-AA15-AK15-AT15-AM15,2) -> 2580.91 | BD15: =ROUND(IF(T15=U15,IF((BC15-BB15)<AX15,AX15-(BC15-BB15),0)),2) -> 159.09 | BE15: =ROUND(AW15-AZ15-BA15+BB15+BD15,2) -> 2980 | BF15: -3584.73 | BG15: 0 | BH15: 0 | BI15: 0 | BJ15: =ROUND(BF15+BE15-5000-(BH15-BI15),2) -> -5604.73 | BK15: =ROUND(MAX(BJ15*{0.03,0.1,0.2,0.25,0.3,0.35,0.45}-{0,2520,16920,31920,52920,85920,181920}-BG15,0),2) -> 0 | BL15: =BG15+BK15 -> 0 | BM15: =ROUND(BE15-BK15,2) -> 2980 | BN15: 0 | BO15: =BE15+BN15 -> 2980 | BP15: =AZ15+BA15 -> 971.3 | BQ15: =AS15+AU15 -> 0 | BR15: =VLOOKUP(H15,社保公积金账单!D:D,1,0) -> 31022519780512504X | BS15: =T15-U15 -> 0
A16: 11 | B16: 江沪 | C16: 上海KA | D16: 上海 | E16: 上海 | F16: 单导长促 | G16: 过苗苗 | H16: 341224198812281328 | I16: 18221675997 | J16: NKA | K16: 直营 | L16: 欧发 | M16: 238976860 | N16: 大润发平型关店 | O16: 44348 | Q16: 2690 | R16: 4 | S16: 0 | T16: 16 | U16: 16 | V16: 0 | W16: 0 | X16: 0 | Y16: 2690 | Z16: 0 | AA16: 0 | AB16: 162.04 | AC16: 248.13889 | AD16: 1.5313434 | AE16: 1702.8333 | AF16: 0 | AG16: 187.45833 | AH16: 1515.375 | AI16: 0 | AJ16: 80 | AK16: 80 | AL16: 0 | AM16: 140 | AQ16: 0 | AW16: 4425.38 | AX16: 2740 | AY16: 上海合杰 | AZ16: 783.3 | BA16: 188 | BB16: 0 | BC16: =ROUND(AW16-AZ16-BA16+BB16-AA16-AK16-AT16-AM16,2) -> 3234.08 | BD16: =ROUND(IF(T16=U16,IF((BC16-BB16)<AX16,AX16-(BC16-BB16),0)),2) -> 0 | BE16: =ROUND(AW16-AZ16-BA16+BB16+BD16,2) -> 3454.08 | BF16: -3857.34 | BG16: 0 | BH16: 0 | BI16: 0 | BJ16: =ROUND(BF16+BE16-5000-(BH16-BI16),2) -> -5403.26 | BK16: =ROUND(MAX(BJ16*{0.03,0.1,0.2,0.25,0.3,0.35,0.45}-{0,2520,16920,31920,52920,85920,181920}-BG16,0),2) -> 0 | BL16: =BG16+BK16 -> 0 | BM16: =ROUND(BE16-BK16,2) -> 3454.08 | BN16: 0 | BO16: =BE16+BN16 -> 3454.08 | BP16: =AZ16+BA16 -> 971.3 | BQ16: =AS16+AU16 -> 0 | BR16: =VLOOKUP(H16,社保公积金账单!D:D,1,0) -> 341224198812281328 | BS16: =T16-U16 -> 0
A17: 12 | B17: 江沪 | C17: 上海KA | D17: 上海 | E17: 上海 | F17: 单导长促 | G17: 戈艳青 | H17: 32082319780513524X | I17: 13918265808 | J17: NKA | K17: 直营 | L17: 欧发 | M17: 238976844 | N17: 大润发泗泾店 | O17: 41738 | Q17: 2690 | R17: 11 | S17: 0 | T17: 16 | U17: 16 | V17: 0 | W17: 0 | X17: 0 | Y17: 2690 | Z17: 0 | AA17: 0 | AB17: 215.49 | AC17: 268.80556 | AD17: 1.2474155 | AE17: 1773.1667 | AF17: -154 | AG17: 326.29167 | AH17: 800.4375 | AI17: 0 | AJ17: 80 | AK17: 80 | AL17: 0 | AM17: 160 | AQ17: 0 | AW17: 3730.44 | AX17: 2740 | AY17: 上海合杰 | AZ17: 783.3 | BA17: 188 | BB17: 0 | BC17: =ROUND(AW17-AZ17-BA17+BB17-AA17-AK17-AT17-AM17,2) -> 2519.14 | BD17: =ROUND(IF(T17=U17,IF((BC17-BB17)<AX17,AX17-(BC17-BB17),0)),2) -> 220.86 | BE17: =ROUND(AW17-AZ17-BA17+BB17+BD17,2) -> 2980 | BF17: -5470.7 | BG17: 0 | BH17: 0 | BI17: 0 | BJ17: =ROUND(BF17+BE17-5000-(BH17-BI17),2) -> -7490.7 | BK17: =ROUND(MAX(BJ17*{0.03,0.1,0.2,0.25,0.3,0.35,0.45}-{0,2520,16920,31920,52920,85920,181920}-BG17,0),2) -> 0 | BL17: =BG17+BK17 -> 0 | BM17: =ROUND(BE17-BK17,2) -> 2980 | BN17: 0 | BO17: =BE17+BN17 -> 2980 | BP17: =AZ17+BA17 -> 971.3 | BQ17: =AS17+AU17 -> 0 | BR17: =VLOOKUP(H17,社保公积金账单!D:D,1,0) -> 32082319780513524X | BS17: =T17-U17 -> 0
A18: 13 | B18: 江沪 | C18: 上海KA | D18: 上海 | E18: 上海 | F18: 单导长促 | G18: 杜以花 | H18: 371122198002227829 | I18: 13917635644 | J18: NKA | K18: 直营 | L18: 欧发 | M18: 238976844 | N18: 大润发泗泾店 | O18: 44743 | Q18: 2690 | R18: 3 | S18: 0 | T18: 22 | U18: 19 | V18: 3 | W18: 0 | X18: 261.54545 | Y18: 2584.7273 | Z18: 0 | AA18: 0 | AB18: 215.49 | AC18: 268.80556 | AD18: 1.2474155 | AE18: 1773.1667 | AF18: -154 | AG18: 326.29167 | AH18: 800.44 | AI18: 0 | AJ18: 69.090909 | AK18: 69.090909 | AL18: 0 | AM18: 190 | AQ18: 0 | AW18: 3644.26 | AX18: 2740 | AY18: 上海合杰 | AZ18: 783.3 | BA18: 188 | BB18: 0 | BC18: =ROUND(AW18-AZ18-BA18+BB18-AA18-AK18-AT18-AM18,2) -> 2413.87 | BD18: =ROUND(IF(T18=U18,IF((BC18-BB18)<AX18,AX18-(BC18-BB18),0)),2) -> 0 | BE18: =ROUND(AW18-AZ18-BA18+BB18+BD18,2) -> 2672.96 | BF18: -6222.04 | BG18: 0 | BH18: 0 | BI18: 0 | BJ18: =ROUND(BF18+BE18-5000-(BH18-BI18),2) -> -8549.08 | BK18: =ROUND(MAX(BJ18*{0.03,0.1,0.2,0.25,0.3,0.35,0.45}-{0,2520,16920,31920,52920,85920,181920}-BG18,0),2) -> 0 | BL18: =BG18+BK18 -> 0 | BM18: =ROUND(BE18-BK18,2) -> 2672.96 | BN18: 0 | BO18: =BE18+BN18 -> 2672.96 | BP18: =AZ18+BA18 -> 971.3 | BQ18: =AS18+AU18 -> 0 | BR18: =VLOOKUP(H18,社保公积金账单!D:D,1,0) -> 371122198002227829 | BS18: =T18-U18 -> 3
A19: 14 | B19: 江沪 | C19: 上海KA | D19: 上海 | E19: 上海 | F19: 单导长促 | G19: 车文秀 | H19: 341623199710154424 | I19: 15801898274 | J19: NKA | K19: 直营 | L19: 欧发 | M19: 238976838 | N19: 大润发松江店 | O19: 43412 | Q19: 2690 | R19: 7 | S19: 0 | T19: 16 | U19: 16 | V19: 0 | W19: 0 | X19: 0 | Y19: 2690 | Z19: 0 | AA19: 0 | AB19: 668.32 | AC19: 710.91667 | AD19: 1.0637369 | AE19: 6292.3333 | AF19: -343.125 | AG19: 975.66667 | AH19: 2829.8958 | AI19: 0 | AJ19: 80 | AK19: 80 | AL19: 0 | AM19: 160 | AQ19: 0 | AW19: 5759.9 | AX19: 2740 | AY19: 上海合杰 | AZ19: 783.3 | BA19: 188 | BB19: 0 | BC19: =ROUND(AW19-AZ19-BA19+BB19-AA19-AK19-AT19-AM19,2) -> 4548.6 | BD19: =ROUND(IF(T19=U19,IF((BC19-BB19)<AX19,AX19-(BC19-BB19),0)),2) -> 0 | BE19: =ROUND(AW19-AZ19-BA19+BB19+BD19,2) -> 4788.6 | BF19: 2709.46 | BG19: 81.28 | BH19: 0 | BI19: 0 | BJ19: =ROUND(BF19+BE19-5000-(BH19-BI19),2) -> 2498.06 | BK19: =ROUND(MAX(BJ19*{0.03,0.1,0.2,0.25,0.3,0.35,0.45}-{0,2520,16920,31920,52920,85920,181920}-BG19,0),2) -> 0 | BL19: =BG19+BK19 -> 81.28 | BM19: =ROUND(BE19-BK19,2) -> 4788.6 | BN19: 0 | BO19: =BE19+BN19 -> 4788.6 | BP19: =AZ19+BA19 -> 971.3 | BQ19: =AS19+AU19 -> 0 | BR19: =VLOOKUP(H19,社保公积金账单!D:D,1,0) -> 341623199710154424 | BS19: =T19-U19 -> 0
A20: 15 | B20: 江沪 | C20: 上海KA | D20: 上海 | E20: 上海 | F20: 单导长促 | G20: 魏永慧 | H20: 511121197511274186 | I20: 15601859520 | J20: NKA | K20: 直营 | L20: 欧发 | M20: 238976838 | N20: 大润发松江店 | O20: 44323 | Q20: 2690 | R20: 4 | S20: 0 | T20: 22 | U20: 22 | V20: 0 | W20: 0 | X20: 0 | Y20: 2690 | Z20: 0 | AA20: 0 | AB20: 668.32 | AC20: 710.91667 | AD20: 1.0637369 | AE20: 6292.3333 | AF20: -343.125 | AG20: 975.66667 | AH20: 2829.8958 | AI20: 0 | AJ20: 80 | AK20: 80 | AL20: 0 | AM20: 220 | AQ20: 0 | AW20: 5819.9 | AX20: 2740 | AY20: 上海合杰 | AZ20: 783.3 | BA20: 188 | BB20: 0 | BC20: =ROUND(AW20-AZ20-BA20+BB20-AA20-AK20-AT20-AM20,2) -> 4548.6 | BD20: =ROUND(IF(T20=U20,IF((BC20-BB20)<AX20,AX20-(BC20-BB20),0)),2) -> 0 | BE20: =ROUND(AW20-AZ20-BA20+BB20+BD20,2) -> 4848.6 | BF20: 3025.23 | BG20: 90.76 | BH20: 0 | BI20: 0 | BJ20: =ROUND(BF20+BE20-5000-(BH20-BI20),2) -> 2873.83 | BK20: =ROUND(MAX(BJ20*{0.03,0.1,0.2,0.25,0.3,0.35,0.45}-{0,2520,16920,31920,52920,85920,181920}-BG20,0),2) -> 0 | BL20: =BG20+BK20 -> 90.76 | BM20: =ROUND(BE20-BK20,2) -> 4848.6 | BN20: 0 | BO20: =BE20+BN20 -> 4848.6 | BP20: =AZ20+BA20 -> 971.3 | BQ20: =AS20+AU20 -> 0 | BR20: =VLOOKUP(H20,社保公积金账单!D:D,1,0) -> 511121197511274186 | BS20: =T20-U20 -> 0
A21: 16 | B21: 江沪 | C21: 上海KA | D21: 上海 | E21: 上海 | F21: 单导长促 | G21: 李永杰 | H21: 410923198302047231 | I21: 15286921996 | J21: NKA | K21: 直营 | L21: 欧发 | M21: 238976858 | N21: 大润发杨浦店 | O21: 43476 | Q21: 2690 | R21: 7 | S21: 0 | T21: 16 | U21: 16 | V21: 0 | W21: 0 | X21: 0 | Y21: 2690 | Z21: 0 | AA21: 0 | AB21: 214.35 | AC21: 323.5 | AD21: 1.5092139 | AE21: 2596.1667 | AF21: 0 | AG21: 483.20833 | AH21: 845.18333 | AI21: 0 | AJ21: 80 | AK21: 80 | AL21: 0 | AM21: 160 | AQ21: 0 | AW21: 3775.18 | AX21: 2740 | AY21: 上海合杰 | AZ21: 783.3 | BA21: 188 | BB21: 0 | BC21: =ROUND(AW21-AZ21-BA21+BB21-AA21-AK21-AT21-AM21,2) -> 2563.88 | BD21: =ROUND(IF(T21=U21,IF((BC21-BB21)<AX21,AX21-(BC21-BB21),0)),2) -> 176.12 | BE21: =ROUND(AW21-AZ21-BA21+BB21+BD21,2) -> 2980 | BF21: -5945.56 | BG21: 0 | BH21: 0 | BI21: 0 | BJ21: =ROUND(BF21+BE21-5000-(BH21-BI21),2) -> -7965.56 | BK21: =ROUND(MAX(BJ21*{0.03,0.1,0.2,0.25,0.3,0.35,0.45}-{0,2520,16920,31920,52920,85920,181920}-BG21,0),2) -> 0 | BL21: =BG21+BK21 -> 0 | BM21: =ROUND(BE21-BK21,2) -> 2980 | BN21: 0 | BO21: =BE21+BN21 -> 2980 | BP21: =AZ21+BA21 -> 971.3 | BQ21: =AS21+AU21 -> 0 | BR21: =VLOOKUP(H21,社保公积金账单!D:D,1,0) -> 410923198302047231 | BS21: =T21-U21 -> 0
A22: 17 | B22: 江沪 | C22: 上海KA | D22: 上海 | E22: 上海 | F22: 单导长促 | G22: 姚友美 | H22: 34122619830430352X | I22: 17355881696 | J22: NKA | K22: 直营 | L22: 欧发 | M22: 238976888 | N22: 大润发杨浦店 | O22: 44835 | Q22: 2690 | R22: 3 | S22: 0 | T22: 27 | U22: 27 | V22: 0 | W22: 0 | X22: 0 | Y22: 2690 | Z22: 0 | AA22: 0 | AB22: 214.35 | AC22: 323.5 | AD22: 1.5092139 | AE22: 2596.1667 | AF22: 0 | AG22: 483.20833 | AH22: 1267.775 | AI22: 0 | AJ22: 80 | AK22: 80 | AL22: 0 | AM22: 270 | AQ22: 0 | AW22: 4307.78 | AX22: 2740 | AY22: 上海合杰 | AZ22: 783.3 | BA22: 188 | BB22: 0 | BC22: =ROUND(AW22-AZ22-BA22+BB22-AA22-AK22-AT22-AM22,2) -> 2986.48 | BD22: =ROUND(IF(T22=U22,IF((BC22-BB22)<AX22,AX22-(BC22-BB22),0)),2) -> 0 | BE22: =ROUND(AW22-AZ22-BA22+BB22+BD22,2) -> 3336.48 | BF22: -4193.34 | BG22: 0 | BH22: 0 | BI22: 0 | BJ22: =ROUND(BF22+BE22-5000-(BH22-BI22),2) -> -5856.86 | BK22: =ROUND(MAX(BJ22*{0.03,0.1,0.2,0.25,0.3,0.35,0.45}-{0,2520,16920,31920,52920,85920,181920}-BG22,0),2) -> 0 | BL22: =BG22+BK22 -> 0 | BM22: =ROUND(BE22-BK22,2) -> 3336.48 | BN22: 0 | BO22: =BE22+BN22 -> 3336.48 | BP22: =AZ22+BA22 -> 971.3 | BQ22: =AS22+AU22 -> 0 | BR22: =VLOOKUP(H22,社保公积金账单!D:D,1,0) -> 34122619830430352X | BS22: =T22-U22 -> 0
A23: 18 | B23: 江沪 | C23: 上海KA | D23: 上海 | E23: 上海 | F23: 单导长促 | G23: 王丽莉 | H23: 342423197609202840 | I23: 15801729382 | J23: NKA | K23: 直营 | L23: 欧发 | M23: 238976866 | N23: 大润发大宁店 | O23: 43952 | Q23: 2690 | R23: 5 | S23: 0 | T23: 15 | U23: 13 | V23: 0 | W23: 2 | X23: 0 | Y23: 2331.3333 | Z23: 0 | AA23: 0 | AB23: 93.67 | AC23: 193 | AD23: 2.0604249 | AE23: 1428.25 | AF23: 0 | AG23: 181.91667 | AH23: 1246.33 | AI23: 0 | AJ23: 69.333333 | AK23: 69.333333 | AL23: 0 | AM23: 130 | AQ23: 0 | AW23: 3777 | AX23: 2740 | AY23: 上海合杰 | AZ23: 783.3 | BA23: 188 | BB23: 0 | BC23: =ROUND(AW23-AZ23-BA23+BB23-AA23-AK23-AT23-AM23,2) -> 2606.37 | BD23: =ROUND(IF(T23=U23,IF((BC23-BB23)<AX23,AX23-(BC23-BB23),0)),2) -> 0 | BE23: =ROUND(AW23-AZ23-BA23+BB23+BD23,2) -> 2805.7 | BF23: -3221.73 | BG23: 0 | BH23: 0 | BI23: 0 | BJ23: =ROUND(BF23+BE23-5000-(BH23-BI23),2) -> -5416.03 | BK23: =ROUND(MAX(BJ23*{0.03,0.1,0.2,0.25,0.3,0.35,0.45}-{0,2520,16920,31920,52920,85920,181920}-BG23,0),2) -> 0 | BL23: =BG23+BK23 -> 0 | BM23: =ROUND(BE23-BK23,2) -> 2805.7 | BN23: 0 | BO23: =BE23+BN23 -> 2805.7 | BP23: =AZ23+BA23 -> 971.3 | BQ23: =AS23+AU23 -> 0 | BR23: =VLOOKUP(H23,社保公积金账单!D:D,1,0) -> 342423197609202840 | BS23: =T23-U23 -> 2
A24: 19 | B24: 江沪 | C24: 上海KA | D24: 上海 | E24: 上海 | F24: 单导长促 | G24: 黄莹 | H24: 370481198807021823 | I24: 13585585049 | J24: NKA | K24: 直营 | L24: 欧发 | M24: 238976868 | N24: 大润发美兰湖店 | O24: 43333 | Q24: 2690 | R24: 7 | S24: 0 | T24: 16 | U24: 16 | V24: 0 | W24: 0 | X24: 0 | Y24: 2690 | Z24: 0 | AA24: 0 | AB24: 246.53 | AC24: 350.41667 | AD24: 1.4213956 | AE24: 2156.5833 | AF24: 0 | AG24: 281.20833 | AH24: 1875.375 | AI24: 0 | AJ24: 80 | AK24: 80 | AL24: 0 | AM24: 160 | AQ24: 0 | AW24: 4805.38 | AX24: 2740 | AY24: 上海合杰 | AZ24: 783.3 | BA24: 188 | BB24: 0 | BC24: =ROUND(AW24-AZ24-BA24+BB24-AA24-AK24-AT24-AM24,2) -> 3594.08 | BD24: =ROUND(IF(T24=U24,IF((BC24-BB24)<AX24,AX24-(BC24-BB24),0)),2) -> 0 | BE24: =ROUND(AW24-AZ24-BA24+BB24+BD24,2) -> 3834.08 | BF24: -692.73 | BG24: 4.15 | BH24: 0 | BI24: 0 | BJ24: =ROUND(BF24+BE24-5000-(BH24-BI24),2) -> -1858.65 | BK24: =ROUND(MAX(BJ24*{0.03,0.1,0.2,0.25,0.3,0.35,0.45}-{0,2520,16920,31920,52920,85920,181920}-BG24,0),2) -> 0 | BL24: =BG24+BK24 -> 4.15 | BM24: =ROUND(BE24-BK24,2) -> 3834.08 | BN24: 0 | BO24: =BE24+BN24 -> 3834.08 | BP24: =AZ24+BA24 -> 971.3 | BQ24: =AS24+AU24 -> 0 | BR24: =VLOOKUP(H24,社保公积金账单!D:D,1,0) -> 370481198807021823 | BS24: =T24-U24 -> 0
A25: 20 | B25: 江沪 | C25: 上海KA | D25: 上海 | E25: 上海 | F25: 单导长促 | G25: 刘宝连 | H25: 413026197908287553 | I25: 13671903482 | J25: NKA | K25: 直营 | L25: 欧发 | M25: 238976854 | N25: 大润发大华店 | O25: 42353 | Q25: 2690 | R25: 10 | S25: 0 | T25: 15 | U25: 15 | V25: 0 | W25: 0 | X25: 0 | Y25: 2690 | Z25: 0 | AA25: 0 | AB25: 182.17 | AC25: 255.94444 | AD25: 1.4049758 | AE25: 1625.4167 | AF25: 210 | AG25: 264.58333 | AH25: 1150.8333 | AI25: 0 | AJ25: 80 | AK25: 80 | AL25: 0 | AM25: 120 | AQ25: 0 | AW25: 4040.83 | AX25: 2740 | AY25: 上海合杰 | AZ25: 783.3 | BA25: 188 | BB25: 0 | BC25: =ROUND(AW25-AZ25-BA25+BB25-AA25-AK25-AT25-AM25,2) -> 2869.53 | BD25: =ROUND(IF(T25=U25,IF((BC25-BB25)<AX25,AX25-(BC25-BB25),0)),2) -> 0 | BE25: =ROUND(AW25-AZ25-BA25+BB25+BD25,2) -> 3069.53 | BF25: -3544.99 | BG25: 0 | BH25: 0 | BI25: 0 | BJ25: =ROUND(BF25+BE25-5000-(BH25-BI25),2) -> -5475.46 | BK25: =ROUND(MAX(BJ25*{0.03,0.1,0.2,0.25,0.3,0.35,0.45}-{0,2520,16920,31920,52920,85920,181920}-BG25,0),2) -> 0 | BL25: =BG25+BK25 -> 0 | BM25: =ROUND(BE25-BK25,2) -> 3069.53 | BN25: 0 | BO25: =BE25+BN25 -> 3069.53 | BP25: =AZ25+BA25 -> 971.3 | BQ25: =AS25+AU25 -> 0 | BR25: =VLOOKUP(H25,社保公积金账单!D:D,1,0) -> 413026197908287553 | BS25: =T25-U25 -> 0
A26: 21 | B26: 江沪 | C26: 上海KA | D26: 上海 | E26: 上海 | F26: 单导长促 | G26: 过小娟 | H26: 341622198311041341 | I26: 17717590761 | J26: NKA | K26: 直营 | L26: 欧发 | M26: 238976852 | N26: 大润发南翔店 | O26: 45545 | Q26: 2690 | R26: 1 | S26: 0 | T26: 15 | U26: 15 | V26: 0 | W26: 0 | X26: 0 | Y26: 2690 | Z26: 0 | AA26: 0 | AB26: 129.3 | AC26: 183.36111 | AD26: 1.418106 | AE26: 1228.0833 | AF26: 0 | AG26: 264.125 | AH26: 963.95833 | AI26: 0 | AJ26: 80 | AK26: 80 | AL26: 0 | AM26: 150 | AQ26: 0 | AW26: 3883.96 | AX26: 2740 | AY26: 上海合杰 | AZ26: 783.3 | BA26: 188 | BB26: 0 | BC26: =ROUND(AW26-AZ26-BA26+BB26-AA26-AK26-AT26-AM26,2) -> 2682.66 | BD26: =ROUND(IF(T26=U26,IF((BC26-BB26)<AX26,AX26-(BC26-BB26),0)),2) -> 57.34 | BE26: =ROUND(AW26-AZ26-BA26+BB26+BD26,2) -> 2970 | BF26: -4817.53 | BG26: 0 | BH26: 0 | BI26: 0 | BJ26: =ROUND(BF26+BE26-5000-(BH26-BI26),2) -> -6847.53 | BK26: =ROUND(MAX(BJ26*{0.03,0.1,0.2,0.25,0.3,0.35,0.45}-{0,2520,16920,31920,52920,85920,181920}-BG26,0),2) -> 0 | BL26: =BG26+BK26 -> 0 | BM26: =ROUND(BE26-BK26,2) -> 2970 | BN26: 0 | BO26: =BE26+BN26 -> 2970 | BP26: =AZ26+BA26 -> 971.3 | BQ26: =AS26+AU26 -> 0 | BR26: =VLOOKUP(H26,社保公积金账单!D:D,1,0) -> 341622198311041341 | BS26: =T26-U26 -> 0
A27: 22 | B27: 江沪 | C27: 上海KA | D27: 上海 | E27: 上海 | F27: 单导长促 | G27: 严洪玉 | H27: 320882197404083426 | I27: 15902185361 | J27: NKA | K27: 直营 | L27: 欧发 | M27: 238976862 | N27: 大润发三林店 | O27: 44501 | Q27: 2690 | R27: 4 | S27: 0 | T27: 15 | U27: 15 | V27: 0 | W27: 0 | X27: 0 | Y27: 2690 | Z27: 6 | AA27: 755.86207 | AB27: 199.99 | AC27: 275.5 | AD27: 1.3775689 | AE27: 1932 | AF27: 37.5 | AG27: 343.58333 | AH27: 1550.9167 | AI27: 0 | AJ27: 80 | AK27: 80 | AL27: 0 | AM27: 150 | AQ27: 0 | AW27: 5226.78 | AX27: 2740 | AY27: 上海合杰 | AZ27: 783.3 | BA27: 188 | BB27: 0 | BC27: =ROUND(AW27-AZ27-BA27+BB27-AA27-AK27-AT27-AM27,2) -> 3269.62 | BD27: =ROUND(IF(T27=U27,IF((BC27-BB27)<AX27,AX27-(BC27-BB27),0)),2) -> 0 | BE27: =ROUND(AW27-AZ27-BA27+BB27+BD27,2) -> 4255.48 | BF27: -1217.85 | BG27: 0 | BH27: 0 | BI27: 0 | BJ27: =ROUND(BF27+BE27-5000-(BH27-BI27),2) -> -1962.37 | BK27: =ROUND(MAX(BJ27*{0.03,0.1,0.2,0.25,0.3,0.35,0.45}-{0,2520,16920,31920,52920,85920,181920}-BG27,0),2) -> 0 | BL27: =BG27+BK27 -> 0 | BM27: =ROUND(BE27-BK27,2) -> 4255.48 | BN27: 0 | BO27: =BE27+BN27 -> 4255.48 | BP27: =AZ27+BA27 -> 971.3 | BQ27: =AS27+AU27 -> 0 | BR27: =VLOOKUP(H27,社保公积金账单!D:D,1,0) -> 320882197404083426 | BS27: =T27-U27 -> 0
A28: 23 | B28: 江沪 | C28: 上海KA | D28: 上海 | E28: 上海 | F28: 单导长促 | G28: 孟书丽 | H28: 511023197705278588 | I28: 15800379800 | J28: NKA | K28: 直营 | L28: 欧发 | M28: 238976856 | N28: 大润发闸北店 | O28: 44287 | Q28: 2690 | R28: 4 | S28: 0 | T28: 22 | U28: 22 | V28: 0 | W28: 0 | X28: 0 | Y28: 2690 | Z28: 0 | AA28: 0 | AB28: 293.65 | AC28: 434.66667 | AD28: 1.4802202 | AE28: 2929.8333 | AF28: 0 | AG28: 521.41667 | AH28: 1728.4167 | AI28: 0 | AJ28: 80 | AK28: 80 | AL28: 0 | AM28: 190 | AQ28: 0 | AW28: 4688.42 | AX28: 2740 | AY28: 上海合杰 | AZ28: 783.3 | BA28: 188 | BB28: 0 | BC28: =ROUND(AW28-AZ28-BA28+BB28-AA28-AK28-AT28-AM28,2) -> 3447.12 | BD28: =ROUND(IF(T28=U28,IF((BC28-BB28)<AX28,AX28-(BC28-BB28),0)),2) -> 0 | BE28: =ROUND(AW28-AZ28-BA28+BB28+BD28,2) -> 3717.12 | BF28: -1623.27 | BG28: 0 | BH28: 0 | BI28: 0 | BJ28: =ROUND(BF28+BE28-5000-(BH28-BI28),2) -> -2906.15 | BK28: =ROUND(MAX(BJ28*{0.03,0.1,0.2,0.25,0.3,0.35,0.45}-{0,2520,16920,31920,52920,85920,181920}-BG28,0),2) -> 0 | BL28: =BG28+BK28 -> 0 | BM28: =ROUND(BE28-BK28,2) -> 3717.12 | BN28: 0 | BO28: =BE28+BN28 -> 3717.12 | BP28: =AZ28+BA28 -> 971.3 | BQ28: =AS28+AU28 -> 0 | BR28: =VLOOKUP(H28,社保公积金账单!D:D,1,0) -> 511023197705278588 | BS28: =T28-U28 -> 0
A29: 24 | B29: 江沪 | C29: 上海KA | D29: 上海 | E29: 上海 | F29: 单导长促 | G29: 管兵娥 | H29: 362329198211245745 | I29: 15800762272 | J29: NKA | K29: 直营 | L29: 欧发 | M29: 238976862 | N29: 大润发安亭店 | O29: 39548 | Q29: 2690 | R29: 17 | S29: 0 | T29: 15 | U29: 15 | V29: 0 | W29: 0 | X29: 0 | Y29: 2690 | Z29: 0 | AA29: 0 | AB29: 141.35 | AC29: 259 | AD29: 1.8323311 | AE29: 1736.5 | AF29: 0 | AG29: 197.66667 | AH29: 1538.8333 | AI29: 0 | AJ29: 80 | AK29: 80 | AL29: 0 | AM29: 150 | AQ29: 0 | AW29: 4458.83 | AX29: 2740 | AY29: 上海合杰 | AZ29: 783.3 | BA29: 188 | BB29: 0 | BC29: =ROUND(AW29-AZ29-BA29+BB29-AA29-AK29-AT29-AM29,2) -> 3257.53 | BD29: =ROUND(IF(T29=U29,IF((BC29-BB29)<AX29,AX29-(BC29-BB29),0)),2) -> 0 | BE29: =ROUND(AW29-AZ29-BA29+BB29+BD29,2) -> 3487.53 | BF29: -2059.14 | BG29: 0 | BH29: 0 | BI29: 0 | BJ29: =ROUND(BF29+BE29-5000-(BH29-BI29),2) -> -3571.61 | BK29: =ROUND(MAX(BJ29*{0.03,0.1,0.2,0.25,0.3,0.35,0.45}-{0,2520,16920,31920,52920,85920,181920}-BG29,0),2) -> 0 | BL29: =BG29+BK29 -> 0 | BM29: =ROUND(BE29-BK29,2) -> 3487.53 | BN29: 0 | BO29: =BE29+BN29 -> 3487.53 | BP29: =AZ29+BA29 -> 971.3 | BQ29: =AS29+AU29 -> 0 | BR29: =VLOOKUP(H29,社保公积金账单!D:D,1,0) -> 362329198211245745 | BS29: =T29-U29 -> 0
A30: 25 | B30: 江沪 | C30: 上海KA | D30: 上海 | E30: 上海 | F30: 单导长促 | G30: 李春霞 | H30: 340222197807066625 | I30: 15821963037 | J30: NKA | K30: 直营 | L30: 欧发 | M30: 238976898 | N30: 欧尚澄浏店 | O30: 43160 | Q30: 2690 | R30: 8 | S30: 0 | T30: 16 | U30: 16 | V30: 0 | W30: 0 | X30: 0 | Y30: 2690 | Z30: 0 | AA30: 0 | AB30: 183.89 | AC30: 239.69444 | AD30: 1.3034664 | AE30: 1644.9167 | AF30: 467 | AG30: 177.375 | AH30: 1000.5417 | AI30: 0 | AJ30: 80 | AK30: 80 | AL30: 0 | AM30: 160 | AQ30: 0 | AW30: 3930.54 | AX30: 2740 | AY30: 上海合杰 | AZ30: 783.3 | BA30: 188 | BB30: 0 | BC30: =ROUND(AW30-AZ30-BA30+BB30-AA30-AK30-AT30-AM30,2) -> 2719.24 | BD30: =ROUND(IF(T30=U30,IF((BC30-BB30)<AX30,AX30-(BC30-BB30),0)),2) -> 20.76 | BE30: =ROUND(AW30-AZ30-BA30+BB30+BD30,2) -> 2980 | BF30: -2647.26 | BG30: 0 | BH30: 1600 | BI30: 1200 | BJ30: =ROUND(BF30+BE30-5000-(BH30-BI30),2) -> -5067.26 | BK30: =ROUND(MAX(BJ30*{0.03,0.1,0.2,0.25,0.3,0.35,0.45}-{0,2520,16920,31920,52920,85920,181920}-BG30,0),2) -> 0 | BL30: =BG30+BK30 -> 0 | BM30: =ROUND(BE30-BK30,2) -> 2980 | BN30: 0 | BO30: =BE30+BN30 -> 2980 | BP30: =AZ30+BA30 -> 971.3 | BQ30: =AS30+AU30 -> 0 | BR30: =VLOOKUP(H30,社保公积金账单!D:D,1,0) -> 340222197807066625 | BS30: =T30-U30 -> 0
A31: 26 | B31: 江沪 | C31: 上海KA | D31: 上海 | E31: 上海 | F31: 单导长促 | G31: 东港 | H31: 210422198201031424 | I31: 15000805616 | J31: NKA | K31: 直营 | L31: 欧发 | M31: 238976892 | N31: 欧尚嘉定店 | O31: 42821 | Q31: 2690 | R31: 8 | S31: 0 | T31: 16 | U31: 16 | V31: 0 | W31: 0 | X31: 0 | Y31: 2690 | Z31: 0 | AA31: 0 | AB31: 225.26 | AC31: 289.63889 | AD31: 1.2857981 | AE31: 1979.3333 | AF31: 0 | AG31: 256.25 | AH31: 861.54167 | AI31: 0 | AJ31: 80 | AK31: 80 | AL31: 0 | AM31: 160 | AQ31: 0 | AW31: 3791.54 | AX31: 2740 | AY31: 上海合杰 | AZ31: 783.3 | BA31: 188 | BB31: 0 | BC31: =ROUND(AW31-AZ31-BA31+BB31-AA31-AK31-AT31-AM31,2) -> 2580.24 | BD31: =ROUND(IF(T31=U31,IF((BC31-BB31)<AX31,AX31-(BC31-BB31),0)),2) -> 159.76 | BE31: =ROUND(AW31-AZ31-BA31+BB31+BD31,2) -> 2980 | BF31: -6679.09 | BG31: 0 | BH31: 0 | BI31: 0 | BJ31: =ROUND(BF31+BE31-5000-(BH31-BI31),2) -> -8699.09 | BK31: =ROUND(MAX(BJ31*{0.03,0.1,0.2,0.25,0.3,0.35,0.45}-{0,2520,16920,31920,52920,85920,181920}-BG31,0),2) -> 0 | BL31: =BG31+BK31 -> 0 | BM31: =ROUND(BE31-BK31,2) -> 2980 | BN31: 0 | BO31: =BE31+BN31 -> 2980 | BP31: =AZ31+BA31 -> 971.3 | BQ31: =AS31+AU31 -> 0 | BR31: =VLOOKUP(H31,社保公积金账单!D:D,1,0) -> 210422198201031424 | BS31: =T31-U31 -> 0
A32: 27 | B32: 江沪 | C32: 上海KA | D32: 上海 | E32: 上海 | F32: 单导长促 | G32: 王美芳 | H32: 310114197706063424 | I32: 15821178955 | J32: NKA | K32: 直营 | L32: 欧发 | M32: 238976892 | N32: 欧尚嘉定店 | O32: 39114 | Q32: 2690 | R32: 19 | S32: 0 | T32: 22 | U32: 22 | V32: 0 | W32: 0 | X32: 0 | Y32: 2690 | Z32: 0 | AA32: 0 | AB32: 225.26 | AC32: 289.63889 | AD32: 1.2857981 | AE32: 1979.3333 | AF32: 0 | AG32: 256.25 | AH32: 861.54167 | AI32: 0 | AJ32: 80 | AK32: 80 | AL32: 0 | AM32: 170 | AQ32: 0 | AW32: 3801.54 | AX32: 2740 | AY32: 上海合杰 | AZ32: 783.3 | BA32: 188 | BB32: 0 | BC32: =ROUND(AW32-AZ32-BA32+BB32-AA32-AK32-AT32-AM32,2) -> 2580.24 | BD32: =ROUND(IF(T32=U32,IF((BC32-BB32)<AX32,AX32-(BC32-BB32),0)),2) -> 159.76 | BE32: =ROUND(AW32-AZ32-BA32+BB32+BD32,2) -> 2990 | BF32: -4591.23 | BG32: 0 | BH32: 0 | BI32: 0 | BJ32: =ROUND(BF32+BE32-5000-(BH32-BI32),2) -> -6601.23 | BK32: =ROUND(MAX(BJ32*{0.03,0.1,0.2,0.25,0.3,0.35,0.45}-{0,2520,16920,31920,52920,85920,181920}-BG32,0),2) -> 0 | BL32: =BG32+BK32 -> 0 | BM32: =ROUND(BE32-BK32,2) -> 2990 | BN32: 0 | BO32: =BE32+BN32 -> 2990 | BP32: =AZ32+BA32 -> 971.3 | BQ32: =AS32+AU32 -> 0 | BR32: =VLOOKUP(H32,社保公积金账单!D:D,1,0) -> 310114197706063424 | BS32: =T32-U32 -> 0
A33: 28 | B33: 江沪 | C33: 上海KA | D33: 上海 | E33: 上海 | F33: 单导长促 | G33: 鲜秀英 | H33: 513030198510153427 | I33: 15601960086 | J33: NKA | K33: 直营 | L33: 欧发 | M33: 238977282 | N33: 欧尚金山店 | O33: 46093 | Q33: 2740 | R33: 0 | S33: 0 | T33: 15 | U33: 10 | V33: 0 | W33: 0 | X33: 0 | Y33: 1826.6667 | Z33: 0 | AA33: 0 | AB33: 218.92 | AC33: 290.97222 | AD33: 1.3291258 | AE33: 2139.8333 | AF33: 0 | AG33: 648.08333 | AH33: 1490.92 | AI33: 0 | AJ33: 53.333333 | AK33: 53.333333 | AL33: 0 | AM33: 100 | AQ33: 0 | AW33: 3470.92 | AX33: 2740 | AY33: 上海合杰 | AZ33: 783.3 | BA33: 192 | BB33: 0 | BC33: =ROUND(AW33-AZ33-BA33+BB33-AA33-AK33-AT33-AM33,2) -> 2342.29 | BD33: =ROUND(IF(T33=U33,IF((BC33-BB33)<AX33,AX33-(BC33-BB33),0)),2) -> 0 | BE33: =ROUND(AW33-AZ33-BA33+BB33+BD33,2) -> 2495.62 | BF33: 0 | BG33: 0 | BH33: 0 | BI33: 0 | BJ33: =ROUND(BF33+BE33-5000-(BH33-BI33),2) -> -2504.38 | BK33: =ROUND(MAX(BJ33*{0.03,0.1,0.2,0.25,0.3,0.35,0.45}-{0,2520,16920,31920,52920,85920,181920}-BG33,0),2) -> 0 | BL33: =BG33+BK33 -> 0 | BM33: =ROUND(BE33-BK33,2) -> 2495.62 | BN33: 0 | BO33: =BE33+BN33 -> 2495.62 | BP33: =AZ33+BA33 -> 975.3 | BQ33: =AS33+AU33 -> 0 | BR33: =VLOOKUP(H33,社保公积金账单!D:D,1,0) -> 513030198510153427 | BS33: =T33-U33 -> 5
A34: 29 | B34: 江沪 | C34: 上海KA | D34: 上海 | E34: 上海 | F34: 单导长促 | G34: 王霞芹 | H34: 310225198204112424 | I34: 15921030310 | J34: NKA | K34: 直营 | L34: 欧发 | M34: 238976894 | N34: 欧尚南汇店 | O34: 43160 | Q34: 2690 | R34: 8 | S34: 0 | T34: 15 | U34: 15 | V34: 0 | W34: 0 | X34: 0 | Y34: 2690 | Z34: 0 | AA34: 0 | AB34: 398.21 | AC34: 408.66667 | AD34: 1.0262592 | AE34: 3537.6667 | AF34: 0 | AG34: 616.33333 | AH34: 2921.3333 | AI34: 0 | AJ34: 80 | AK34: 80 | AL34: 0 | AM34: 140 | AQ34: 0 | AW34: 5831.33 | AX34: 2740 | AY34: 上海合杰 | AZ34: 783.3 | BA34: 188 | BB34: 0 | BC34: =ROUND(AW34-AZ34-BA34+BB34-AA34-AK34-AT34-AM34,2) -> 4640.03 | BD34: =ROUND(IF(T34=U34,IF((BC34-BB34)<AX34,AX34-(BC34-BB34),0)),2) -> 0 | BE34: =ROUND(AW34-AZ34-BA34+BB34+BD34,2) -> 4860.03 | BF34: 4504.83 | BG34: 135.14 | BH34: 0 | BI34: 0 | BJ34: =ROUND(BF34+BE34-5000-(BH34-BI34),2) -> 4364.86 | BK34: =ROUND(MAX(BJ34*{0.03,0.1,0.2,0.25,0.3,0.35,0.45}-{0,2520,16920,31920,52920,85920,181920}-BG34,0),2) -> 0 | BL34: =BG34+BK34 -> 135.14 | BM34: =ROUND(BE34-BK34,2) -> 4860.03 | BN34: 0 | BO34: =BE34+BN34 -> 4860.03 | BP34: =AZ34+BA34 -> 971.3 | BQ34: =AS34+AU34 -> 0 | BR34: =VLOOKUP(H34,社保公积金账单!D:D,1,0) -> 310225198204112424 | BS34: =T34-U34 -> 0
A35: 30 | B35: 江沪 | C35: 上海KA | D35: 上海 | E35: 上海 | F35: 单导长促 | G35: 邵旱萍 | H35: 342501197807188629 | I35: 15902181583 | J35: NKA | K35: 直营 | L35: 欧发 | M35: 238976886 | N35: 欧尚中原店 | O35: 45778 | Q35: 2690 | R35: 0 | S35: 0 | T35: 22 | U35: 22 | V35: 0 | W35: 0 | X35: 0 | Y35: 2690 | Z35: 0 | AA35: 0 | AB35: 275.26 | AC35: 387.44444 | AD35: 1.4075581 | AE35: 2975.6667 | AF35: 0 | AG35: 580.375 | AH35: 2395.2917 | AI35: 0 | AJ35: 80 | AK35: 80 | AL35: 0 | AM35: 220 | AQ35: 0 | AW35: 5385.29 | AX35: 2740 | AY35: 上海合杰 | AZ35: 783.3 | BA35: 188 | BB35: 0 | BC35: =ROUND(AW35-AZ35-BA35+BB35-AA35-AK35-AT35-AM35,2) -> 4113.99 | BD35: =ROUND(IF(T35=U35,IF((BC35-BB35)<AX35,AX35-(BC35-BB35),0)),2) -> 0 | BE35: =ROUND(AW35-AZ35-BA35+BB35+BD35,2) -> 4413.99 | BF35: 1350.06 | BG35: 40.5 | BH35: 0 | BI35: 0 | BJ35: =ROUND(BF35+BE35-5000-(BH35-BI35),2) -> 764.05 | BK35: =ROUND(MAX(BJ35*{0.03,0.1,0.2,0.25,0.3,0.35,0.45}-{0,2520,16920,31920,52920,85920,181920}-BG35,0),2) -> 0 | BL35: =BG35+BK35 -> 40.5 | BM35: =ROUND(BE35-BK35,2) -> 4413.99 | BN35: 0 | BO35: =BE35+BN35 -> 4413.99 | BP35: =AZ35+BA35 -> 971.3 | BQ35: =AS35+AU35 -> 0 | BR35: =VLOOKUP(H35,社保公积金账单!D:D,1,0) -> 342501197807188629 | BS35: =T35-U35 -> 0
A36: 31 | B36: 江沪 | C36: 上海KA | D36: 上海 | E36: 上海 | F36: 单导长促 | G36: 王运乐 | H36: 342423196808132393 | I36: 13524491885 | J36: NKA | K36: 直营 | L36: 欧发 | M36: 238976888 | N36: 欧尚长阳店 | O36: 38412 | Q36: 2690 | R36: 21 | S36: 0 | T36: 15 | U36: 15 | V36: 0 | W36: 0 | X36: 0 | Y36: 2690 | Z36: 0 | AA36: 0 | AB36: 106.88 | AC36: 158.47222 | AD36: 1.4827117 | AE36: 1144.3333 | AF36: 0 | AG36: 197.5 | AH36: 946.83333 | AI36: 0 | AJ36: 80 | AK36: 80 | AL36: 0 | AM36: 140 | AQ36: 0 | AW36: 3856.83 | AX36: 2740 | AY36: 上海合杰 | AZ36: 783.3 | BA36: 188 | BB36: 0 | BC36: =ROUND(AW36-AZ36-BA36+BB36-AA36-AK36-AT36-AM36,2) -> 2665.53 | BD36: =ROUND(IF(T36=U36,IF((BC36-BB36)<AX36,AX36-(BC36-BB36),0)),2) -> 74.47 | BE36: =ROUND(AW36-AZ36-BA36+BB36+BD36,2) -> 2960 | BF36: -5179.17 | BG36: 0 | BH36: 0 | BI36: 0 | BJ36: =ROUND(BF36+BE36-5000-(BH36-BI36),2) -> -7219.17 | BK36: =ROUND(MAX(BJ36*{0.03,0.1,0.2,0.25,0.3,0.35,0.45}-{0,2520,16920,31920,52920,85920,181920}-BG36,0),2) -> 0 | BL36: =BG36+BK36 -> 0 | BM36: =ROUND(BE36-BK36,2) -> 2960 | BN36: 0 | BO36: =BE36+BN36 -> 2960 | BP36: =AZ36+BA36 -> 971.3 | BQ36: =AS36+AU36 -> 0 | BR36: =VLOOKUP(H36,社保公积金账单!D:D,1,0) -> 342423196808132393 | BS36: =T36-U36 -> 0
A37: 32 | B37: 江沪 | C37: 上海KA | D37: 上海 | E37: 上海 | F37: 单导长促 | G37: 吴思堂 | H37: 342423197603062138 | I37: 13564265158 | J37: NKA | K37: 直营 | L37: 麦德龙 | M37: 238976874 | N37: 麦德龙闵行店 | O37: 42418 | Q37: 2690 | R37: 10 | S37: 0 | T37: 16 | U37: 16 | V37: 0 | W37: 0 | X37: 0 | Y37: 2690 | Z37: 0 | AA37: 0 | AB37: 89.62 | AC37: 120 | AD37: 1.3389868 | AE37: 1128.02 | AF37: 0 | AG37: 9.4166667 | AH37: 1118.6033 | AI37: 0 | AJ37: 80 | AK37: 80 | AL37: 100 | AM37: 160 | AQ37: 0 | AW37: 4148.6 | AX37: 2740 | AY37: 上海合杰 | AZ37: 783.3 | BA37: 188 | BB37: 0 | BC37: =ROUND(AW37-AZ37-BA37+BB37-AA37-AK37-AT37-AM37,2) -> 2937.3 | BD37: =ROUND(IF(T37=U37,IF((BC37-BB37)<AX37,AX37-(BC37-BB37),0)),2) -> 0 | BE37: =ROUND(AW37-AZ37-BA37+BB37+BD37,2) -> 3177.3 | BF37: -4677.34 | BG37: 0 | BH37: 0 | BI37: 0 | BJ37: =ROUND(BF37+BE37-5000-(BH37-BI37),2) -> -6500.04 | BK37: =ROUND(MAX(BJ37*{0.03,0.1,0.2,0.25,0.3,0.35,0.45}-{0,2520,16920,31920,52920,85920,181920}-BG37,0),2) -> 0 | BL37: =BG37+BK37 -> 0 | BM37: =ROUND(BE37-BK37,2) -> 3177.3 | BN37: 0 | BO37: =BE37+BN37 -> 3177.3 | BP37: =AZ37+BA37 -> 971.3 | BQ37: =AS37+AU37 -> 0 | BR37: =VLOOKUP(H37,社保公积金账单!D:D,1,0) -> 342423197603062138 | BS37: =T37-U37 -> 0
A38: 33 | B38: 江沪 | C38: 上海KA | D38: 上海 | E38: 上海 | F38: 单导长促 | G38: 王静 | H38: 340122198603201708 | I38: 18756591219 | J38: NKA | K38: 直营 | L38: 麦德龙 | M38: 238976876 | N38: 麦德龙浦东店 | O38: 45941 | Q38: 2740 | R38: 0 | S38: 0 | T38: 15 | U38: 10 | V38: 0 | W38: 0 | X38: 0 | Y38: 1826.6667 | Z38: 0 | AA38: 0 | AB38: 108.26 | AC38: 149.14 | AD38: 1.3776095 | AE38: 1379.62 | AF38: 0 | AG38: 8.625 | AH38: 1370.99 | AI38: 0 | AJ38: 53.333333 | AK38: 53.333333 | AL38: 0 | AM38: 100 | AQ38: 0 | AW38: 3350.99 | AX38: 2740 | AY38: 上海合杰 | AZ38: 783.3 | BA38: 192 | BB38: 0 | BC38: =ROUND(AW38-AZ38-BA38+BB38-AA38-AK38-AT38-AM38,2) -> 2222.36 | BD38: =ROUND(IF(T38=U38,IF((BC38-BB38)<AX38,AX38-(BC38-BB38),0)),2) -> 0 | BE38: =ROUND(AW38-AZ38-BA38+BB38+BD38,2) -> 2375.69 | BF38: -2888.7 | BG38: 0 | BH38: 0 | BI38: 0 | BJ38: =ROUND(BF38+BE38-5000-(BH38-BI38),2) -> -5513.01 | BK38: =ROUND(MAX(BJ38*{0.03,0.1,0.2,0.25,0.3,0.35,0.45}-{0,2520,16920,31920,52920,85920,181920}-BG38,0),2) -> 0 | BL38: =BG38+BK38 -> 0 | BM38: =ROUND(BE38-BK38,2) -> 2375.69 | BN38: 0 | BO38: =BE38+BN38 -> 2375.69 | BP38: =AZ38+BA38 -> 975.3 | BQ38: =AS38+AU38 -> 0 | BR38: =VLOOKUP(H38,社保公积金账单!D:D,1,0) -> 340122198603201708 | BS38: =T38-U38 -> 5
A39: 34 | B39: 江沪 | C39: 上海KA | D39: 上海 | E39: 上海 | F39: 单导长促 | G39: 杜雷军 | H39: 320923197303084257 | I39: 15300428327 | J39: NKA | K39: 直营 | L39: 麦德龙 | M39: 238976872 | N39: 麦德龙真北店 | O39: 45113 | Q39: 2690 | R39: 2 | S39: 0 | T39: 15 | U39: 15 | V39: 0 | W39: 0 | X39: 0 | Y39: 2690 | Z39: 0 | AA39: 0 | AB39: 134.74 | AC39: 200.95 | AD39: 1.4913908 | AE39: 1655.14 | AF39: 118.125 | AG39: 13.666667 | AH39: 1523.3483 | AI39: 0 | AJ39: 80 | AK39: 80 | AL39: 100 | AM39: 150 | AQ39: 0 | AW39: 4543.35 | AX39: 2740 | AY39: 上海合杰 | AZ39: 783.3 | BA39: 188 | BB39: 0 | BC39: =ROUND(AW39-AZ39-BA39+BB39-AA39-AK39-AT39-AM39,2) -> 3342.05 | BD39: =ROUND(IF(T39=U39,IF((BC39-BB39)<AX39,AX39-(BC39-BB39),0)),2) -> 0 | BE39: =ROUND(AW39-AZ39-BA39+BB39+BD39,2) -> 3572.05 | BF39: -117.63 | BG39: 19.01 | BH39: 0 | BI39: 0 | BJ39: =ROUND(BF39+BE39-5000-(BH39-BI39),2) -> -1545.58 | BK39: =ROUND(MAX(BJ39*{0.03,0.1,0.2,0.25,0.3,0.35,0.45}-{0,2520,16920,31920,52920,85920,181920}-BG39,0),2) -> 0 | BL39: =BG39+BK39 -> 19.01 | BM39: =ROUND(BE39-BK39,2) -> 3572.05 | BN39: 0 | BO39: =BE39+BN39 -> 3572.05 | BP39: =AZ39+BA39 -> 971.3 | BQ39: =AS39+AU39 -> 0 | BR39: =VLOOKUP(H39,社保公积金账单!D:D,1,0) -> 320923197303084257 | BS39: =T39-U39 -> 0
A40: 合计 | Q40: =SUM(Q6:Q39) -> 91610 | R40: =SUM(R6:R39) -> 202 | S40: =SUM(S6:S39) -> 0 | T40: =SUM(T6:T39) -> 598 | U40: =SUM(U6:U39) -> 583 | V40: =SUM(V6:V39) -> 3 | W40: =SUM(W6:W39) -> 2 | X40: =SUM(X6:X39) -> 261.54545 | ... BP40: =SUM(BP6:BP39) -> 33036.2

Sheet Sheet9
A1: 姓名 | B1: 身份证号码 | C1: 门店 | D1: 雇主责任险 | E1: 本月应缴金额 | I1: 补缴金额 | M1: 实缴金额
E2: 社保 | G2: 公积金 | I2: 社保 | K2: 公积金 | M2: 个人 | N2: 公司 | O2: 小计
E3: 个人 | F3: 公司 | G3: 个人 | H3: 公司 | I3: 个人 | J3: 公司 | K3: 个人 | L3: 公司 | M3: 个人 | N3: 公司 | O3: 小计
A4: 车文秀 | B4: 341623199710154424 | C4: 大润发松江店 | D4: 21 | E4: 684.6 | F4: 1744.5 | G4: 181 | H4: 181 | I4: 0 | J4: 0 | K4: 0 | L4: 0 | M4: 865.6 | N4: 1925.5 | O4: 2791.1
A5: 陈福娟 | B5: 342423197403292668 | C5: 大润发春申店 | D5: 21 | E5: 684.6 | F5: 1744.5 | G5: 181 | H5: 181 | I5: 0 | J5: 0 | K5: 0 | L5: 0 | M5: 865.6 | N5: 1925.5 | O5: 2791.1
A6: 陈敏 | B6: 310226197301243524 | C6: 大润发奉贤店 | D6: 21 | E6: 684.6 | F6: 1744.5 | G6: 181 | H6: 181 | I6: 0 | J6: 0 | K6: 0 | L6: 0 | M6: 865.6 | N6: 1925.5 | O6: 2791.1
A7: 东港 | B7: 210422198201031424 | C7: 欧尚嘉定店 | D7: 21 | E7: 684.6 | F7: 1744.5 | G7: 181 | H7: 181 | I7: 0 | J7: 0 | K7: 0 | L7: 0 | M7: 865.6 | N7: 1925.5 | O7: 2791.1
A8: 范祖容 | B8: 51253319820521484X | C8: 家乐福金桥店 | D8: 21 | E8: 684.6 | F8: 1744.5 | G8: 181 | H8: 181 | I8: 0 | J8: 0 | K8: 0 | L8: 0 | M8: 865.6 | N8: 1925.5 | O8: 2791.1
A9: 戈艳青 | B9: 32082319780513524X | C9: 家乐福中山店 | D9: 21 | E9: 684.6 | F9: 1744.5 | G9: 181 | H9: 181 | I9: 0 | J9: 0 | K9: 0 | L9: 0 | M9: 865.6 | N9: 1925.5 | O9: 2791.1
A10: 葛菊 | B10: 340421198104213042 | C10: 欧尚中原店 | D10: 21 | E10: 684.6 | F10: 1744.5 | G10: 181 | H10: 181 | I10: 0 | J10: 0 | K10: 0 | L10: 0 | M10: 865.6 | N10: 1925.5 | O10: 2791.1
A11: 顾建凤 | B11: 310226197704023526 | C11: 大润发奉贤店 | D11: 21 | E11: 684.6 | F11: 1744.5 | G11: 181 | H11: 181 | I11: 0 | J11: 0 | K11: 0 | L11: 0 | M11: 865.6 | N11: 1925.5 | O11: 2791.1
A12: 管兵娥 | B12: 362329198211245745 | C12: 大润发安亭店 | D12: 21 | E12: 684.6 | F12: 1744.5 | G12: 181 | H12: 181 | I12: 0 | J12: 0 | K12: 0 | L12: 0 | M12: 865.6 | N12: 1925.5 | O12: 2791.1
A13: 郭胜霞 | B13: 320925197905205821 | C13: 家乐福古北店 | D13: 21 | E13: 684.6 | F13: 1744.5 | G13: 181 | H13: 181 | I13: 0 | J13: 0 | K13: 0 | L13: 0 | M13: 865.6 | N13: 1925.5 | O13: 2791.1
A14: 过苗苗 | B14: 341224198812281328 | C14: 大润发平型关店 | D14: 21 | E14: 684.6 | F14: 1744.5 | G14: 181 | H14: 181 | I14: 0 | J14: 0 | K14: 0 | L14: 0 | M14: 865.6 | N14: 1925.5 | O14: 2791.1
A15: 洪艳 | B15: 342422197308163968 | C15: 沃尔玛南浦大桥店 | D15: 21 | E15: 684.6 | F15: 1744.5 | G15: 181 | H15: 181 | I15: 0 | J15: 0 | K15: 0 | L15: 0 | M15: 865.6 | N15: 1925.5 | O15: 2791.1
... A75: 姚友美 | B75: 34122619830430352X | C75: 大润发中原店 | D75: 21 | E75: 684.6 | F75: 1744.5 | G75: 181 | H75: 181 | I75: 0 | J75: 0 | K75: 0 | L75: 0 | M75: 865.6 | N75: 1925.5 | O75: 2791.1
A76: 耿良莉 | B76: 34242319840516738X | D76: 21 | E76: 415.49 | F76: 967.5 | G76: 182 | H76: 182 | I76: 0 | J76: 0 | K76: 0 | L76: 0 | M76: 597.49 | N76: 1149.5 | O76: 1746.99
A77: 霍雪 | B77: 41152819860103524X | D77: 21 | E77: 341.35 | F77: 977.05 | G77: 317 | H77: 317 | I77: 0 | J77: 0 | K77: 0 | L77: 0 | M77: 658.35 | N77: 1294.05 | O77: 1952.4
A78: 涂秀华 | B78: 511123197304307822 | D78: 21 | E78: 415.49 | F78: 967.5 | G78: 182 | H78: 182 | I78: 0 | J78: 0 | K78: 0 | L78: 0 | M78: 597.49 | N78: 1149.5 | O78: 1746.99
A79: 尹雪峰 | B79: 342224198109020741 | D79: 21 | E79: 415.49 | F79: 967.5 | G79: 182 | H79: 182 | I79: 0 | J79: 0 | K79: 0 | L79: 0 | M79: 597.49 | N79: 1149.5 | O79: 1746.99
A80: 丁小红 | B80: 321025197404040821 | D80: 21 | E80: 446.25 | F80: 1096.5 | G80: 0 | H80: 0 | I80: 0 | J80: 0 | K80: 0 | L80: 0 | M80: 446.25 | N80: 1096.5 | O80: 1542.75
A81: 顾宏 | B81: 320924197303033448 | D81: 21 | E81: 451.25 | F81: 1051.88 | G81: 340 | H81: 340 | I81: 0 | J81: 0 | K81: 36 | L81: 36 | M81: 827.25 | N81: 1427.88 | O81: 2255.13
A82: 孙开艳 | B82: 32092419760320718X | D82: 21 | E82: 446.25 | F82: 1096.5 | G82: 183 | H82: 183 | I82: 0 | J82: 0 | K82: 21 | L82: 21 | M82: 650.25 | N82: 1300.5 | O82: 1950.75
A83: 孙莉莉 | B83: 320922198304053645 | D83: 21 | E83: 446.25 | F83: 1096.5 | G83: 183 | H83: 183 | I83: 0 | J83: 0 | K83: 21 | L83: 21 | M83: 650.25 | N83: 1300.5 | O83: 1950.75
A84: 陶宝芹 | B84: 321023197201015869 | D84: 21 | E84: 446.25 | F84: 1096.5 | G84: 0 | H84: 0 | I84: 0 | J84: 0 | K84: 0 | L84: 0 | M84: 446.25 | N84: 1096.5 | O84: 1542.75
A85: 吴海珍 | B85: 321123197802191644 | D85: 21 | E85: 456.25 | F85: 1092.25 | G85: 0 | H85: 0 | I85: 0 | J85: 0 | K85: 0 | L85: 0 | M85: 456.25 | N85: 1092.25 | O85: 1548.5
A86: 吴永红 | B86: 42032319710815250X | D86: 21 | E86: 446.25 | F86: 1096.5 | G86: 183 | H86: 183 | I86: 0 | J86: 0 | K86: 21 | L86: 21 | M86: 650.25 | N86: 1300.5 | O86: 1950.75
A87: 谢如香 | B87: 321322198705145223 | D87: 21 | E87: 451.25 | F87: 1051.88 | G87: 340 | H87: 340 | I87: 0 | J87: 0 | K87: 36 | L87: 36 | M87: 827.25 | N87: 1427.88 | O87: 2255.13
A88: 徐婷 | B88: 320828197509113064 | D88: 21 | E88: 446.25 | F88: 1096.5 | G88: 183 | H88: 183 | I88: 0 | J88: 0 | K88: 0 | L88: 0 | M88: 629.25 | N88: 1279.5 | O88: 1908.75
D89: =SUM(D4:D88) -> 1785 | E89: =SUM(E4:E88) -> 54915.27 | F89: =SUM(F4:F88) -> 139258.56 | G89: =SUM(G4:G88) -> 15307 | H89: =SUM(H4:H88) -> 15307 | I89: =SUM(I4:I88) -> 0 | J89: =SUM(J4:J88) -> 0 | K89: =SUM(K4:K88) -> 135 | ... O89: =SUM(O4:O88) -> 225057.83
D92: 公司社保 | E92: =F89+J89 -> 139258.56
D93: 公司公积金 | E93: =H89+L89 -> 15442
D94: 个人社保 | E94: =E89+I89 -> 54915.27
D95: 个人公积金 | E95: =G89+K89 -> 15442

Sheet 社保公积金账单
H2: 养老 | O2: 医疗 | X2: 失业 | AE2: 住房 | AL2: 其他类社保 | BA2: 医疗生育 | BH2: 工伤 | BO2: 补充公积金 | BV2: 本月应缴金额 | BZ2: 补缴金额 | CD2: 实缴金额 | CH2: 社保个人 | CI2: 社保公司 | CJ2: 公积金个人 | CK2: 公积金公司
A3: 序号 | B3: 组织名称 | C3: 姓名 | D3: 身份证号码 | E3: 渠道 | F3: 门店名称 | G3: 雇主责任险 | H3: 基数 | I3: 公司 | L3: 个人 | O3: 基数 | P3: 公司 | T3: 个人 | X3: 基数 | Y3: 公司 | AB3: 个人 | AE3: 基数 | AF3: 公司 | AI3: 个人 | AL3: 大病公司 | AN3: 大病个人 | AP3: 采暖费 | AR3: 保障金 | AT3: 社保工会费 | AV3: 公司其他 | AX3: 个人其他 | AZ3: 备注 | BA3: 基数 | BB3: 公司 | BE3: 个人 | BH3: 基数 | BI3: 公司 | BL3: 个人 | BO3: 基数 | BP3: 公司 | BS3: 个人 | BV3: 社保 | BX3: 社保 | BZ3: 社保 | CB3: 公积金 | CD3: 个人 | CE3: 公司 | CF3: 小计
H4: 基数 | I4: 比例(%) | J4: 应缴 | K4: 补缴 | L4: 比例(%) | M4: 应缴 | N4: 补缴 | O4: 基数 | P4: 比例(%) | Q4: 固定 | R4: 应缴 | S4: 补缴 | T4: 比例(%) | U4: 固定 | V4: 应缴 | W4: 补缴 | X4: 基数 | Y4: 比例(%) | Z4: 应缴 | AA4: 补缴 | AB4: 比例(%) | AC4: 应缴 | AD4: 补缴 | AE4: 基数 | AF4: 比例(%) | AG4: 应缴 | AH4: 补缴 | AI4: 比例(%) | AJ4: 应缴 | AK4: 补缴 | AL4: 应缴 | AM4: 补缴 | AN4: 应缴 | AO4: 补缴 | AP4: 应缴 | AQ4: 补缴 | AR4: 应缴 | AS4: 补缴 | AT4: 应缴 | AU4: 补缴 | AV4: 应缴 | AW4: 补缴 | AX4: 应缴 | AY4: 补缴 | AZ4: 备注 | BA4: 基数 | BB4: 比例(%) | BC4: 应缴 | BD4: 补缴 | BE4: 比例(%) | BF4: 应缴 | BG4: 补缴 | BH4: 基数 | BI4: 比例(%) | BJ4: 应缴 | BK4: 补缴 | BL4: 比例(%) | BM4: 应缴 | BN4: 补缴 | BO4: 基数 | BP4: 比例(%) | BQ4: 应缴 | BR4: 补缴 | BS4: 比例(%) | BT4: 应缴 | BU4: 补缴 | BV4: 个人 | BW4: 公司 | BX4: 个人 | BY4: 公司 | BZ4: 个人 | CA4: 公司 | CB4: 个人 | CC4: 公司
A5: 1 | B5: 中粮上海导购 | C5: 车文秀 | D5: 341623199710154424 | E5: =VLOOKUP(D5,长促工资明细!H:P,3,0) -> NKA | F5: =VLOOKUP(D5,长促工资明细!H:P,7,0) -> 大润发松江店 | G5: 19.67 | H5: 7460 | I5: 16 | J5: 1193.6 | K5: 0 | L5: 8 | M5: 596.8 | N5: 0 | O5: 7460 | P5: 9 | R5: 671.4 | S5: 0 | T5: 2 | V5: 149.2 | W5: 0 | X5: 7460 | Y5: 0.5 | Z5: 37.3 | AA5: 0 | AB5: 0.5 | AC5: 37.3 | AD5: 0 | AE5: 2690 | AF5: 7 | AG5: 188 | AH5: 0 | AI5: 7 | AJ5: 188 | AK5: 0 | AL5: 0 | AM5: 0 | AN5: 0 | AO5: 0 | AP5: 0 | AQ5: 0 | AS5: 0 | AT5: 0 | AU5: 0 | AV5: 0 | AW5: 0 | AX5: 0 | AY5: 0 | BC5: 0 | BD5: 0 | BF5: 0 | BG5: 0 | BH5: 7460 | BI5: 0.32 | BJ5: 23.87 | BK5: 0 | BM5: 0 | BN5: 0 | BQ5: 0 | BR5: 0 | BT5: 0 | BU5: 0 | BV5: =M5+V5+AC5+AN5+AX5+BF5+BM5 -> 783.3 | BW5: =BJ5+BC5+AV5+AT5+AR5+AP5+AL5+Z5+R5+J5 -> 1926.17 | BX5: =AJ5 -> 188 | BY5: =AG5 -> 188 | BZ5: =N5+W5+AD5+AO5+AY5+BG5+BN5 -> 0 | CA5: =K5+S5+AA5+AM5+AQ5+AS5+AU5+AW5+BD5+BK5+BR5 -> 0 | CB5: =BU5+AK5 -> 0 | CC5: =BR5+AH5 -> 0 | CD5: =BV5+BX5+BZ5+CB5 -> 971.3 | CE5: =BW5+BY5+CA5+CC5 -> 2114.17 | CF5: =CD5+CE5 -> 3085.47 | CG5: 上海市； | CH5: =BV5+BZ5 -> 783.3 | CI5: =BW5+CA5 -> 1926.17 | CJ5: =BX5+CB5 -> 188 | CK5: =BY5+CC5 -> 188 | CL5: =CH5+CI5 -> 2709.47 | CM5: =CJ5+CK5 -> 376 | CN5: 本部 | CO5: =N5+M5 -> 596.8 | CP5: =V5+W5+AN5+AO5 -> 149.2 | CQ5: =AD5+AC5 -> 37.3 | CR5: =CQ5+CP5+CO5=CH5 -> TRUE | CS5: =VLOOKUP(C5,长促工资明细!G:G,1,0) -> 车文秀
A6: 2 | B6: 中粮上海导购 | C6: 东港 | D6: 210422198201031424 | E6: =VLOOKUP(D6,长促工资明细!H:P,3,0) -> NKA | F6: =VLOOKUP(D6,长促工资明细!H:P,7,0) -> 欧尚嘉定店 | G6: 19.67 | H6: 7460 | I6: 16 | J6: 1193.6 | K6: 0 | L6: 8 | M6: 596.8 | N6: 0 | O6: 7460 | P6: 9 | R6: 671.4 | S6: 0 | T6: 2 | V6: 149.2 | W6: 0 | X6: 7460 | Y6: 0.5 | Z6: 37.3 | AA6: 0 | AB6: 0.5 | AC6: 37.3 | AD6: 0 | AE6: 2690 | AF6: 7 | AG6: 188 | AH6: 0 | AI6: 7 | AJ6: 188 | AK6: 0 | AL6: 0 | AM6: 0 | AN6: 0 | AO6: 0 | AP6: 0 | AQ6: 0 | AS6: 0 | AT6: 0 | AU6: 0 | AV6: 0 | AW6: 0 | AX6: 0 | AY6: 0 | BC6: 0 | BD6: 0 | BF6: 0 | BG6: 0 | BH6: 7460 | BI6: 0.32 | BJ6: 23.87 | BK6: 0 | BM6: 0 | BN6: 0 | BQ6: 0 | BR6: 0 | BT6: 0 | BU6: 0 | BV6: =M6+V6+AC6+AN6+AX6+BF6+BM6 -> 783.3 | BW6: =BJ6+BC6+AV6+AT6+AR6+AP6+AL6+Z6+R6+J6 -> 1926.17 | BX6: =AJ6 -> 188 | BY6: =AG6 -> 188 | BZ6: =N6+W6+AD6+AO6+AY6+BG6+BN6 -> 0 | CA6: =K6+S6+AA6+AM6+AQ6+AS6+AU6+AW6+BD6+BK6+BR6 -> 0 | CB6: =BU6+AK6 -> 0 | CC6: =BR6+AH6 -> 0 | CD6: =BV6+BX6+BZ6+CB6 -> 971.3 | CE6: =BW6+BY6+CA6+CC6 -> 2114.17 | CF6: =CD6+CE6 -> 3085.47 | CG6: 上海市； | CH6: =BV6+BZ6 -> 783.3 | CI6: =BW6+CA6 -> 1926.17 | CJ6: =BX6+CB6 -> 188 | CK6: =BY6+CC6 -> 188 | CL6: =CH6+CI6 -> 2709.47 | CM6: =CJ6+CK6 -> 376 | CN6: 本部 | CO6: =N6+M6 -> 596.8 | CP6: =V6+W6+AN6+AO6 -> 149.2 | CQ6: =AD6+AC6 -> 37.3 | CR6: =CQ6+CP6+CO6=CH6 -> TRUE | CS6: =VLOOKUP(C6,长促工资明细!G:G,1,0) -> 东港
A7: 3 | B7: 中粮上海导购 | C7: 董燕芳 | D7: 31022519780512504X | E7: =VLOOKUP(D7,长促工资明细!H:P,3,0) -> NKA | F7: =VLOOKUP(D7,长促工资明细!H:P,7,0) -> 大润发泥城店 | G7: 19.67 | H7: 7460 | I7: 16 | J7: 1193.6 | K7: 0 | L7: 8 | M7: 596.8 | N7: 0 | O7: 7460 | P7: 9 | R7: 671.4 | S7: 0 | T7: 2 | V7: 149.2 | W7: 0 | X7: 7460 | Y7: 0.5 | Z7: 37.3 | AA7: 0 | AB7: 0.5 | AC7: 37.3 | AD7: 0 | AE7: 2690 | AF7: 7 | AG7: 188 | AH7: 0 | AI7: 7 | AJ7: 188 | AK7: 0 | AL7: 0 | AM7: 0 | AN7: 0 | AO7: 0 | AP7: 0 | AQ7: 0 | AS7: 0 | AT7: 0 | AU7: 0 | AV7: 0 | AW7: 0 | AX7: 0 | AY7: 0 | BC7: 0 | BD7: 0 | BF7: 0 | BG7: 0 | BH7: 7460 | BI7: 0.32 | BJ7: 23.87 | BK7: 0 | BM7: 0 | BN7: 0 | BQ7: 0 | BR7: 0 | BT7: 0 | BU7: 0 | BV7: =M7+V7+AC7+AN7+AX7+BF7+BM7 -> 783.3 | BW7: =BJ7+BC7+AV7+AT7+AR7+AP7+AL7+Z7+R7+J7 -> 1926.17 | BX7: =AJ7 -> 188 | BY7: =AG7 -> 188 | BZ7: =N7+W7+AD7+AO7+AY7+BG7+BN7 -> 0 | CA7: =K7+S7+AA7+AM7+AQ7+AS7+AU7+AW7+BD7+BK7+BR7 -> 0 | CB7: =BU7+AK7 -> 0 | CC7: =BR7+AH7 -> 0 | CD7: =BV7+BX7+BZ7+CB7 -> 971.3 | CE7: =BW7+BY7+CA7+CC7 -> 2114.17 | CF7: =CD7+CE7 -> 3085.47 | CG7: 上海市； | CH7: =BV7+BZ7 -> 783.3 | CI7: =BW7+CA7 -> 1926.17 | CJ7: =BX7+CB7 -> 188 | CK7: =BY7+CC7 -> 188 | CL7: =CH7+CI7 -> 2709.47 | CM7: =CJ7+CK7 -> 376 | CN7: 本部 | CO7: =N7+M7 -> 596.8 | CP7: =V7+W7+AN7+AO7 -> 149.2 | CQ7: =AD7+AC7 -> 37.3 | CR7: =CQ7+CP7+CO7=CH7 -> TRUE | CS7: =VLOOKUP(C7,长促工资明细!G:G,1,0) -> 董燕芳
A8: 4 | B8: 中粮上海导购 | C8: 杜雷军 | D8: 320923197303084257 | E8: =VLOOKUP(D8,长促工资明细!H:P,3,0) -> NKA | F8: =VLOOKUP(D8,长促工资明细!H:P,7,0) -> 麦德龙真北店 | G8: 19.67 | H8: 7460 | I8: 16 | J8: 1193.6 | K8: 0 | L8: 8 | M8: 596.8 | N8: 0 | O8: 7460 | P8: 9 | R8: 671.4 | S8: 0 | T8: 2 | V8: 149.2 | W8: 0 | X8: 7460 | Y8: 0.5 | Z8: 37.3 | AA8: 0 | AB8: 0.5 | AC8: 37.3 | AD8: 0 | AE8: 2690 | AF8: 7 | AG8: 188 | AH8: 0 | AI8: 7 | AJ8: 188 | AK8: 0 | AL8: 0 | AM8: 0 | AN8: 0 | AO8: 0 | AP8: 0 | AQ8: 0 | AS8: 0 | AT8: 0 | AU8: 0 | AV8: 0 | AW8: 0 | AX8: 0 | AY8: 0 | BC8: 0 | BD8: 0 | BF8: 0 | BG8: 0 | BH8: 7460 | BI8: 0.32 | BJ8: 23.87 | BK8: 0 | BM8: 0 | BN8: 0 | BQ8: 0 | BR8: 0 | BT8: 0 | BU8: 0 | BV8: =M8+V8+AC8+AN8+AX8+BF8+BM8 -> 783.3 | BW8: =BJ8+BC8+AV8+AT8+AR8+AP8+AL8+Z8+R8+J8 -> 1926.17 | BX8: =AJ8 -> 188 | BY8: =AG8 -> 188 | BZ8: =N8+W8+AD8+AO8+AY8+BG8+BN8 -> 0 | CA8: =K8+S8+AA8+AM8+AQ8+AS8+AU8+AW8+BD8+BK8+BR8 -> 0 | CB8: =BU8+AK8 -> 0 | CC8: =BR8+AH8 -> 0 | CD8: =BV8+BX8+BZ8+CB8 -> 971.3 | CE8: =BW8+BY8+CA8+CC8 -> 2114.17 | CF8: =CD8+CE8 -> 3085.47 | CG8: 上海市； | CH8: =BV8+BZ8 -> 783.3 | CI8: =BW8+CA8 -> 1926.17 | CJ8: =BX8+CB8 -> 188 | CK8: =BY8+CC8 -> 188 | CL8: =CH8+CI8 -> 2709.47 | CM8: =CJ8+CK8 -> 376 | CN8: 本部 | CO8: =N8+M8 -> 596.8 | CP8: =V8+W8+AN8+AO8 -> 149.2 | CQ8: =AD8+AC8 -> 37.3 | CR8: =CQ8+CP8+CO8=CH8 -> TRUE | CS8: =VLOOKUP(C8,长促工资明细!G:G,1,0) -> 杜雷军
A9: 5 | B9: 中粮上海导购 | C9: 杜以花 | D9: 371122198002227829 | E9: =VLOOKUP(D9,长促工资明细!H:P,3,0) -> NKA | F9: =VLOOKUP(D9,长促工资明细!H:P,7,0) -> 大润发泗泾店 | G9: 19.67 | H9: 7460 | I9: 16 | J9: 1193.6 | K9: 0 | L9: 8 | M9: 596.8 | N9: 0 | O9: 7460 | P9: 9 | R9: 671.4 | S9: 0 | T9: 2 | V9: 149.2 | W9: 0 | X9: 7460 | Y9: 0.5 | Z9: 37.3 | AA9: 0 | AB9: 0.5 | AC9: 37.3 | AD9: 0 | AE9: 2690 | AF9: 7 | AG9: 188 | AH9: 0 | AI9: 7 | AJ9: 188 | AK9: 0 | AL9: 0 | AM9: 0 | AN9: 0 | AO9: 0 | AP9: 0 | AQ9: 0 | AS9: 0 | AT9: 0 | AU9: 0 | AV9: 0 | AW9: 0 | AX9: 0 | AY9: 0 | BC9: 0 | BD9: 0 | BF9: 0 | BG9: 0 | BH9: 7460 | BI9: 0.32 | BJ9: 23.87 | BK9: 0 | BM9: 0 | BN9: 0 | BQ9: 0 | BR9: 0 | BT9: 0 | BU9: 0 | BV9: =M9+V9+AC9+AN9+AX9+BF9+BM9 -> 783.3 | BW9: =BJ9+BC9+AV9+AT9+AR9+AP9+AL9+Z9+R9+J9 -> 1926.17 | BX9: =AJ9 -> 188 | BY9: =AG9 -> 188 | BZ9: =N9+W9+AD9+AO9+AY9+BG9+BN9 -> 0 | CA9: =K9+S9+AA9+AM9+AQ9+AS9+AU9+AW9+BD9+BK9+BR9 -> 0 | CB9: =BU9+AK9 -> 0 | CC9: =BR9+AH9 -> 0 | CD9: =BV9+BX9+BZ9+CB9 -> 971.3 | CE9: =BW9+BY9+CA9+CC9 -> 2114.17 | CF9: =CD9+CE9 -> 3085.47 | CG9: 上海市； | CH9: =BV9+BZ9 -> 783.3 | CI9: =BW9+CA9 -> 1926.17 | CJ9: =BX9+CB9 -> 188 | CK9: =BY9+CC9 -> 188 | CL9: =CH9+CI9 -> 2709.47 | CM9: =CJ9+CK9 -> 376 | CN9: 本部 | CO9: =N9+M9 -> 596.8 | CP9: =V9+W9+AN9+AO9 -> 149.2 | CQ9: =AD9+AC9 -> 37.3 | CR9: =CQ9+CP9+CO9=CH9 -> TRUE | CS9: =VLOOKUP(C9,长促工资明细!G:G,1,0) -> 杜以花
A10: 6 | B10: 中粮上海导购 | C10: 戈艳青 | D10: 32082319780513524X | E10: =VLOOKUP(D10,长促工资明细!H:P,3,0) -> NKA | F10: =VLOOKUP(D10,长促工资明细!H:P,7,0) -> 大润发泗泾店 | G10: 19.67 | H10: 7460 | I10: 16 | J10: 1193.6 | K10: 0 | L10: 8 | M10: 596.8 | N10: 0 | O10: 7460 | P10: 9 | R10: 671.4 | S10: 0 | T10: 2 | V10: 149.2 | W10: 0 | X10: 7460 | Y10: 0.5 | Z10: 37.3 | AA10: 0 | AB10: 0.5 | AC10: 37.3 | AD10: 0 | AE10: 2690 | AF10: 7 | AG10: 188 | AH10: 0 | AI10: 7 | AJ10: 188 | AK10: 0 | AL10: 0 | AM10: 0 | AN10: 0 | AO10: 0 | AP10: 0 | AQ10: 0 | AS10: 0 | AT10: 0 | AU10: 0 | AV10: 0 | AW10: 0 | AX10: 0 | AY10: 0 | BC10: 0 | BD10: 0 | BF10: 0 | BG10: 0 | BH10: 7460 | BI10: 0.32 | BJ10: 23.87 | BK10: 0 | BM10: 0 | BN10: 0 | BQ10: 0 | BR10: 0 | BT10: 0 | BU10: 0 | BV10: =M10+V10+AC10+AN10+AX10+BF10+BM10 -> 783.3 | BW10: =BJ10+BC10+AV10+AT10+AR10+AP10+AL10+Z10+R10+J10 -> 1926.17 | BX10: =AJ10 -> 188 | BY10: =AG10 -> 188 | BZ10: =N10+W10+AD10+AO10+AY10+BG10+BN10 -> 0 | CA10: =K10+S10+AA10+AM10+AQ10+AS10+AU10+AW10+BD10+BK10+BR10 -> 0 | CB10: =BU10+AK10 -> 0 | CC10: =BR10+AH10 -> 0 | CD10: =BV10+BX10+BZ10+CB10 -> 971.3 | CE10: =BW10+BY10+CA10+CC10 -> 2114.17 | CF10: =CD10+CE10 -> 3085.47 | CG10: 上海市； | CH10: =BV10+BZ10 -> 783.3 | CI10: =BW10+CA10 -> 1926.17 | CJ10: =BX10+CB10 -> 188 | CK10: =BY10+CC10 -> 188 | CL10: =CH10+CI10 -> 2709.47 | CM10: =CJ10+CK10 -> 376 | CN10: 本部 | CO10: =N10+M10 -> 596.8 | CP10: =V10+W10+AN10+AO10 -> 149.2 | CQ10: =AD10+AC10 -> 37.3 | CR10: =CQ10+CP10+CO10=CH10 -> TRUE | CS10: =VLOOKUP(C10,长促工资明细!G:G,1,0) -> 戈艳青
