Workbook

Sheet 结果报表
A1: 薪资年月 | B1: 薪资月 | C1: 主体 | D1: 合同所属地 | E1: 所属薪资包 | F1: 职能块 | G1: 部门 | H1: 门店 | I1: 账单供应商 | J1: 人数 | K1: 工号 | L1: 中文姓名 | M1: 职位 | N1: 聘用日期 | O1: 最后工作日期 | P1: 员工性质 | Q1: 实际出勤工时数 | R1: 月薪 | S1: 小时薪资 | T1: 实发月薪 | U1: 实发小时薪资 | V1: 岗位津贴 | W1: 补贴合计 | X1: 其它补贴 | Y1: 外派补贴 | Z1: 交通补贴 | AA1: 住房补贴 | AB1: 加班费 | AC1: 平时加班费 | AD1: 周末加班费 | AE1: 国假出勤工时 | AF1: 国假加班费合计 | AG1: 外送奖金 | AH1: 奖金 | AI1: 月度绩效奖金 | AJ1: 季度奖金 | AK1: 开发/工程/网规奖金 | AL1: 其他奖金1 | AM1: 其他奖金2 | AN1: 员工推荐奖金 | AO1: 补产假工资 | AP1: OJE酬劳 | AQ1: 年终奖 | AR1: 年度绩效考评奖 | AS1: 年度其它奖金 | AT1: 离职补偿金 | AU1: 税前调整 | AV1: 年假工资 | AW1: 病假工资 | AX1: 全薪假期工资 | AY1: 事假扣款 | AZ1: 病假扣款 | BA1: 产假扣款 | BB1: 税前扣减 | BC1: 年假折现 | BD1: 工会费个人 | BE1: 工会费公司 | BF1: 其它项补税 | BG1: 税后调整 | BH1: 服务费合计 | BI1: 税前工资总额 | BJ1: 养老金个人 | BK1: 医疗金个人 | BL1: 失业金个人 | BM1: 公积金个人 | BN1: 大病个人 | BO1: 补缴养老金个人 | BP1: 补缴医疗金个人 | BQ1: 补缴失业金个人 | BR1: 补缴公积金个人 | BS1: 补缴大病个人 | BT1: 社保合计个人 | BU1: 个人所得税 | BV1: 年终奖税 | BW1: 离职补偿税 | BX1: 个税合计 | BY1: 净收入 | BZ1: 养老金公司 | CA1: 医疗金公司 | CB1: 公积金公司 | CC1: 失业金公司 | CD1: 工伤金公司 | CE1: 生育金公司 | CF1: 大病公司 | CG1: 补缴养老金公司 | CH1: 补缴医疗金公司 | CI1: 补缴失业金公司 | CJ1: 补缴公积金 | CK1: 补缴工伤金公司 | CL1: 补缴生育金公司 | CM1: 补缴大病公司 | CN1: 社保合计公司 | CO1: 公司成本 | CP1: 计提残疾人保障金 | CQ1: 计提商业保险 | CR1: 计提雇主责任险 | CS1: 计提年终奖 | CT1: 计提营运奖金 | CU1: 养老金基数 | CV1: 公积金基数 | CW1: 医疗保险基数 | CX1: 失业保险基数 | CY1: 工伤保险基数 | CZ1: 生育保险基数 | DA1: 财务入账工资 | DB1: 财务入账总费用 | DC1: 开户银行 | DD1: 银行账号 | DE1: 开户银行明确支行 | DF1: 身份证号码 | DG1: 手机号码 | DH1: 工作地 | DI1: 子女教育支出 | DJ1: 住房租金支出 | DK1: 住房贷款利息支出 | DL1: 赡养老人支出 | DM1: 继续教育支出 | DN1: 婴幼儿照护费用 | DO1: 累计税基数 | DP1: 累计税 | DQ1: 累计免扣除数 | DR1: 中间项
A2: =参数!$B$2 -> 2025 | B2: =参数!$B$3 -> 12 | D2: 上海达美乐 | E2: 店铺营运 | F2: =IFERROR(VLOOKUP(K2,源_7银行卡表_Sheet1!$A:$J,6,FALSE),"") -> 华东营运 | G2: 上海2 | H2: 新村店 | I2: 外服-上海门店全职 | J2: 1 | K2: 26123001 | L2: 龚忆秋 | M2: 餐厅经理 | N2: 2012-03-20 | O2: 2025-12-04 | P2: 门店管理组 | Q2: =IF(P2="门店全职",IFERROR(VLOOKUP(K2,源_3考勤报表_考勤表!$F:$BG,34,FALSE),0)+IFERROR(VLOOKUP(K2,源_8补工时表_补当月工时!$A:$AC,14,FALSE),0),IF(P2="门店管理组",IF(IFERROR(VLOOKUP(K2,源_3考勤报表_考勤表!$F:$BG,34,FALSE),0)+IFERROR(VLOOKUP(K2,源_8补工时表_补当月工时!$A:$AC,14,FALSE),0)+IFERROR(VLOOKUP(K2,源_3考勤报表_考勤表!$F:$BG,37,FALSE),0)+IFERROR(VLOOKUP(K2,源_8补工时表_补当月工时!$A:$AC,15,FALSE),0)+IFERROR(VLOOKUP(K2,源_3考勤报表_考勤表!$F:$BG,38,FALSE),0)+IFERROR(VLOOKUP(K2,源_8补工时表_补当月工时!$A:$AC,17,FALSE),0)+IFERROR(VLOOKUP(K2,源_3考勤报表_考勤表!$F:$BG,40,FALSE),0)+IFERROR(VLOOKUP(K2,源_8补工时表_补当月工时!$A:$AC,20,FALSE),0)+IFERROR(VLOOKUP(K2,源_8补工时表_补当月工时!$A:$AC,22,FALSE),0)+IFERROR(VLOOKUP(K2,源_3考勤报表_考勤表!$F:$BG,41,FALSE),0)+IFERROR(VLOOKUP(K2,源_8补工时表_补当月工时!$A:$AC,18,FALSE),0)+IFERROR(VLOOKUP(K2,源_3考勤报表_考勤表!$F:$BG,44,FALSE),0)+IFERROR(VLOOKUP(K2,源_8补工时表_补当月工时!$A:$AC,16,FALSE),0)+IFERROR(VLOOKUP(K2,源_3考勤报表_考勤表!$F:$BG,45,FALSE),0)>=参数!$B$4,参数!$B$4-IFERROR(VLOOKUP(K2,源_3考勤报表_考勤表!$F:$BG,37,FALSE),0)-IFERROR(VLOOKUP(K2,源_8补工时表_补当月工时!$A:$AC,15,FALSE),0)-IFERROR(VLOOKUP(K2,源_3考勤报表_考勤表!$F:$BG,38,FALSE),0)-IFERROR(VLOOKUP(K2,源_8补工时表_补当月工时!$A:$AC,17,FALSE),0)-IFERROR(VLOOKUP(K2,源_3考勤报表_考勤表!$F:$BG,40,FALSE),0)-IFERROR(VLOOKUP(K2,源_8补工时表_补当月工时!$A:$AC,20,FALSE),0)-IFERROR(VLOOKUP(K2,源_8补工时表_补当月工时!$A:$AC,22,FALSE),0)-IFERROR(VLOOKUP(K2,源_3考勤报表_考勤表!$F:$BG,41,FALSE),0)-IFERROR(VLOOKUP(K2,源_8补工时表_补当月工时!$A:$AC,18,FALSE),0)-IFERROR(VLOOKUP(K2,源_3考勤报表_考勤表!$F:$BG,44,FALSE),0)-IFERROR(VLOOKUP(K2,源_8补工时表_补当月工时!$A:$AC,16,FALSE),0)-IFERROR(VLOOKUP(K2,源_3考勤报表_考勤表!$F:$BG,45,FALSE),0),IFERROR(VLOOKUP(K2,源_3考勤报表_考勤表!$F:$BG,34,FALSE),0)+IFERROR(VLOOKUP(K2,源_8补工时表_补当月工时!$A:$AC,14,FALSE),0)),0)) -> 168 | R2: 7514 | S2: 0 | T2: =IF(P2="门店全职",R2/参数!$B$4*(Q2-MAX(IFERROR(VLOOKUP(K2,源_3考勤报表_考勤表!$F:$BG,34,FALSE),0)+IFERROR(VLOOKUP(K2,源_8补工时表_补当月工时!$A:$AC,14,FALSE),0)+IFERROR(VLOOKUP(K2,源_3考勤报表_考勤表!$F:$BG,37,FALSE),0)+IFERROR(VLOOKUP(K2,源_8补工时表_补当月工时!$A:$AC,15,FALSE),0)+IFERROR(VLOOKUP(K2,源_3考勤报表_考勤表!$F:$BG,38,FALSE),0)+IFERROR(VLOOKUP(K2,源_8补工时表_补当月工时!$A:$AC,17,FALSE),0)+IFERROR(VLOOKUP(K2,源_3考勤报表_考勤表!$F:$BG,40,FALSE),0)+IFERROR(VLOOKUP(K2,源_8补工时表_补当月工时!$A:$AC,20,FALSE),0)+IFERROR(VLOOKUP(K2,源_8补工时表_补当月工时!$A:$AC,22,FALSE),0)+IFERROR(VLOOKUP(K2,源_3考勤报表_考勤表!$F:$BG,41,FALSE),0)+IFERROR(VLOOKUP(K2,源_8补工时表_补当月工时!$A:$AC,18,FALSE),0)+IFERROR(VLOOKUP(K2,源_3考勤报表_考勤表!$F:$BG,42,FALSE),0)+IFERROR(VLOOKUP(K2,源_8补工时表_补当月工时!$A:$AC,19,FALSE),0)+IFERROR(VLOOKUP(K2,源_3考勤报表_考勤表!$F:$BG,44,FALSE),0)+IFERROR(VLOOKUP(K2,源_8补工时表_补当月工时!$A:$AC,16,FALSE),0)+IFERROR(VLOOKUP(K2,源_3考勤报表_考勤表!$F:$BG,45,FALSE),0)-参数!$B$4,0)),R2/参数!$B$4*Q2) -> 6860.6087 | U2: 0 | V2: 0 | W2: =X2+Y2+Z2+AA2 -> 25.5 | X2: =IFERROR(VLOOKUP(K2,源_4奖金汇总表_拆分手工算!$A:$N,8,FALSE),0) -> 25.5 | Y2: =IFERROR(VLOOKUP(K2,源_5薪资备忘录_工资调整项!$A:$AC,14,FALSE),0) -> 0 | Z2: =IFERROR(VLOOKUP(K2,源_5薪资备忘录_工资调整项!$A:$AC,16,FALSE),0) -> 0 | AA2: =IFERROR(VLOOKUP(K2,源_5薪资备忘录_工资调整项!$A:$AC,15,FALSE),0) -> 0 | AB2: =AC2+AD2+AF2 -> 0 | AC2: =IF(P2="门店全职",R2/174*MAX(IFERROR(VLOOKUP(K2,源_3考勤报表_考勤表!$F:$BG,34,FALSE),0)+IFERROR(VLOOKUP(K2,源_8补工时表_补当月工时!$A:$AC,14,FALSE),0)+IFERROR(VLOOKUP(K2,源_3考勤报表_考勤表!$F:$BG,37,FALSE),0)+IFERROR(VLOOKUP(K2,源_8补工时表_补当月工时!$A:$AC,15,FALSE),0)+IFERROR(VLOOKUP(K2,源_3考勤报表_考勤表!$F:$BG,38,FALSE),0)+IFERROR(VLOOKUP(K2,源_8补工时表_补当月工时!$A:$AC,17,FALSE),0)+IFERROR(VLOOKUP(K2,源_3考勤报表_考勤表!$F:$BG,40,FALSE),0)+IFERROR(VLOOKUP(K2,源_8补工时表_补当月工时!$A:$AC,20,FALSE),0)+IFERROR(VLOOKUP(K2,源_8补工时表_补当月工时!$A:$AC,22,FALSE),0)+IFERROR(VLOOKUP(K2,源_3考勤报表_考勤表!$F:$BG,41,FALSE),0)+IFERROR(VLOOKUP(K2,源_8补工时表_补当月工时!$A:$AC,18,FALSE),0)+IFERROR(VLOOKUP(K2,源_3考勤报表_考勤表!$F:$BG,42,FALSE),0)+IFERROR(VLOOKUP(K2,源_8补工时表_补当月工时!$A:$AC,19,FALSE),0)+IFERROR(VLOOKUP(K2,源_3考勤报表_考勤表!$F:$BG,44,FALSE),0)+IFERROR(VLOOKUP(K2,源_8补工时表_补当月工时!$A:$AC,16,FALSE),0)+IFERROR(VLOOKUP(K2,源_3考勤报表_考勤表!$F:$BG,45,FALSE),0)-参数!$B$4,0)*1.5,0) -> 0 | AD2: 0 | AE2: =IFERROR(VLOOKUP(K2,源_3考勤报表_考勤表!$F:$BG,46,FALSE),0)+IFERROR(VLOOKUP(K2,源_8补工时表_补当月工时!$A:$AC,25,FALSE),0) -> 0 | AF2: =R2/174*AE2*3 -> 0 | AG2: =IFERROR(VLOOKUP(K2,源_4奖金汇总表_拆分手工算!$A:$N,10,FALSE),0) -> 0 | AH2: =IFERROR(VLOOKUP(K2,源_4奖金汇总表_拆分手工算!$A:$N,5,FALSE),0) -> 0 | AI2: =IFERROR(VLOOKUP(K2,源_4奖金汇总表_拆分手工算!$A:$N,11,FALSE),0) -> 2000 | AJ2: =IFERROR(VLOOKUP(K2,源_4奖金汇总表_拆分手工算!$A:$N,4,FALSE),0) -> 1500 | AK2: =IFERROR(VLOOKUP(K2,源_4奖金汇总表_拆分手工算!$A:$N,3,FALSE),0) -> 9000 | AL2: =IFERROR(VLOOKUP(K2,源_4奖金汇总表_拆分手工算!$A:$N,6,FALSE),0) -> 0 | AM2: =IFERROR(VLOOKUP(K2,源_5薪资备忘录_工资调整项!$A:$AC,18,FALSE),0)+IFERROR(VLOOKUP(K2,源_4奖金汇总表_拆分手工算!$A:$N,7,FALSE),0) -> 0 | AN2: =IFERROR(VLOOKUP(K2,源_5薪资备忘录_工资调整项!$A:$AC,17,FALSE),0) -> 0 | AO2: =IF(OR(IFERROR(VLOOKUP(K2,源_3考勤报表_考勤表!$F:$BG,39,FALSE),0)+IFERROR(VLOOKUP(K2,源_8补工时表_补当月工时!$A:$AC,24,FALSE),0)>0,IFERROR(VLOOKUP(K2,源_3考勤报表_考勤表!$F:$BG,43,FALSE),0)+IFERROR(VLOOKUP(K2,源_8补工时表_补当月工时!$A:$AC,26,FALSE),0)>0),IF(IFERROR(VLOOKUP(DH2,源_11产假政策_Sheet1!$C:$F,4,FALSE),"")="是",R2/参数!$B$4*(IFERROR(VLOOKUP(K2,源_3考勤报表_考勤表!$F:$BG,39,FALSE),0)+IFERROR(VLOOKUP(K2,源_8补工时表_补当月工时!$A:$AC,24,FALSE),0)+IFERROR(VLOOKUP(K2,源_3考勤报表_考勤表!$F:$BG,43,FALSE),0)+IFERROR(VLOOKUP(K2,源_8补工时表_补当月工时!$A:$AC,26,FALSE),0)),IFERROR(VLOOKUP(K2,源_5薪资备忘录_工资调整项!$A:$AC,19,FALSE),0)),0) -> 0 | AP2: 0 | AQ2: =IFERROR(VLOOKUP(K2,源_4奖金汇总表_拆分手工算!$A:$N,12,FALSE),0)+IFERROR(VLOOKUP(K2,源_9年终奖表_Sheet1!$A:$E,3,FALSE),0) -> 0 | AR2: =IFERROR(VLOOKUP(K2,源_4奖金汇总表_拆分手工算!$A:$N,13,FALSE),0)+IFERROR(VLOOKUP(K2,源_9年终奖表_Sheet1!$A:$E,4,FALSE),0) -> 0 | AS2: =IFERROR(VLOOKUP(K2,源_4奖金汇总表_拆分手工算!$A:$N,14,FALSE),0)+IFERROR(VLOOKUP(K2,源_9年终奖表_Sheet1!$A:$E,5,FALSE),0) -> 0 | AT2: =IFERROR(VLOOKUP(K2,源_5薪资备忘录_工资调整项!$A:$AC,20,FALSE),0) -> 0 | AU2: =IFERROR(VLOOKUP(K2,源_5薪资备忘录_工资调整项!$A:$AC,21,FALSE),0)+IFERROR(VLOOKUP(K2,源_4奖金汇总表_拆分手工算!$A:$N,9,FALSE),0) -> 1733.79 | AV2: =R2/参数!$B$4*(IFERROR(VLOOKUP(K2,源_3考勤报表_考勤表!$F:$BG,37,FALSE),0)+IFERROR(VLOOKUP(K2,源_8补工时表_补当月工时!$A:$AC,15,FALSE),0)) -> 653.3913 | AW2: =R2/174*MIN(IFERROR(VLOOKUP(K2,源_3考勤报表_考勤表!$F:$BG,35,FALSE),0),174)*IF(DATEDIF(N2,DATE(参数!$B$2,参数!$B$3+1,0),"Y")<2,0.6,IF(DATEDIF(N2,DATE(参数!$B$2,参数!$B$3+1,0),"Y")<4,0.7,IF(DATEDIF(N2,DATE(参数!$B$2,参数!$B$3+1,0),"Y")<6,0.8,IF(DATEDIF(N2,DATE(参数!$B$2,参数!$B$3+1,0),"Y")<8,0.9,1)))) -> 0 | AX2: =IF(Q2+IFERROR(VLOOKUP(K2,源_3考勤报表_考勤表!$F:$BG,37,FALSE),0)+IFERROR(VLOOKUP(K2,源_8补工时表_补当月工时!$A:$AC,15,FALSE),0)>=参数!$B$4,0,IF(Q2+IFERROR(VLOOKUP(K2,源_3考勤报表_考勤表!$F:$BG,37,FALSE),0)+IFERROR(VLOOKUP(K2,源_8补工时表_补当月工时!$A:$AC,15,FALSE),0)+IFERROR(VLOOKUP(K2,源_3考勤报表_考勤表!$F:$BG,38,FALSE),0)+IFERROR(VLOOKUP(K2,源_8补工时表_补当月工时!$A:$AC,17,FALSE),0)+IFERROR(VLOOKUP(K2,源_3考勤报表_考勤表!$F:$BG,40,FALSE),0)+IFERROR(VLOOKUP(K2,源_8补工时表_补当月工时!$A:$AC,20,FALSE),0)+IFERROR(VLOOKUP(K2,源_8补工时表_补当月工时!$A:$AC,22,FALSE),0)+IFERROR(VLOOKUP(K2,源_3考勤报表_考勤表!$F:$BG,41,FALSE),0)+IFERROR(VLOOKUP(K2,源_8补工时表_补当月工时!$A:$AC,18,FALSE),0)+IFERROR(VLOOKUP(K2,源_3考勤报表_考勤表!$F:$BG,42,FALSE),0)+IFERROR(VLOOKUP(K2,源_8补工时表_补当月工时!$A:$AC,19,FALSE),0)+IFERROR(VLOOKUP(K2,源_3考勤报表_考勤表!$F:$BG,44,FALSE),0)+IFERROR(VLOOKUP(K2,源_8补工时表_补当月工时!$A:$AC,16,FALSE),0)+IFERROR(VLOOKUP(K2,源_3考勤报表_考勤表!$F:$BG,45,FALSE),0)<=参数!$B$4,R2/参数!$B$4*(IFERROR(VLOOKUP(K2,源_3考勤报表_考勤表!$F:$BG,38,FALSE),0)+IFERROR(VLOOKUP(K2,源_8补工时表_补当月工时!$A:$AC,17,FALSE),0)+IFERROR(VLOOKUP(K2,源_3考勤报表_考勤表!$F:$BG,40,FALSE),0)+IFERROR(VLOOKUP(K2,源_8补工时表_补当月工时!$A:$AC,20,FALSE),0)+IFERROR(VLOOKUP(K2,源_8补工时表_补当月工时!$A:$AC,22,FALSE),0)+IFERROR(VLOOKUP(K2,源_3考勤报表_考勤表!$F:$BG,41,FALSE),0)+IFERROR(VLOOKUP(K2,源_8补工时表_补当月工时!$A:$AC,18,FALSE),0)+IFERROR(VLOOKUP(K2,源_3考勤报表_考勤表!$F:$BG,42,FALSE),0)+IFERROR(VLOOKUP(K2,源_8补工时表_补当月工时!$A:$AC,19,FALSE),0)+IFERROR(VLOOKUP(K2,源_3考勤报表_考勤表!$F:$BG,44,FALSE),0)+IFERROR(VLOOKUP(K2,源_8补工时表_补当月工时!$A:$AC,16,FALSE),0)+IFERROR(VLOOKUP(K2,源_3考勤报表_考勤表!$F:$BG,45,FALSE),0)),0)) -> 0 | AY2: 0 | AZ2: 0 | BA2: 0 | BB2: 0 | BC2: =IFERROR(VLOOKUP(K2,源_5薪资备忘录_工资调整项!$A:$AC,25,FALSE),0) -> 0 | BD2: 0 | BE2: 0 | BF2: 0 | BG2: =IFERROR(VLOOKUP(K2,源_5薪资备忘录_工资调整项!$A:$AC,22,FALSE),0)+IFERROR(VLOOKUP(K2,源_5薪资备忘录_工资调整项!$A:$AC,23,FALSE),0)+IFERROR(VLOOKUP(K2,源_5薪资备忘录_工资调整项!$A:$AC,24,FALSE),0) -> 0 | BH2: =IFERROR(VLOOKUP(DF2,源_6社保表_Sheet1!$C:$CD,80,FALSE),0)+4.5 -> 6.5 | BI2: =T2+W2+AB2+AG2+AH2+AI2+AJ2+AK2+AL2+AM2+AN2+AO2+AP2+AQ2+AR2+AS2+AT2+AU2+AV2+AW2+AX2+BC2 -> 21773.29 | BJ2: =IFERROR(VLOOKUP(DF2,源_6社保表_Sheet1!$C:$BZ,26,FALSE),0) -> 782.96 | BK2: =IFERROR(VLOOKUP(DF2,源_6社保表_Sheet1!$C:$BZ,27,FALSE),0) -> 195.74 | BL2: =IFERROR(VLOOKUP(DF2,源_6社保表_Sheet1!$C:$BZ,28,FALSE),0) -> 48.935 | BM2: =IFERROR(VLOOKUP(DF2,源_6社保表_Sheet1!$C:$BZ,30,FALSE),0) -> 685.09 | BN2: =IFERROR(VLOOKUP(DF2,源_6社保表_Sheet1!$C:$BZ,29,FALSE),0) -> 0 | BO2: =IFERROR(VLOOKUP(DF2,源_6社保表_Sheet1!$C:$BZ,40,FALSE),0) -> 700.96 | BP2: =IFERROR(VLOOKUP(DF2,源_6社保表_Sheet1!$C:$BZ,41,FALSE),0) -> 100.74 | BQ2: =IFERROR(VLOOKUP(DF2,源_6社保表_Sheet1!$C:$BZ,42,FALSE),0) -> 40.935 | BR2: =IFERROR(VLOOKUP(DF2,源_6社保表_Sheet1!$C:$BZ,44,FALSE),0) -> 600.09 | BS2: =IFERROR(VLOOKUP(DF2,源_6社保表_Sheet1!$C:$BZ,43,FALSE),0) -> 0 | BT2: =BJ2+BK2+BL2+BM2+BN2+BO2+BP2+BQ2+BR2+BS2 -> 3155.45 | BU2: 0 | BV2: 0 | BW2: 0 | BX2: =BU2+BV2+BW2 -> 0 | BY2: 0 | BZ2: =IFERROR(VLOOKUP(DF2,源_6社保表_Sheet1!$C:$BZ,18,FALSE),0) -> 1565.92 | CA2: =IFERROR(VLOOKUP(DF2,源_6社保表_Sheet1!$C:$BZ,19,FALSE),0) -> 880.83 | CB2: =IFERROR(VLOOKUP(DF2,源_6社保表_Sheet1!$C:$BZ,24,FALSE),0) -> 685.09 | CC2: =IFERROR(VLOOKUP(DF2,源_6社保表_Sheet1!$C:$BZ,20,FALSE),0) -> 48.935 | CD2: =IFERROR(VLOOKUP(DF2,源_6社保表_Sheet1!$C:$BZ,21,FALSE),0) -> 31.3184 | CE2: =IFERROR(VLOOKUP(DF2,源_6社保表_Sheet1!$C:$BZ,22,FALSE),0) -> 0 | CF2: =IFERROR(VLOOKUP(DF2,源_6社保表_Sheet1!$C:$BZ,23,FALSE),0) -> 0 | CG2: =IFERROR(VLOOKUP(DF2,源_6社保表_Sheet1!$C:$BZ,32,FALSE),0) -> 1500.92 | CH2: =IFERROR(VLOOKUP(DF2,源_6社保表_Sheet1!$C:$BZ,33,FALSE),0) -> 800.83 | CI2: =IFERROR(VLOOKUP(DF2,源_6社保表_Sheet1!$C:$BZ,34,FALSE),0) -> 40.935 | CJ2: =IFERROR(VLOOKUP(DF2,源_6社保表_Sheet1!$C:$BZ,38,FALSE),0) -> 600.09 | CK2: =IFERROR(VLOOKUP(DF2,源_6社保表_Sheet1!$C:$BZ,35,FALSE),0) -> 30.3184 | CL2: =IFERROR(VLOOKUP(DF2,源_6社保表_Sheet1!$C:$BZ,36,FALSE),0) -> 0 | CM2: =IFERROR(VLOOKUP(DF2,源_6社保表_Sheet1!$C:$BZ,37,FALSE),0) -> 0 | CN2: =BZ2+CA2+CB2+CC2+CD2+CE2+CF2+CG2+CH2+CI2+CJ2+CK2+CL2+CM2 -> 6185.1868 | CO2: =BI2+BG2+CN2+BE2+BH2 -> 27964.977 | CP2: =IF(IFERROR(VLOOKUP(K2,源_13残疾人信息_残疾人信息!$A:$M,1,FALSE),"")<>"",0,IF(OR(P2="门店全职",P2="门店管理组",P2="全职(非门店)"),(BI2-AT2)*IFERROR(VLOOKUP(D2,源_12计提残保金规则_Sheet1!$A:$E,4,FALSE),0)*IFERROR(VLOOKUP(D2,源_12计提残保金规则_Sheet1!$A:$E,5,FALSE),0),0)) -> 293.93942 | CQ2: =IF(M2="行政",0,16.05) -> 16.05 | CR2: =IF(M2="门卫",0,20.67) -> 20.67 | CS2: =IF(DATEVALUE(N2)>DATE(参数!$B$2,9,30),0,IF(M2="行政",0,IF(O2="",R2/12,IF(MONTH(DATEVALUE(O2))=参数!$B$3,0,IF(DATEVALUE(O2)<DATE(参数!$B$2,参数!$B$3,1),0,R2/12))))) -> 0 | CT2: =IF(P2="门店管理组",R2*0.12*0.85,0) -> 766.428 | CU2: =IFERROR(VLOOKUP(DF2,源_6社保表_Sheet1!$C:$I,2,FALSE),0) -> 9787 | CV2: =IFERROR(VLOOKUP(DF2,源_6社保表_Sheet1!$C:$I,7,FALSE),0) -> 9787 | CW2: =IFERROR(VLOOKUP(DF2,源_6社保表_Sheet1!$C:$I,3,FALSE),0) -> 9787 | CX2: =IFERROR(VLOOKUP(DF2,源_6社保表_Sheet1!$C:$I,4,FALSE),0) -> 9787 | CY2: =IFERROR(VLOOKUP(DF2,源_6社保表_Sheet1!$C:$I,5,FALSE),0) -> 9787 | CZ2: =IFERROR(VLOOKUP(DF2,源_6社保表_Sheet1!$C:$I,6,FALSE),0) -> 0 | DA2: =BI2+CN2-AG2-AH2-AI2-AJ2-AK2-AL2-AM2-AQ2-AR2-AS2-AT2 -> 15458.477 | DB2: =DA2+CP2+CQ2+CR2+CS2+CT2+BH2 -> 16562.064 | DC2: =IFERROR(VLOOKUP(K2,源_7银行卡表_Sheet1!$A:$J,8,FALSE),"") -> 招商银行 | DD2: =IFERROR(VLOOKUP(K2,源_7银行卡表_Sheet1!$A:$J,9,FALSE),"") -> 6684906511538095695 | DE2: =IFERROR(VLOOKUP(K2,源_7银行卡表_Sheet1!$A:$J,10,FALSE),"") -> 东莞滨海湾新区支行 | DF2: 140000197007051683 | DG2: 16755985896 | DH2: 上海 | DI2: 0 | DJ2: 0 | DK2: 0 | DL2: 0 | DM2: 0 | DN2: 0 | DO2: 0 | DP2: 0 | DQ2: 0 | DR2: =IF(OR(IFERROR(VLOOKUP(K2,源_3考勤报表_考勤表!$F:$BG,39,FALSE),0)+IFERROR(VLOOKUP(K2,源_8补工时表_补当月工时!$A:$AC,24,FALSE),0)=0,IFERROR(VLOOKUP(K2,源_3考勤报表_考勤表!$F:$BG,43,FALSE),0)+IFERROR(VLOOKUP(K2,源_8补工时表_补当月工时!$A:$AC,26,FALSE),0)=0),IF(BI2+BG2-BT2<0,BI2+BG2-BT2,0),0) -> 0
A3: =参数!$B$2 -> 2025 | B3: =参数!$B$3 -> 12 | D3: 上海达美乐 | E3: 店铺营运 | F3: =IFERROR(VLOOKUP(K3,源_7银行卡表_Sheet1!$A:$J,6,FALSE),"") -> 华东营运 | G3: 上海2 | H3: 龙华西路店 | I3: 外服-上海门店全职 | J3: 1 | K3: 26123002 | L3: 程绍辉 | M3: 餐厅经理 | N3: 2014-06-18 | P3: 门店管理组 | Q3: =IF(P3="门店全职",IFERROR(VLOOKUP(K3,源_3考勤报表_考勤表!$F:$BG,34,FALSE),0)+IFERROR(VLOOKUP(K3,源_8补工时表_补当月工时!$A:$AC,14,FALSE),0),IF(P3="门店管理组",IF(IFERROR(VLOOKUP(K3,源_3考勤报表_考勤表!$F:$BG,34,FALSE),0)+IFERROR(VLOOKUP(K3,源_8补工时表_补当月工时!$A:$AC,14,FALSE),0)+IFERROR(VLOOKUP(K3,源_3考勤报表_考勤表!$F:$BG,37,FALSE),0)+IFERROR(VLOOKUP(K3,源_8补工时表_补当月工时!$A:$AC,15,FALSE),0)+IFERROR(VLOOKUP(K3,源_3考勤报表_考勤表!$F:$BG,38,FALSE),0)+IFERROR(VLOOKUP(K3,源_8补工时表_补当月工时!$A:$AC,17,FALSE),0)+IFERROR(VLOOKUP(K3,源_3考勤报表_考勤表!$F:$BG,40,FALSE),0)+IFERROR(VLOOKUP(K3,源_8补工时表_补当月工时!$A:$AC,20,FALSE),0)+IFERROR(VLOOKUP(K3,源_8补工时表_补当月工时!$A:$AC,22,FALSE),0)+IFERROR(VLOOKUP(K3,源_3考勤报表_考勤表!$F:$BG,41,FALSE),0)+IFERROR(VLOOKUP(K3,源_8补工时表_补当月工时!$A:$AC,18,FALSE),0)+IFERROR(VLOOKUP(K3,源_3考勤报表_考勤表!$F:$BG,44,FALSE),0)+IFERROR(VLOOKUP(K3,源_8补工时表_补当月工时!$A:$AC,16,FALSE),0)+IFERROR(VLOOKUP(K3,源_3考勤报表_考勤表!$F:$BG,45,FALSE),0)>=参数!$B$4,参数!$B$4-IFERROR(VLOOKUP(K3,源_3考勤报表_考勤表!$F:$BG,37,FALSE),0)-IFERROR(VLOOKUP(K3,源_8补工时表_补当月工时!$A:$AC,15,FALSE),0)-IFERROR(VLOOKUP(K3,源_3考勤报表_考勤表!$F:$BG,38,FALSE),0)-IFERROR(VLOOKUP(K3,源_8补工时表_补当月工时!$A:$AC,17,FALSE),0)-IFERROR(VLOOKUP(K3,源_3考勤报表_考勤表!$F:$BG,40,FALSE),0)-IFERROR(VLOOKUP(K3,源_8补工时表_补当月工时!$A:$AC,20,FALSE),0)-IFERROR(VLOOKUP(K3,源_8补工时表_补当月工时!$A:$AC,22,FALSE),0)-IFERROR(VLOOKUP(K3,源_3考勤报表_考勤表!$F:$BG,41,FALSE),0)-IFERROR(VLOOKUP(K3,源_8补工时表_补当月工时!$A:$AC,18,FALSE),0)-IFERROR(VLOOKUP(K3,源_3考勤报表_考勤表!$F:$BG,44,FALSE),0)-IFERROR(VLOOKUP(K3,源_8补工时表_补当月工时!$A:$AC,16,FALSE),0)-IFERROR(VLOOKUP(K3,源_3考勤报表_考勤表!$F:$BG,45,FALSE),0),IFERROR(VLOOKUP(K3,源_3考勤报表_考勤表!$F:$BG,34,FALSE),0)+IFERROR(VLOOKUP(K3,源_8补工时表_补当月工时!$A:$AC,14,FALSE),0)),0)) -> 184 | R3: 7809 | S3: 0 | T3: =IF(P3="门店全职",R3/参数!$B$4*(Q3-MAX(IFERROR(VLOOKUP(K3,源_3考勤报表_考勤表!$F:$BG,34,FALSE),0)+IFERROR(VLOOKUP(K3,源_8补工时表_补当月工时!$A:$AC,14,FALSE),0)+IFERROR(VLOOKUP(K3,源_3考勤报表_考勤表!$F:$BG,37,FALSE),0)+IFERROR(VLOOKUP(K3,源_8补工时表_补当月工时!$A:$AC,15,FALSE),0)+IFERROR(VLOOKUP(K3,源_3考勤报表_考勤表!$F:$BG,38,FALSE),0)+IFERROR(VLOOKUP(K3,源_8补工时表_补当月工时!$A:$AC,17,FALSE),0)+IFERROR(VLOOKUP(K3,源_3考勤报表_考勤表!$F:$BG,40,FALSE),0)+IFERROR(VLOOKUP(K3,源_8补工时表_补当月工时!$A:$AC,20,FALSE),0)+IFERROR(VLOOKUP(K3,源_8补工时表_补当月工时!$A:$AC,22,FALSE),0)+IFERROR(VLOOKUP(K3,源_3考勤报表_考勤表!$F:$BG,41,FALSE),0)+IFERROR(VLOOKUP(K3,源_8补工时表_补当月工时!$A:$AC,18,FALSE),0)+IFERROR(VLOOKUP(K3,源_3考勤报表_考勤表!$F:$BG,42,FALSE),0)+IFERROR(VLOOKUP(K3,源_8补工时表_补当月工时!$A:$AC,19,FALSE),0)+IFERROR(VLOOKUP(K3,源_3考勤报表_考勤表!$F:$BG,44,FALSE),0)+IFERROR(VLOOKUP(K3,源_8补工时表_补当月工时!$A:$AC,16,FALSE),0)+IFERROR(VLOOKUP(K3,源_3考勤报表_考勤表!$F:$BG,45,FALSE),0)-参数!$B$4,0)),R3/参数!$B$4*Q3) -> 7809 | U3: 0 | V3: 0 | W3: =X3+Y3+Z3+AA3 -> 7 | X3: =IFERROR(VLOOKUP(K3,源_4奖金汇总表_拆分手工算!$A:$N,8,FALSE),0) -> 7 | Y3: =IFERROR(VLOOKUP(K3,源_5薪资备忘录_工资调整项!$A:$AC,14,FALSE),0) -> 0 | Z3: =IFERROR(VLOOKUP(K3,源_5薪资备忘录_工资调整项!$A:$AC,16,FALSE),0) -> 0 | AA3: =IFERROR(VLOOKUP(K3,源_5薪资备忘录_工资调整项!$A:$AC,15,FALSE),0) -> 0 | AB3: =AC3+AD3+AF3 -> 0 | AC3: =IF(P3="门店全职",R3/174*MAX(IFERROR(VLOOKUP(K3,源_3考勤报表_考勤表!$F:$BG,34,FALSE),0)+IFERROR(VLOOKUP(K3,源_8补工时表_补当月工时!$A:$AC,14,FALSE),0)+IFERROR(VLOOKUP(K3,源_3考勤报表_考勤表!$F:$BG,37,FALSE),0)+IFERROR(VLOOKUP(K3,源_8补工时表_补当月工时!$A:$AC,15,FALSE),0)+IFERROR(VLOOKUP(K3,源_3考勤报表_考勤表!$F:$BG,38,FALSE),0)+IFERROR(VLOOKUP(K3,源_8补工时表_补当月工时!$A:$AC,17,FALSE),0)+IFERROR(VLOOKUP(K3,源_3考勤报表_考勤表!$F:$BG,40,FALSE),0)+IFERROR(VLOOKUP(K3,源_8补工时表_补当月工时!$A:$AC,20,FALSE),0)+IFERROR(VLOOKUP(K3,源_8补工时表_补当月工时!$A:$AC,22,FALSE),0)+IFERROR(VLOOKUP(K3,源_3考勤报表_考勤表!$F:$BG,41,FALSE),0)+IFERROR(VLOOKUP(K3,源_8补工时表_补当月工时!$A:$AC,18,FALSE),0)+IFERROR(VLOOKUP(K3,源_3考勤报表_考勤表!$F:$BG,42,FALSE),0)+IFERROR(VLOOKUP(K3,源_8补工时表_补当月工时!$A:$AC,19,FALSE),0)+IFERROR(VLOOKUP(K3,源_3考勤报表_考勤表!$F:$BG,44,FALSE),0)+IFERROR(VLOOKUP(K3,源_8补工时表_补当月工时!$A:$AC,16,FALSE),0)+IFERROR(VLOOKUP(K3,源_3考勤报表_考勤表!$F:$BG,45,FALSE),0)-参数!$B$4,0)*1.5,0) -> 0 | AD3: 0 | AE3: =IFERROR(VLOOKUP(K3,源_3考勤报表_考勤表!$F:$BG,46,FALSE),0)+IFERROR(VLOOKUP(K3,源_8补工时表_补当月工时!$A:$AC,25,FALSE),0) -> 0 | AF3: =R3/174*AE3*3 -> 0 | AG3: =IFERROR(VLOOKUP(K3,源_4奖金汇总表_拆分手工算!$A:$N,10,FALSE),0) -> 0 | AH3: =IFERROR(VLOOKUP(K3,源_4奖金汇总表_拆分手工算!$A:$N,5,FALSE),0) -> 0 | AI3: =IFERROR(VLOOKUP(K3,源_4奖金汇总表_拆分手工算!$A:$N,11,FALSE),0) -> 1500 | AJ3: =IFERROR(VLOOKUP(K3,源_4奖金汇总表_拆分手工算!$A:$N,4,FALSE),0) -> 1000 | AK3: =IFERROR(VLOOKUP(K3,源_4奖金汇总表_拆分手工算!$A:$N,3,FALSE),0) -> 7000 | AL3: =IFERROR(VLOOKUP(K3,源_4奖金汇总表_拆分手工算!$A:$N,6,FALSE),0) -> 100 | AM3: =IFERROR(VLOOKUP(K3,源_5薪资备忘录_工资调整项!$A:$AC,18,FALSE),0)+IFERROR(VLOOKUP(K3,源_4奖金汇总表_拆分手工算!$A:$N,7,FALSE),0) -> 200 | AN3: =IFERROR(VLOOKUP(K3,源_5薪资备忘录_工资调整项!$A:$AC,17,FALSE),0) -> 0 | AO3: =IF(OR(IFERROR(VLOOKUP(K3,源_3考勤报表_考勤表!$F:$BG,39,FALSE),0)+IFERROR(VLOOKUP(K3,源_8补工时表_补当月工时!$A:$AC,24,FALSE),0)>0,IFERROR(VLOOKUP(K3,源_3考勤报表_考勤表!$F:$BG,43,FALSE),0)+IFERROR(VLOOKUP(K3,源_8补工时表_补当月工时!$A:$AC,26,FALSE),0)>0),IF(IFERROR(VLOOKUP(DH3,源_11产假政策_Sheet1!$C:$F,4,FALSE),"")="是",R3/参数!$B$4*(IFERROR(VLOOKUP(K3,源_3考勤报表_考勤表!$F:$BG,39,FALSE),0)+IFERROR(VLOOKUP(K3,源_8补工时表_补当月工时!$A:$AC,24,FALSE),0)+IFERROR(VLOOKUP(K3,源_3考勤报表_考勤表!$F:$BG,43,FALSE),0)+IFERROR(VLOOKUP(K3,源_8补工时表_补当月工时!$A:$AC,26,FALSE),0)),IFERROR(VLOOKUP(K3,源_5薪资备忘录_工资调整项!$A:$AC,19,FALSE),0)),0) -> 0 | AP3: 0 | AQ3: =IFERROR(VLOOKUP(K3,源_4奖金汇总表_拆分手工算!$A:$N,12,FALSE),0)+IFERROR(VLOOKUP(K3,源_9年终奖表_Sheet1!$A:$E,3,FALSE),0) -> 1200 | AR3: =IFERROR(VLOOKUP(K3,源_4奖金汇总表_拆分手工算!$A:$N,13,FALSE),0)+IFERROR(VLOOKUP(K3,源_9年终奖表_Sheet1!$A:$E,4,FALSE),0) -> 600 | AS3: =IFERROR(VLOOKUP(K3,源_4奖金汇总表_拆分手工算!$A:$N,14,FALSE),0)+IFERROR(VLOOKUP(K3,源_9年终奖表_Sheet1!$A:$E,5,FALSE),0) -> 111 | AT3: =IFERROR(VLOOKUP(K3,源_5薪资备忘录_工资调整项!$A:$AC,20,FALSE),0) -> 0 | AU3: =IFERROR(VLOOKUP(K3,源_5薪资备忘录_工资调整项!$A:$AC,21,FALSE),0)+IFERROR(VLOOKUP(K3,源_4奖金汇总表_拆分手工算!$A:$N,9,FALSE),0) -> 0 | AV3: =R3/参数!$B$4*(IFERROR(VLOOKUP(K3,源_3考勤报表_考勤表!$F:$BG,37,FALSE),0)+IFERROR(VLOOKUP(K3,源_8补工时表_补当月工时!$A:$AC,15,FALSE),0)) -> 0 | AW3: =R3/174*MIN(IFERROR(VLOOKUP(K3,源_3考勤报表_考勤表!$F:$BG,35,FALSE),0),174)*IF(DATEDIF(N3,DATE(参数!$B$2,参数!$B$3+1,0),"Y")<2,0.6,IF(DATEDIF(N3,DATE(参数!$B$2,参数!$B$3+1,0),"Y")<4,0.7,IF(DATEDIF(N3,DATE(参数!$B$2,参数!$B$3+1,0),"Y")<6,0.8,IF(DATEDIF(N3,DATE(参数!$B$2,参数!$B$3+1,0),"Y")<8,0.9,1)))) -> 0 | AX3: =IF(Q3+IFERROR(VLOOKUP(K3,源_3考勤报表_考勤表!$F:$BG,37,FALSE),0)+IFERROR(VLOOKUP(K3,源_8补工时表_补当月工时!$A:$AC,15,FALSE),0)>=参数!$B$4,0,IF(Q3+IFERROR(VLOOKUP(K3,源_3考勤报表_考勤表!$F:$BG,37,FALSE),0)+IFERROR(VLOOKUP(K3,源_8补工时表_补当月工时!$A:$AC,15,FALSE),0)+IFERROR(VLOOKUP(K3,源_3考勤报表_考勤表!$F:$BG,38,FALSE),0)+IFERROR(VLOOKUP(K3,源_8补工时表_补当月工时!$A:$AC,17,FALSE),0)+IFERROR(VLOOKUP(K3,源_3考勤报表_考勤表!$F:$BG,40,FALSE),0)+IFERROR(VLOOKUP(K3,源_8补工时表_补当月工时!$A:$AC,20,FALSE),0)+IFERROR(VLOOKUP(K3,源_8补工时表_补当月工时!$A:$AC,22,FALSE),0)+IFERROR(VLOOKUP(K3,源_3考勤报表_考勤表!$F:$BG,41,FALSE),0)+IFERROR(VLOOKUP(K3,源_8补工时表_补当月工时!$A:$AC,18,FALSE),0)+IFERROR(VLOOKUP(K3,源_3考勤报表_考勤表!$F:$BG,42,FALSE),0)+IFERROR(VLOOKUP(K3,源_8补工时表_补当月工时!$A:$AC,19,FALSE),0)+IFERROR(VLOOKUP(K3,源_3考勤报表_考勤表!$F:$BG,44,FALSE),0)+IFERROR(VLOOKUP(K3,源_8补工时表_补当月工时!$A:$AC,16,FALSE),0)+IFERROR(VLOOKUP(K3,源_3考勤报表_考勤表!$F:$BG,45,FALSE),0)<=参数!$B$4,R3/参数!$B$4*(IFERROR(VLOOKUP(K3,源_3考勤报表_考勤表!$F:$BG,38,FALSE),0)+IFERROR(VLOOKUP(K3,源_8补工时表_补当月工时!$A:$AC,17,FALSE),0)+IFERROR(VLOOKUP(K3,源_3考勤报表_考勤表!$F:$BG,40,FALSE),0)+IFERROR(VLOOKUP(K3,源_8补工时表_补当月工时!$A:$AC,20,FALSE),0)+IFERROR(VLOOKUP(K3,源_8补工时表_补当月工时!$A:$AC,22,FALSE),0)+IFERROR(VLOOKUP(K3,源_3考勤报表_考勤表!$F:$BG,41,FALSE),0)+IFERROR(VLOOKUP(K3,源_8补工时表_补当月工时!$A:$AC,18,FALSE),0)+IFERROR(VLOOKUP(K3,源_3考勤报表_考勤表!$F:$BG,42,FALSE),0)+IFERROR(VLOOKUP(K3,源_8补工时表_补当月工时!$A:$AC,19,FALSE),0)+IFERROR(VLOOKUP(K3,源_3考勤报表_考勤表!$F:$BG,44,FALSE),0)+IFERROR(VLOOKUP(K3,源_8补工时表_补当月工时!$A:$AC,16,FALSE),0)+IFERROR(VLOOKUP(K3,源_3考勤报表_考勤表!$F:$BG,45,FALSE),0)),0)) -> 0 | AY3: 0 | AZ3: 0 | BA3: 0 | BB3: 0 | BC3: =IFERROR(VLOOKUP(K3,源_5薪资备忘录_工资调整项!$A:$AC,25,FALSE),0) -> 0 | BD3: 0 | BE3: 0 | BF3: 0 | BG3: =IFERROR(VLOOKUP(K3,源_5薪资备忘录_工资调整项!$A:$AC,22,FALSE),0)+IFERROR(VLOOKUP(K3,源_5薪资备忘录_工资调整项!$A:$AC,23,FALSE),0)+IFERROR(VLOOKUP(K3,源_5薪资备忘录_工资调整项!$A:$AC,24,FALSE),0) -> 0 | BH3: =IFERROR(VLOOKUP(DF3,源_6社保表_Sheet1!$C:$CD,80,FALSE),0)+4.5 -> 6.5 | BI3: =T3+W3+AB3+AG3+AH3+AI3+AJ3+AK3+AL3+AM3+AN3+AO3+AP3+AQ3+AR3+AS3+AT3+AU3+AV3+AW3+AX3+BC3 -> 19527 | BJ3: =IFERROR(VLOOKUP(DF3,源_6社保表_Sheet1!$C:$BZ,26,FALSE),0) -> 797.68 | BK3: =IFERROR(VLOOKUP(DF3,源_6社保表_Sheet1!$C:$BZ,27,FALSE),0) -> 199.42 | BL3: =IFERROR(VLOOKUP(DF3,源_6社保表_Sheet1!$C:$BZ,28,FALSE),0) -> 49.855 | BM3: =IFERROR(VLOOKUP(DF3,源_6社保表_Sheet1!$C:$BZ,30,FALSE),0) -> 697.97 | BN3: =IFERROR(VLOOKUP(DF3,源_6社保表_Sheet1!$C:$BZ,29,FALSE),0) -> 0 | BO3: =IFERROR(VLOOKUP(DF3,源_6社保表_Sheet1!$C:$BZ,40,FALSE),0) -> 0 | BP3: =IFERROR(VLOOKUP(DF3,源_6社保表_Sheet1!$C:$BZ,41,FALSE),0) -> 0 | BQ3: =IFERROR(VLOOKUP(DF3,源_6社保表_Sheet1!$C:$BZ,42,FALSE),0) -> 0 | BR3: =IFERROR(VLOOKUP(DF3,源_6社保表_Sheet1!$C:$BZ,44,FALSE),0) -> 0 | BS3: =IFERROR(VLOOKUP(DF3,源_6社保表_Sheet1!$C:$BZ,43,FALSE),0) -> 0 | BT3: =BJ3+BK3+BL3+BM3+BN3+BO3+BP3+BQ3+BR3+BS3 -> 1744.925 | BU3: 0 | BV3: 0 | BW3: 0 | BX3: =BU3+BV3+BW3 -> 0 | BY3: 0 | BZ3: =IFERROR(VLOOKUP(DF3,源_6社保表_Sheet1!$C:$BZ,18,FALSE),0) -> 1595.36 | CA3: =IFERROR(VLOOKUP(DF3,源_6社保表_Sheet1!$C:$BZ,19,FALSE),0) -> 897.39 | CB3: =IFERROR(VLOOKUP(DF3,源_6社保表_Sheet1!$C:$BZ,24,FALSE),0) -> 697.97 | CC3: =IFERROR(VLOOKUP(DF3,源_6社保表_Sheet1!$C:$BZ,20,FALSE),0) -> 49.855 | CD3: =IFERROR(VLOOKUP(DF3,源_6社保表_Sheet1!$C:$BZ,21,FALSE),0) -> 31.9072 | CE3: =IFERROR(VLOOKUP(DF3,源_6社保表_Sheet1!$C:$BZ,22,FALSE),0) -> 0 | CF3: =IFERROR(VLOOKUP(DF3,源_6社保表_Sheet1!$C:$BZ,23,FALSE),0) -> 0 | CG3: =IFERROR(VLOOKUP(DF3,源_6社保表_Sheet1!$C:$BZ,32,FALSE),0) -> 0 | CH3: =IFERROR(VLOOKUP(DF3,源_6社保表_Sheet1!$C:$BZ,33,FALSE),0) -> 0 | CI3: =IFERROR(VLOOKUP(DF3,源_6社保表_Sheet1!$C:$BZ,34,FALSE),0) -> 0 | CJ3: =IFERROR(VLOOKUP(DF3,源_6社保表_Sheet1!$C:$BZ,38,FALSE),0) -> 0 | CK3: =IFERROR(VLOOKUP(DF3,源_6社保表_Sheet1!$C:$BZ,35,FALSE),0) -> 0 | CL3: =IFERROR(VLOOKUP(DF3,源_6社保表_Sheet1!$C:$BZ,36,FALSE),0) -> 0 | CM3: =IFERROR(VLOOKUP(DF3,源_6社保表_Sheet1!$C:$BZ,37,FALSE),0) -> 0 | CN3: =BZ3+CA3+CB3+CC3+CD3+CE3+CF3+CG3+CH3+CI3+CJ3+CK3+CL3+CM3 -> 3272.4822 | CO3: =BI3+BG3+CN3+BE3+BH3 -> 22805.982 | CP3: =IF(IFERROR(VLOOKUP(K3,源_13残疾人信息_残疾人信息!$A:$M,1,FALSE),"")<>"",0,IF(OR(P3="门店全职",P3="门店管理组",P3="全职(非门店)"),(BI3-AT3)*IFERROR(VLOOKUP(D3,源_12计提残保金规则_Sheet1!$A:$E,4,FALSE),0)*IFERROR(VLOOKUP(D3,源_12计提残保金规则_Sheet1!$A:$E,5,FALSE),0),0)) -> 263.6145 | CQ3: =IF(M3="行政",0,16.05) -> 16.05 | CR3: =IF(M3="门卫",0,20.67) -> 20.67 | CS3: =IF(DATEVALUE(N3)>DATE(参数!$B$2,9,30),0,IF(M3="行政",0,IF(O3="",R3/12,IF(MONTH(DATEVALUE(O3))=参数!$B$3,0,IF(DATEVALUE(O3)<DATE(参数!$B$2,参数!$B$3,1),0,R3/12))))) -> 650.75 | CT3: =IF(P3="门店管理组",R3*0.12*0.85,0) -> 796.518 | CU3: =IFERROR(VLOOKUP(DF3,源_6社保表_Sheet1!$C:$I,2,FALSE),0) -> 9971 | CV3: =IFERROR(VLOOKUP(DF3,源_6社保表_Sheet1!$C:$I,7,FALSE),0) -> 9971 | CW3: =IFERROR(VLOOKUP(DF3,源_6社保表_Sheet1!$C:$I,3,FALSE),0) -> 9971 | CX3: =IFERROR(VLOOKUP(DF3,源_6社保表_Sheet1!$C:$I,4,FALSE),0) -> 9971 | CY3: =IFERROR(VLOOKUP(DF3,源_6社保表_Sheet1!$C:$I,5,FALSE),0) -> 9971 | CZ3: =IFERROR(VLOOKUP(DF3,源_6社保表_Sheet1!$C:$I,6,FALSE),0) -> 0 | DA3: =BI3+CN3-AG3-AH3-AI3-AJ3-AK3-AL3-AM3-AQ3-AR3-AS3-AT3 -> 11088.482 | DB3: =DA3+CP3+CQ3+CR3+CS3+CT3+BH3 -> 12842.585 | DC3: =IFERROR(VLOOKUP(K3,源_7银行卡表_Sheet1!$A:$J,8,FALSE),"") -> 招商银行 | DD3: =IFERROR(VLOOKUP(K3,源_7银行卡表_Sheet1!$A:$J,9,FALSE),"") -> 6686494367435887888 | DE3: =IFERROR(VLOOKUP(K3,源_7银行卡表_Sheet1!$A:$J,10,FALSE),"") -> 广西自贸试验区南宁片区五 | DF3: 130000195301178797 | DG3: 13789690671 | DH3: 上海 | DI3: 0 | DJ3: 0 | DK3: 0 | DL3: 0 | DM3: 0 | DN3: 0 | DO3: 0 | DP3: 0 | DQ3: 0 | DR3: =IF(OR(IFERROR(VLOOKUP(K3,源_3考勤报表_考勤表!$F:$BG,39,FALSE),0)+IFERROR(VLOOKUP(K3,源_8补工时表_补当月工时!$A:$AC,24,FALSE),0)=0,IFERROR(VLOOKUP(K3,源_3考勤报表_考勤表!$F:$BG,43,FALSE),0)+IFERROR(VLOOKUP(K3,源_8补工时表_补当月工时!$A:$AC,26,FALSE),0)=0),IF(BI3+BG3-BT3<0,BI3+BG3-BT3,0),0) -> 0
A4: =参数!$B$2 -> 2025 | B4: =参数!$B$3 -> 12 | D4: 上海达美乐 | E4: 店铺营运 | F4: =IFERROR(VLOOKUP(K4,源_7银行卡表_Sheet1!$A:$J,6,FALSE),"") -> 华东营运 | G4: 上海2 | H4: 桂林路店 | I4: 外服-上海门店全职 | J4: 1 | K4: 26123003 | L4: 董晚樱 | M4: 餐厅副理 | N4: 2015-07-09 | P4: 门店管理组 | Q4: =IF(P4="门店全职",IFERROR(VLOOKUP(K4,源_3考勤报表_考勤表!$F:$BG,34,FALSE),0)+IFERROR(VLOOKUP(K4,源_8补工时表_补当月工时!$A:$AC,14,FALSE),0),IF(P4="门店管理组",IF(IFERROR(VLOOKUP(K4,源_3考勤报表_考勤表!$F:$BG,34,FALSE),0)+IFERROR(VLOOKUP(K4,源_8补工时表_补当月工时!$A:$AC,14,FALSE),0)+IFERROR(VLOOKUP(K4,源_3考勤报表_考勤表!$F:$BG,37,FALSE),0)+IFERROR(VLOOKUP(K4,源_8补工时表_补当月工时!$A:$AC,15,FALSE),0)+IFERROR(VLOOKUP(K4,源_3考勤报表_考勤表!$F:$BG,38,FALSE),0)+IFERROR(VLOOKUP(K4,源_8补工时表_补当月工时!$A:$AC,17,FALSE),0)+IFERROR(VLOOKUP(K4,源_3考勤报表_考勤表!$F:$BG,40,FALSE),0)+IFERROR(VLOOKUP(K4,源_8补工时表_补当月工时!$A:$AC,20,FALSE),0)+IFERROR(VLOOKUP(K4,源_8补工时表_补当月工时!$A:$AC,22,FALSE),0)+IFERROR(VLOOKUP(K4,源_3考勤报表_考勤表!$F:$BG,41,FALSE),0)+IFERROR(VLOOKUP(K4,源_8补工时表_补当月工时!$A:$AC,18,FALSE),0)+IFERROR(VLOOKUP(K4,源_3考勤报表_考勤表!$F:$BG,44,FALSE),0)+IFERROR(VLOOKUP(K4,源_8补工时表_补当月工时!$A:$AC,16,FALSE),0)+IFERROR(VLOOKUP(K4,源_3考勤报表_考勤表!$F:$BG,45,FALSE),0)>=参数!$B$4,参数!$B$4-IFERROR(VLOOKUP(K4,源_3考勤报表_考勤表!$F:$BG,37,FALSE),0)-IFERROR(VLOOKUP(K4,源_8补工时表_补当月工时!$A:$AC,15,FALSE),0)-IFERROR(VLOOKUP(K4,源_3考勤报表_考勤表!$F:$BG,38,FALSE),0)-IFERROR(VLOOKUP(K4,源_8补工时表_补当月工时!$A:$AC,17,FALSE),0)-IFERROR(VLOOKUP(K4,源_3考勤报表_考勤表!$F:$BG,40,FALSE),0)-IFERROR(VLOOKUP(K4,源_8补工时表_补当月工时!$A:$AC,20,FALSE),0)-IFERROR(VLOOKUP(K4,源_8补工时表_补当月工时!$A:$AC,22,FALSE),0)-IFERROR(VLOOKUP(K4,源_3考勤报表_考勤表!$F:$BG,41,FALSE),0)-IFERROR(VLOOKUP(K4,源_8补工时表_补当月工时!$A:$AC,18,FALSE),0)-IFERROR(VLOOKUP(K4,源_3考勤报表_考勤表!$F:$BG,44,FALSE),0)-IFERROR(VLOOKUP(K4,源_8补工时表_补当月工时!$A:$AC,16,FALSE),0)-IFERROR(VLOOKUP(K4,源_3考勤报表_考勤表!$F:$BG,45,FALSE),0),IFERROR(VLOOKUP(K4,源_3考勤报表_考勤表!$F:$BG,34,FALSE),0)+IFERROR(VLOOKUP(K4,源_8补工时表_补当月工时!$A:$AC,14,FALSE),0)),0)) -> 110 | R4: 5693 | S4: 0 | T4: =IF(P4="门店全职",R4/参数!$B$4*(Q4-MAX(IFERROR(VLOOKUP(K4,源_3考勤报表_考勤表!$F:$BG,34,FALSE),0)+IFERROR(VLOOKUP(K4,源_8补工时表_补当月工时!$A:$AC,14,FALSE),0)+IFERROR(VLOOKUP(K4,源_3考勤报表_考勤表!$F:$BG,37,FALSE),0)+IFERROR(VLOOKUP(K4,源_8补工时表_补当月工时!$A:$AC,15,FALSE),0)+IFERROR(VLOOKUP(K4,源_3考勤报表_考勤表!$F:$BG,38,FALSE),0)+IFERROR(VLOOKUP(K4,源_8补工时表_补当月工时!$A:$AC,17,FALSE),0)+IFERROR(VLOOKUP(K4,源_3考勤报表_考勤表!$F:$BG,40,FALSE),0)+IFERROR(VLOOKUP(K4,源_8补工时表_补当月工时!$A:$AC,20,FALSE),0)+IFERROR(VLOOKUP(K4,源_8补工时表_补当月工时!$A:$AC,22,FALSE),0)+IFERROR(VLOOKUP(K4,源_3考勤报表_考勤表!$F:$BG,41,FALSE),0)+IFERROR(VLOOKUP(K4,源_8补工时表_补当月工时!$A:$AC,18,FALSE),0)+IFERROR(VLOOKUP(K4,源_3考勤报表_考勤表!$F:$BG,42,FALSE),0)+IFERROR(VLOOKUP(K4,源_8补工时表_补当月工时!$A:$AC,19,FALSE),0)+IFERROR(VLOOKUP(K4,源_3考勤报表_考勤表!$F:$BG,44,FALSE),0)+IFERROR(VLOOKUP(K4,源_8补工时表_补当月工时!$A:$AC,16,FALSE),0)+IFERROR(VLOOKUP(K4,源_3考勤报表_考勤表!$F:$BG,45,FALSE),0)-参数!$B$4,0)),R4/参数!$B$4*Q4) -> 3403.4239 | U4: 0 | V4: 0 | W4: =X4+Y4+Z4+AA4 -> 11.5 | X4: =IFERROR(VLOOKUP(K4,源_4奖金汇总表_拆分手工算!$A:$N,8,FALSE),0) -> 11.5 | Y4: =IFERROR(VLOOKUP(K4,源_5薪资备忘录_工资调整项!$A:$AC,14,FALSE),0) -> 0 | Z4: =IFERROR(VLOOKUP(K4,源_5薪资备忘录_工资调整项!$A:$AC,16,FALSE),0) -> 0 | AA4: =IFERROR(VLOOKUP(K4,源_5薪资备忘录_工资调整项!$A:$AC,15,FALSE),0) -> 0 | AB4: =AC4+AD4+AF4 -> 294.46552 | AC4: =IF(P4="门店全职",R4/174*MAX(IFERROR(VLOOKUP(K4,源_3考勤报表_考勤表!$F:$BG,34,FALSE),0)+IFERROR(VLOOKUP(K4,源_8补工时表_补当月工时!$A:$AC,14,FALSE),0)+IFERROR(VLOOKUP(K4,源_3考勤报表_考勤表!$F:$BG,37,FALSE),0)+IFERROR(VLOOKUP(K4,源_8补工时表_补当月工时!$A:$AC,15,FALSE),0)+IFERROR(VLOOKUP(K4,源_3考勤报表_考勤表!$F:$BG,38,FALSE),0)+IFERROR(VLOOKUP(K4,源_8补工时表_补当月工时!$A:$AC,17,FALSE),0)+IFERROR(VLOOKUP(K4,源_3考勤报表_考勤表!$F:$BG,40,FALSE),0)+IFERROR(VLOOKUP(K4,源_8补工时表_补当月工时!$A:$AC,20,FALSE),0)+IFERROR(VLOOKUP(K4,源_8补工时表_补当月工时!$A:$AC,22,FALSE),0)+IFERROR(VLOOKUP(K4,源_3考勤报表_考勤表!$F:$BG,41,FALSE),0)+IFERROR(VLOOKUP(K4,源_8补工时表_补当月工时!$A:$AC,18,FALSE),0)+IFERROR(VLOOKUP(K4,源_3考勤报表_考勤表!$F:$BG,42,FALSE),0)+IFERROR(VLOOKUP(K4,源_8补工时表_补当月工时!$A:$AC,19,FALSE),0)+IFERROR(VLOOKUP(K4,源_3考勤报表_考勤表!$F:$BG,44,FALSE),0)+IFERROR(VLOOKUP(K4,源_8补工时表_补当月工时!$A:$AC,16,FALSE),0)+IFERROR(VLOOKUP(K4,源_3考勤报表_考勤表!$F:$BG,45,FALSE),0)-参数!$B$4,0)*1.5,0) -> 0 | AD4: 0 | AE4: =IFERROR(VLOOKUP(K4,源_3考勤报表_考勤表!$F:$BG,46,FALSE),0)+IFERROR(VLOOKUP(K4,源_8补工时表_补当月工时!$A:$AC,25,FALSE),0) -> 3 | AF4: =R4/174*AE4*3 -> 294.46552 | AG4: =IFERROR(VLOOKUP(K4,源_4奖金汇总表_拆分手工算!$A:$N,10,FALSE),0) -> 0 | AH4: =IFERROR(VLOOKUP(K4,源_4奖金汇总表_拆分手工算!$A:$N,5,FALSE),0) -> 0 | AI4: =IFERROR(VLOOKUP(K4,源_4奖金汇总表_拆分手工算!$A:$N,11,FALSE),0) -> 0 | AJ4: =IFERROR(VLOOKUP(K4,源_4奖金汇总表_拆分手工算!$A:$N,4,FALSE),0) -> 0 | AK4: =IFERROR(VLOOKUP(K4,源_4奖金汇总表_拆分手工算!$A:$N,3,FALSE),0) -> 0 | AL4: =IFERROR(VLOOKUP(K4,源_4奖金汇总表_拆分手工算!$A:$N,6,FALSE),0) -> 212.5 | AM4: =IFERROR(VLOOKUP(K4,源_5薪资备忘录_工资调整项!$A:$AC,18,FALSE),0)+IFERROR(VLOOKUP(K4,源_4奖金汇总表_拆分手工算!$A:$N,7,FALSE),0) -> 200 | AN4: =IFERROR(VLOOKUP(K4,源_5薪资备忘录_工资调整项!$A:$AC,17,FALSE),0) -> 0 | AO4: =IF(OR(IFERROR(VLOOKUP(K4,源_3考勤报表_考勤表!$F:$BG,39,FALSE),0)+IFERROR(VLOOKUP(K4,源_8补工时表_补当月工时!$A:$AC,24,FALSE),0)>0,IFERROR(VLOOKUP(K4,源_3考勤报表_考勤表!$F:$BG,43,FALSE),0)+IFERROR(VLOOKUP(K4,源_8补工时表_补当月工时!$A:$AC,26,FALSE),0)>0),IF(IFERROR(VLOOKUP(DH4,源_11产假政策_Sheet1!$C:$F,4,FALSE),"")="是",R4/参数!$B$4*(IFERROR(VLOOKUP(K4,源_3考勤报表_考勤表!$F:$BG,39,FALSE),0)+IFERROR(VLOOKUP(K4,源_8补工时表_补当月工时!$A:$AC,24,FALSE),0)+IFERROR(VLOOKUP(K4,源_3考勤报表_考勤表!$F:$BG,43,FALSE),0)+IFERROR(VLOOKUP(K4,源_8补工时表_补当月工时!$A:$AC,26,FALSE),0)),IFERROR(VLOOKUP(K4,源_5薪资备忘录_工资调整项!$A:$AC,19,FALSE),0)),0) -> 0 | AP4: 0 | AQ4: =IFERROR(VLOOKUP(K4,源_4奖金汇总表_拆分手工算!$A:$N,12,FALSE),0)+IFERROR(VLOOKUP(K4,源_9年终奖表_Sheet1!$A:$E,3,FALSE),0) -> 1200 | AR4: =IFERROR(VLOOKUP(K4,源_4奖金汇总表_拆分手工算!$A:$N,13,FALSE),0)+IFERROR(VLOOKUP(K4,源_9年终奖表_Sheet1!$A:$E,4,FALSE),0) -> 600 | AS4: =IFERROR(VLOOKUP(K4,源_4奖金汇总表_拆分手工算!$A:$N,14,FALSE),0)+IFERROR(VLOOKUP(K4,源_9年终奖表_Sheet1!$A:$E,5,FALSE),0) -> 222 | AT4: =IFERROR(VLOOKUP(K4,源_5薪资备忘录_工资调整项!$A:$AC,20,FALSE),0) -> 0 | AU4: =IFERROR(VLOOKUP(K4,源_5薪资备忘录_工资调整项!$A:$AC,21,FALSE),0)+IFERROR(VLOOKUP(K4,源_4奖金汇总表_拆分手工算!$A:$N,9,FALSE),0) -> 0 | AV4: =R4/参数!$B$4*(IFERROR(VLOOKUP(K4,源_3考勤报表_考勤表!$F:$BG,37,FALSE),0)+IFERROR(VLOOKUP(K4,源_8补工时表_补当月工时!$A:$AC,15,FALSE),0)) -> 0 | AW4: =R4/174*MIN(IFERROR(VLOOKUP(K4,源_3考勤报表_考勤表!$F:$BG,35,FALSE),0),174)*IF(DATEDIF(N4,DATE(参数!$B$2,参数!$B$3+1,0),"Y")<2,0.6,IF(DATEDIF(N4,DATE(参数!$B$2,参数!$B$3+1,0),"Y")<4,0.7,IF(DATEDIF(N4,DATE(参数!$B$2,参数!$B$3+1,0),"Y")<6,0.8,IF(DATEDIF(N4,DATE(参数!$B$2,参数!$B$3+1,0),"Y")<8,0.9,1)))) -> 261.74713 | AX4: =IF(Q4+IFERROR(VLOOKUP(K4,源_3考勤报表_考勤表!$F:$BG,37,FALSE),0)+IFERROR(VLOOKUP(K4,源_8补工时表_补当月工时!$A:$AC,15,FALSE),0)>=参数!$B$4,0,IF(Q4+IFERROR(VLOOKUP(K4,源_3考勤报表_考勤表!$F:$BG,37,FALSE),0)+IFERROR(VLOOKUP(K4,源_8补工时表_补当月工时!$A:$AC,15,FALSE),0)+IFERROR(VLOOKUP(K4,源_3考勤报表_考勤表!$F:$BG,38,FALSE),0)+IFERROR(VLOOKUP(K4,源_8补工时表_补当月工时!$A:$AC,17,FALSE),0)+IFERROR(VLOOKUP(K4,源_3考勤报表_考勤表!$F:$BG,40,FALSE),0)+IFERROR(VLOOKUP(K4,源_8补工时表_补当月工时!$A:$AC,20,FALSE),0)+IFERROR(VLOOKUP(K4,源_8补工时表_补当月工时!$A:$AC,22,FALSE),0)+IFERROR(VLOOKUP(K4,源_3考勤报表_考勤表!$F:$BG,41,FALSE),0)+IFERROR(VLOOKUP(K4,源_8补工时表_补当月工时!$A:$AC,18,FALSE),0)+IFERROR(VLOOKUP(K4,源_3考勤报表_考勤表!$F:$BG,42,FALSE),0)+IFERROR(VLOOKUP(K4,源_8补工时表_补当月工时!$A:$AC,19,FALSE),0)+IFERROR(VLOOKUP(K4,源_3考勤报表_考勤表!$F:$BG,44,FALSE),0)+IFERROR(VLOOKUP(K4,源_8补工时表_补当月工时!$A:$AC,16,FALSE),0)+IFERROR(VLOOKUP(K4,源_3考勤报表_考勤表!$F:$BG,45,FALSE),0)<=参数!$B$4,R4/参数!$B$4*(IFERROR(VLOOKUP(K4,源_3考勤报表_考勤表!$F:$BG,38,FALSE),0)+IFERROR(VLOOKUP(K4,源_8补工时表_补当月工时!$A:$AC,17,FALSE),0)+IFERROR(VLOOKUP(K4,源_3考勤报表_考勤表!$F:$BG,40,FALSE),0)+IFERROR(VLOOKUP(K4,源_8补工时表_补当月工时!$A:$AC,20,FALSE),0)+IFERROR(VLOOKUP(K4,源_8补工时表_补当月工时!$A:$AC,22,FALSE),0)+IFERROR(VLOOKUP(K4,源_3考勤报表_考勤表!$F:$BG,41,FALSE),0)+IFERROR(VLOOKUP(K4,源_8补工时表_补当月工时!$A:$AC,18,FALSE),0)+IFERROR(VLOOKUP(K4,源_3考勤报表_考勤表!$F:$BG,42,FALSE),0)+IFERROR(VLOOKUP(K4,源_8补工时表_补当月工时!$A:$AC,19,FALSE),0)+IFERROR(VLOOKUP(K4,源_3考勤报表_考勤表!$F:$BG,44,FALSE),0)+IFERROR(VLOOKUP(K4,源_8补工时表_补当月工时!$A:$AC,16,FALSE),0)+IFERROR(VLOOKUP(K4,源_3考勤报表_考勤表!$F:$BG,45,FALSE),0)),0)) -> 0 | AY4: 0 | AZ4: 0 | BA4: 0 | BB4: 0 | BC4: =IFERROR(VLOOKUP(K4,源_5薪资备忘录_工资调整项!$A:$AC,25,FALSE),0) -> 0 | BD4: 0 | BE4: 0 | BF4: 0 | BG4: =IFERROR(VLOOKUP(K4,源_5薪资备忘录_工资调整项!$A:$AC,22,FALSE),0)+IFERROR(VLOOKUP(K4,源_5薪资备忘录_工资调整项!$A:$AC,23,FALSE),0)+IFERROR(VLOOKUP(K4,源_5薪资备忘录_工资调整项!$A:$AC,24,FALSE),0) -> 0 | BH4: =IFERROR(VLOOKUP(DF4,源_6社保表_Sheet1!$C:$CD,80,FALSE),0)+4.5 -> 6.5 | BI4: =T4+W4+AB4+AG4+AH4+AI4+AJ4+AK4+AL4+AM4+AN4+AO4+AP4+AQ4+AR4+AS4+AT4+AU4+AV4+AW4+AX4+BC4 -> 6405.6366 | BJ4: =IFERROR(VLOOKUP(DF4,源_6社保表_Sheet1!$C:$BZ,26,FALSE),0) -> 522.2 | BK4: =IFERROR(VLOOKUP(DF4,源_6社保表_Sheet1!$C:$BZ,27,FALSE),0) -> 74.6 | BL4: =IFERROR(VLOOKUP(DF4,源_6社保表_Sheet1!$C:$BZ,28,FALSE),0) -> 37.3 | BM4: =IFERROR(VLOOKUP(DF4,源_6社保表_Sheet1!$C:$BZ,30,FALSE),0) -> 437.04 | BN4: =IFERROR(VLOOKUP(DF4,源_6社保表_Sheet1!$C:$BZ,29,FALSE),0) -> 0 | BO4: =IFERROR(VLOOKUP(DF4,源_6社保表_Sheet1!$C:$BZ,40,FALSE),0) -> 0 | BP4: =IFERROR(VLOOKUP(DF4,源_6社保表_Sheet1!$C:$BZ,41,FALSE),0) -> 0 | BQ4: =IFERROR(VLOOKUP(DF4,源_6社保表_Sheet1!$C:$BZ,42,FALSE),0) -> 0 | BR4: =IFERROR(VLOOKUP(DF4,源_6社保表_Sheet1!$C:$BZ,44,FALSE),0) -> 0 | BS4: =IFERROR(VLOOKUP(DF4,源_6社保表_Sheet1!$C:$BZ,43,FALSE),0) -> 0 | BT4: =BJ4+BK4+BL4+BM4+BN4+BO4+BP4+BQ4+BR4+BS4 -> 1071.14 | BU4: 0 | BV4: 0 | BW4: 0 | BX4: =BU4+BV4+BW4 -> 0 | BY4: 0 | BZ4: =IFERROR(VLOOKUP(DF4,源_6社保表_Sheet1!$C:$BZ,18,FALSE),0) -> 1119 | CA4: =IFERROR(VLOOKUP(DF4,源_6社保表_Sheet1!$C:$BZ,19,FALSE),0) -> 596.8 | CB4: =IFERROR(VLOOKUP(DF4,源_6社保表_Sheet1!$C:$BZ,24,FALSE),0) -> 437.04 | CC4: =IFERROR(VLOOKUP(DF4,源_6社保表_Sheet1!$C:$BZ,20,FALSE),0) -> 37.3 | CD4: =IFERROR(VLOOKUP(DF4,源_6社保表_Sheet1!$C:$BZ,21,FALSE),0) -> 23.872 | CE4: =IFERROR(VLOOKUP(DF4,源_6社保表_Sheet1!$C:$BZ,22,FALSE),0) -> 0 | CF4: =IFERROR(VLOOKUP(DF4,源_6社保表_Sheet1!$C:$BZ,23,FALSE),0) -> 0 | CG4: =IFERROR(VLOOKUP(DF4,源_6社保表_Sheet1!$C:$BZ,32,FALSE),0) -> 0 | CH4: =IFERROR(VLOOKUP(DF4,源_6社保表_Sheet1!$C:$BZ,33,FALSE),0) -> 0 | CI4: =IFERROR(VLOOKUP(DF4,源_6社保表_Sheet1!$C:$BZ,34,FALSE),0) -> 0 | CJ4: =IFERROR(VLOOKUP(DF4,源_6社保表_Sheet1!$C:$BZ,38,FALSE),0) -> 0 | CK4: =IFERROR(VLOOKUP(DF4,源_6社保表_Sheet1!$C:$BZ,35,FALSE),0) -> 0 | CL4: =IFERROR(VLOOKUP(DF4,源_6社保表_Sheet1!$C:$BZ,36,FALSE),0) -> 0 | CM4: =IFERROR(VLOOKUP(DF4,源_6社保表_Sheet1!$C:$BZ,37,FALSE),0) -> 0 | CN4: =BZ4+CA4+CB4+CC4+CD4+CE4+CF4+CG4+CH4+CI4+CJ4+CK4+CL4+CM4 -> 2214.012 | CO4: =BI4+BG4+CN4+BE4+BH4 -> 8626.1486 | CP4: =IF(IFERROR(VLOOKUP(K4,源_13残疾人信息_残疾人信息!$A:$M,1,FALSE),"")<>"",0,IF(OR(P4="门店全职",P4="门店管理组",P4="全职(非门店)"),(BI4-AT4)*IFERROR(VLOOKUP(D4,源_12计提残保金规则_Sheet1!$A:$E,4,FALSE),0)*IFERROR(VLOOKUP(D4,源_12计提残保金规则_Sheet1!$A:$E,5,FALSE),0),0)) -> 86.476094 | CQ4: =IF(M4="行政",0,16.05) -> 16.05 | CR4: =IF(M4="门卫",0,20.67) -> 20.67 | CS4: =IF(DATEVALUE(N4)>DATE(参数!$B$2,9,30),0,IF(M4="行政",0,IF(O4="",R4/12,IF(MONTH(DATEVALUE(O4))=参数!$B$3,0,IF(DATEVALUE(O4)<DATE(参数!$B$2,参数!$B$3,1),0,R4/12))))) -> 474.41667 | CT4: =IF(P4="门店管理组",R4*0.12*0.85,0) -> 580.686 | CU4: =IFERROR(VLOOKUP(DF4,源_6社保表_Sheet1!$C:$I,2,FALSE),0) -> 7460 | CV4: =IFERROR(VLOOKUP(DF4,源_6社保表_Sheet1!$C:$I,7,FALSE),0) -> 7284 | CW4: =IFERROR(VLOOKUP(DF4,源_6社保表_Sheet1!$C:$I,3,FALSE),0) -> 7460 | CX4: =IFERROR(VLOOKUP(DF4,源_6社保表_Sheet1!$C:$I,4,FALSE),0) -> 7460 | CY4: =IFERROR(VLOOKUP(DF4,源_6社保表_Sheet1!$C:$I,5,FALSE),0) -> 7460 | CZ4: =IFERROR(VLOOKUP(DF4,源_6社保表_Sheet1!$C:$I,6,FALSE),0) -> 0 | DA4: =BI4+CN4-AG4-AH4-AI4-AJ4-AK4-AL4-AM4-AQ4-AR4-AS4-AT4 -> 6185.1486 | DB4: =DA4+CP4+CQ4+CR4+CS4+CT4+BH4 -> 7369.9473 | DC4: =IFERROR(VLOOKUP(K4,源_7银行卡表_Sheet1!$A:$J,8,FALSE),"") -> 招商银行 | DD4: =IFERROR(VLOOKUP(K4,源_7银行卡表_Sheet1!$A:$J,9,FALSE),"") -> 6687807193600801610 | DE4: =IFERROR(VLOOKUP(K4,源_7银行卡表_Sheet1!$A:$J,10,FALSE),"") -> 成都蜀都中心支行 | DF4: 110000198902241890 | DG4: 17603289482 | DH4: 上海 | DI4: 0 | DJ4: 0 | DK4: 0 | DL4: 0 | DM4: 0 | DN4: 0 | DO4: 0 | DP4: 0 | DQ4: 0 | DR4: =IF(OR(IFERROR(VLOOKUP(K4,源_3考勤报表_考勤表!$F:$BG,39,FALSE),0)+IFERROR(VLOOKUP(K4,源_8补工时表_补当月工时!$A:$AC,24,FALSE),0)=0,IFERROR(VLOOKUP(K4,源_3考勤报表_考勤表!$F:$BG,43,FALSE),0)+IFERROR(VLOOKUP(K4,源_8补工时表_补当月工时!$A:$AC,26,FALSE),0)=0),IF(BI4+BG4-BT4<0,BI4+BG4-BT4,0),0) -> 0
A5: =参数!$B$2 -> 2025 | B5: =参数!$B$3 -> 12 | D5: 上海达美乐 | E5: 店铺营运 | F5: =IFERROR(VLOOKUP(K5,源_7银行卡表_Sheet1!$A:$J,6,FALSE),"") -> 华东营运 | G5: 上海2 | H5: 崧泽大道店 | I5: 外服-上海门店全职 | J5: 1 | K5: 26123004 | L5: 元曼柔 | M5: 餐厅经理 | N5: 2017-07-01 | P5: 门店管理组 | Q5: =IF(P5="门店全职",IFERROR(VLOOKUP(K5,源_3考勤报表_考勤表!$F:$BG,34,FALSE),0)+IFERROR(VLOOKUP(K5,源_8补工时表_补当月工时!$A:$AC,14,FALSE),0),IF(P5="门店管理组",IF(IFERROR(VLOOKUP(K5,源_3考勤报表_考勤表!$F:$BG,34,FALSE),0)+IFERROR(VLOOKUP(K5,源_8补工时表_补当月工时!$A:$AC,14,FALSE),0)+IFERROR(VLOOKUP(K5,源_3考勤报表_考勤表!$F:$BG,37,FALSE),0)+IFERROR(VLOOKUP(K5,源_8补工时表_补当月工时!$A:$AC,15,FALSE),0)+IFERROR(VLOOKUP(K5,源_3考勤报表_考勤表!$F:$BG,38,FALSE),0)+IFERROR(VLOOKUP(K5,源_8补工时表_补当月工时!$A:$AC,17,FALSE),0)+IFERROR(VLOOKUP(K5,源_3考勤报表_考勤表!$F:$BG,40,FALSE),0)+IFERROR(VLOOKUP(K5,源_8补工时表_补当月工时!$A:$AC,20,FALSE),0)+IFERROR(VLOOKUP(K5,源_8补工时表_补当月工时!$A:$AC,22,FALSE),0)+IFERROR(VLOOKUP(K5,源_3考勤报表_考勤表!$F:$BG,41,FALSE),0)+IFERROR(VLOOKUP(K5,源_8补工时表_补当月工时!$A:$AC,18,FALSE),0)+IFERROR(VLOOKUP(K5,源_3考勤报表_考勤表!$F:$BG,44,FALSE),0)+IFERROR(VLOOKUP(K5,源_8补工时表_补当月工时!$A:$AC,16,FALSE),0)+IFERROR(VLOOKUP(K5,源_3考勤报表_考勤表!$F:$BG,45,FALSE),0)>=参数!$B$4,参数!$B$4-IFERROR(VLOOKUP(K5,源_3考勤报表_考勤表!$F:$BG,37,FALSE),0)-IFERROR(VLOOKUP(K5,源_8补工时表_补当月工时!$A:$AC,15,FALSE),0)-IFERROR(VLOOKUP(K5,源_3考勤报表_考勤表!$F:$BG,38,FALSE),0)-IFERROR(VLOOKUP(K5,源_8补工时表_补当月工时!$A:$AC,17,FALSE),0)-IFERROR(VLOOKUP(K5,源_3考勤报表_考勤表!$F:$BG,40,FALSE),0)-IFERROR(VLOOKUP(K5,源_8补工时表_补当月工时!$A:$AC,20,FALSE),0)-IFERROR(VLOOKUP(K5,源_8补工时表_补当月工时!$A:$AC,22,FALSE),0)-IFERROR(VLOOKUP(K5,源_3考勤报表_考勤表!$F:$BG,41,FALSE),0)-IFERROR(VLOOKUP(K5,源_8补工时表_补当月工时!$A:$AC,18,FALSE),0)-IFERROR(VLOOKUP(K5,源_3考勤报表_考勤表!$F:$BG,44,FALSE),0)-IFERROR(VLOOKUP(K5,源_8补工时表_补当月工时!$A:$AC,16,FALSE),0)-IFERROR(VLOOKUP(K5,源_3考勤报表_考勤表!$F:$BG,45,FALSE),0),IFERROR(VLOOKUP(K5,源_3考勤报表_考勤表!$F:$BG,34,FALSE),0)+IFERROR(VLOOKUP(K5,源_8补工时表_补当月工时!$A:$AC,14,FALSE),0)),0)) -> 184 | R5: 7980 | S5: 0 | T5: =IF(P5="门店全职",R5/参数!$B$4*(Q5-MAX(IFERROR(VLOOKUP(K5,源_3考勤报表_考勤表!$F:$BG,34,FALSE),0)+IFERROR(VLOOKUP(K5,源_8补工时表_补当月工时!$A:$AC,14,FALSE),0)+IFERROR(VLOOKUP(K5,源_3考勤报表_考勤表!$F:$BG,37,FALSE),0)+IFERROR(VLOOKUP(K5,源_8补工时表_补当月工时!$A:$AC,15,FALSE),0)+IFERROR(VLOOKUP(K5,源_3考勤报表_考勤表!$F:$BG,38,FALSE),0)+IFERROR(VLOOKUP(K5,源_8补工时表_补当月工时!$A:$AC,17,FALSE),0)+IFERROR(VLOOKUP(K5,源_3考勤报表_考勤表!$F:$BG,40,FALSE),0)+IFERROR(VLOOKUP(K5,源_8补工时表_补当月工时!$A:$AC,20,FALSE),0)+IFERROR(VLOOKUP(K5,源_8补工时表_补当月工时!$A:$AC,22,FALSE),0)+IFERROR(VLOOKUP(K5,源_3考勤报表_考勤表!$F:$BG,41,FALSE),0)+IFERROR(VLOOKUP(K5,源_8补工时表_补当月工时!$A:$AC,18,FALSE),0)+IFERROR(VLOOKUP(K5,源_3考勤报表_考勤表!$F:$BG,42,FALSE),0)+IFERROR(VLOOKUP(K5,源_8补工时表_补当月工时!$A:$AC,19,FALSE),0)+IFERROR(VLOOKUP(K5,源_3考勤报表_考勤表!$F:$BG,44,FALSE),0)+IFERROR(VLOOKUP(K5,源_8补工时表_补当月工时!$A:$AC,16,FALSE),0)+IFERROR(VLOOKUP(K5,源_3考勤报表_考勤表!$F:$BG,45,FALSE),0)-参数!$B$4,0)),R5/参数!$B$4*Q5) -> 7980 | U5: 0 | V5: 0 | W5: =X5+Y5+Z5+AA5 -> 53 | X5: =IFERROR(VLOOKUP(K5,源_4奖金汇总表_拆分手工算!$A:$N,8,FALSE),0) -> 53 | Y5: =IFERROR(VLOOKUP(K5,源_5薪资备忘录_工资调整项!$A:$AC,14,FALSE),0) -> 0 | Z5: =IFERROR(VLOOKUP(K5,源_5薪资备忘录_工资调整项!$A:$AC,16,FALSE),0) -> 0 | AA5: =IFERROR(VLOOKUP(K5,源_5薪资备忘录_工资调整项!$A:$AC,15,FALSE),0) -> 0 | AB5: =AC5+AD5+AF5 -> 0 | AC5: =IF(P5="门店全职",R5/174*MAX(IFERROR(VLOOKUP(K5,源_3考勤报表_考勤表!$F:$BG,34,FALSE),0)+IFERROR(VLOOKUP(K5,源_8补工时表_补当月工时!$A:$AC,14,FALSE),0)+IFERROR(VLOOKUP(K5,源_3考勤报表_考勤表!$F:$BG,37,FALSE),0)+IFERROR(VLOOKUP(K5,源_8补工时表_补当月工时!$A:$AC,15,FALSE),0)+IFERROR(VLOOKUP(K5,源_3考勤报表_考勤表!$F:$BG,38,FALSE),0)+IFERROR(VLOOKUP(K5,源_8补工时表_补当月工时!$A:$AC,17,FALSE),0)+IFERROR(VLOOKUP(K5,源_3考勤报表_考勤表!$F:$BG,40,FALSE),0)+IFERROR(VLOOKUP(K5,源_8补工时表_补当月工时!$A:$AC,20,FALSE),0)+IFERROR(VLOOKUP(K5,源_8补工时表_补当月工时!$A:$AC,22,FALSE),0)+IFERROR(VLOOKUP(K5,源_3考勤报表_考勤表!$F:$BG,41,FALSE),0)+IFERROR(VLOOKUP(K5,源_8补工时表_补当月工时!$A:$AC,18,FALSE),0)+IFERROR(VLOOKUP(K5,源_3考勤报表_考勤表!$F:$BG,42,FALSE),0)+IFERROR(VLOOKUP(K5,源_8补工时表_补当月工时!$A:$AC,19,FALSE),0)+IFERROR(VLOOKUP(K5,源_3考勤报表_考勤表!$F:$BG,44,FALSE),0)+IFERROR(VLOOKUP(K5,源_8补工时表_补当月工时!$A:$AC,16,FALSE),0)+IFERROR(VLOOKUP(K5,源_3考勤报表_考勤表!$F:$BG,45,FALSE),0)-参数!$B$4,0)*1.5,0) -> 0 | AD5: 0 | AE5: =IFERROR(VLOOKUP(K5,源_3考勤报表_考勤表!$F:$BG,46,FALSE),0)+IFERROR(VLOOKUP(K5,源_8补工时表_补当月工时!$A:$AC,25,FALSE),0) -> 0 | AF5: =R5/174*AE5*3 -> 0 | AG5: =IFERROR(VLOOKUP(K5,源_4奖金汇总表_拆分手工算!$A:$N,10,FALSE),0) -> 0 | AH5: =IFERROR(VLOOKUP(K5,源_4奖金汇总表_拆分手工算!$A:$N,5,FALSE),0) -> 250 | AI5: =IFERROR(VLOOKUP(K5,源_4奖金汇总表_拆分手工算!$A:$N,11,FALSE),0) -> 0 | AJ5: =IFERROR(VLOOKUP(K5,源_4奖金汇总表_拆分手工算!$A:$N,4,FALSE),0) -> 0 | AK5: =IFERROR(VLOOKUP(K5,源_4奖金汇总表_拆分手工算!$A:$N,3,FALSE),0) -> 0 | AL5: =IFERROR(VLOOKUP(K5,源_4奖金汇总表_拆分手工算!$A:$N,6,FALSE),0) -> 0 | AM5: =IFERROR(VLOOKUP(K5,源_5薪资备忘录_工资调整项!$A:$AC,18,FALSE),0)+IFERROR(VLOOKUP(K5,源_4奖金汇总表_拆分手工算!$A:$N,7,FALSE),0) -> 0 | AN5: =IFERROR(VLOOKUP(K5,源_5薪资备忘录_工资调整项!$A:$AC,17,FALSE),0) -> 0 | AO5: =IF(OR(IFERROR(VLOOKUP(K5,源_3考勤报表_考勤表!$F:$BG,39,FALSE),0)+IFERROR(VLOOKUP(K5,源_8补工时表_补当月工时!$A:$AC,24,FALSE),0)>0,IFERROR(VLOOKUP(K5,源_3考勤报表_考勤表!$F:$BG,43,FALSE),0)+IFERROR(VLOOKUP(K5,源_8补工时表_补当月工时!$A:$AC,26,FALSE),0)>0),IF(IFERROR(VLOOKUP(DH5,源_11产假政策_Sheet1!$C:$F,4,FALSE),"")="是",R5/参数!$B$4*(IFERROR(VLOOKUP(K5,源_3考勤报表_考勤表!$F:$BG,39,FALSE),0)+IFERROR(VLOOKUP(K5,源_8补工时表_补当月工时!$A:$AC,24,FALSE),0)+IFERROR(VLOOKUP(K5,源_3考勤报表_考勤表!$F:$BG,43,FALSE),0)+IFERROR(VLOOKUP(K5,源_8补工时表_补当月工时!$A:$AC,26,FALSE),0)),IFERROR(VLOOKUP(K5,源_5薪资备忘录_工资调整项!$A:$AC,19,FALSE),0)),0) -> 0 | AP5: 0 | AQ5: =IFERROR(VLOOKUP(K5,源_4奖金汇总表_拆分手工算!$A:$N,12,FALSE),0)+IFERROR(VLOOKUP(K5,源_9年终奖表_Sheet1!$A:$E,3,FALSE),0) -> 1200 | AR5: =IFERROR(VLOOKUP(K5,源_4奖金汇总表_拆分手工算!$A:$N,13,FALSE),0)+IFERROR(VLOOKUP(K5,源_9年终奖表_Sheet1!$A:$E,4,FALSE),0) -> 600 | AS5: =IFERROR(VLOOKUP(K5,源_4奖金汇总表_拆分手工算!$A:$N,14,FALSE),0)+IFERROR(VLOOKUP(K5,源_9年终奖表_Sheet1!$A:$E,5,FALSE),0) -> 111 | AT5: =IFERROR(VLOOKUP(K5,源_5薪资备忘录_工资调整项!$A:$AC,20,FALSE),0) -> 0 | AU5: =IFERROR(VLOOKUP(K5,源_5薪资备忘录_工资调整项!$A:$AC,21,FALSE),0)+IFERROR(VLOOKUP(K5,源_4奖金汇总表_拆分手工算!$A:$N,9,FALSE),0) -> 1456.81 | AV5: =R5/参数!$B$4*(IFERROR(VLOOKUP(K5,源_3考勤报表_考勤表!$F:$BG,37,FALSE),0)+IFERROR(VLOOKUP(K5,源_8补工时表_补当月工时!$A:$AC,15,FALSE),0)) -> 0 | AW5: =R5/174*MIN(IFERROR(VLOOKUP(K5,源_3考勤报表_考勤表!$F:$BG,35,FALSE),0),174)*IF(DATEDIF(N5,DATE(参数!$B$2,参数!$B$3+1,0),"Y")<2,0.6,IF(DATEDIF(N5,DATE(参数!$B$2,参数!$B$3+1,0),"Y")<4,0.7,IF(DATEDIF(N5,DATE(参数!$B$2,参数!$B$3+1,0),"Y")<6,0.8,IF(DATEDIF(N5,DATE(参数!$B$2,参数!$B$3+1,0),"Y")<8,0.9,1)))) -> 0 | AX5: =IF(Q5+IFERROR(VLOOKUP(K5,源_3考勤报表_考勤表!$F:$BG,37,FALSE),0)+IFERROR(VLOOKUP(K5,源_8补工时表_补当月工时!$A:$AC,15,FALSE),0)>=参数!$B$4,0,IF(Q5+IFERROR(VLOOKUP(K5,源_3考勤报表_考勤表!$F:$BG,37,FALSE),0)+IFERROR(VLOOKUP(K5,源_8补工时表_补当月工时!$A:$AC,15,FALSE),0)+IFERROR(VLOOKUP(K5,源_3考勤报表_考勤表!$F:$BG,38,FALSE),0)+IFERROR(VLOOKUP(K5,源_8补工时表_补当月工时!$A:$AC,17,FALSE),0)+IFERROR(VLOOKUP(K5,源_3考勤报表_考勤表!$F:$BG,40,FALSE),0)+IFERROR(VLOOKUP(K5,源_8补工时表_补当月工时!$A:$AC,20,FALSE),0)+IFERROR(VLOOKUP(K5,源_8补工时表_补当月工时!$A:$AC,22,FALSE),0)+IFERROR(VLOOKUP(K5,源_3考勤报表_考勤表!$F:$BG,41,FALSE),0)+IFERROR(VLOOKUP(K5,源_8补工时表_补当月工时!$A:$AC,18,FALSE),0)+IFERROR(VLOOKUP(K5,源_3考勤报表_考勤表!$F:$BG,42,FALSE),0)+IFERROR(VLOOKUP(K5,源_8补工时表_补当月工时!$A:$AC,19,FALSE),0)+IFERROR(VLOOKUP(K5,源_3考勤报表_考勤表!$F:$BG,44,FALSE),0)+IFERROR(VLOOKUP(K5,源_8补工时表_补当月工时!$A:$AC,16,FALSE),0)+IFERROR(VLOOKUP(K5,源_3考勤报表_考勤表!$F:$BG,45,FALSE),0)<=参数!$B$4,R5/参数!$B$4*(IFERROR(VLOOKUP(K5,源_3考勤报表_考勤表!$F:$BG,38,FALSE),0)+IFERROR(VLOOKUP(K5,源_8补工时表_补当月工时!$A:$AC,17,FALSE),0)+IFERROR(VLOOKUP(K5,源_3考勤报表_考勤表!$F:$BG,40,FALSE),0)+IFERROR(VLOOKUP(K5,源_8补工时表_补当月工时!$A:$AC,20,FALSE),0)+IFERROR(VLOOKUP(K5,源_8补工时表_补当月工时!$A:$AC,22,FALSE),0)+IFERROR(VLOOKUP(K5,源_3考勤报表_考勤表!$F:$BG,41,FALSE),0)+IFERROR(VLOOKUP(K5,源_8补工时表_补当月工时!$A:$AC,18,FALSE),0)+IFERROR(VLOOKUP(K5,源_3考勤报表_考勤表!$F:$BG,42,FALSE),0)+IFERROR(VLOOKUP(K5,源_8补工时表_补当月工时!$A:$AC,19,FALSE),0)+IFERROR(VLOOKUP(K5,源_3考勤报表_考勤表!$F:$BG,44,FALSE),0)+IFERROR(VLOOKUP(K5,源_8补工时表_补当月工时!$A:$AC,16,FALSE),0)+IFERROR(VLOOKUP(K5,源_3考勤报表_考勤表!$F:$BG,45,FALSE),0)),0)) -> 0 | AY5: 0 | AZ5: 0 | BA5: 0 | BB5: 0 | BC5: =IFERROR(VLOOKUP(K5,源_5薪资备忘录_工资调整项!$A:$AC,25,FALSE),0) -> 0 | BD5: 0 | BE5: 0 | BF5: 0 | BG5: =IFERROR(VLOOKUP(K5,源_5薪资备忘录_工资调整项!$A:$AC,22,FALSE),0)+IFERROR(VLOOKUP(K5,源_5薪资备忘录_工资调整项!$A:$AC,23,FALSE),0)+IFERROR(VLOOKUP(K5,源_5薪资备忘录_工资调整项!$A:$AC,24,FALSE),0) -> 0 | BH5: =IFERROR(VLOOKUP(DF5,源_6社保表_Sheet1!$C:$CD,80,FALSE),0)+4.5 -> 6.5 | BI5: =T5+W5+AB5+AG5+AH5+AI5+AJ5+AK5+AL5+AM5+AN5+AO5+AP5+AQ5+AR5+AS5+AT5+AU5+AV5+AW5+AX5+BC5 -> 11650.81 | BJ5: =IFERROR(VLOOKUP(DF5,源_6社保表_Sheet1!$C:$BZ,26,FALSE),0) -> 671.76 | BK5: =IFERROR(VLOOKUP(DF5,源_6社保表_Sheet1!$C:$BZ,27,FALSE),0) -> 167.94 | BL5: =IFERROR(VLOOKUP(DF5,源_6社保表_Sheet1!$C:$BZ,28,FALSE),0) -> 41.985 | BM5: =IFERROR(VLOOKUP(DF5,源_6社保表_Sheet1!$C:$BZ,30,FALSE),0) -> 587.79 | BN5: =IFERROR(VLOOKUP(DF5,源_6社保表_Sheet1!$C:$BZ,29,FALSE),0) -> 0 | BO5: =IFERROR(VLOOKUP(DF5,源_6社保表_Sheet1!$C:$BZ,40,FALSE),0) -> 0 | BP5: =IFERROR(VLOOKUP(DF5,源_6社保表_Sheet1!$C:$BZ,41,FALSE),0) -> 0 | BQ5: =IFERROR(VLOOKUP(DF5,源_6社保表_Sheet1!$C:$BZ,42,FALSE),0) -> 0 | BR5: =IFERROR(VLOOKUP(DF5,源_6社保表_Sheet1!$C:$BZ,44,FALSE),0) -> 0 | BS5: =IFERROR(VLOOKUP(DF5,源_6社保表_Sheet1!$C:$BZ,43,FALSE),0) -> 0 | BT5: =BJ5+BK5+BL5+BM5+BN5+BO5+BP5+BQ5+BR5+BS5 -> 1469.475 | BU5: 0 | BV5: 0 | BW5: 0 | BX5: =BU5+BV5+BW5 -> 0 | BY5: 0 | BZ5: =IFERROR(VLOOKUP(DF5,源_6社保表_Sheet1!$C:$BZ,18,FALSE),0) -> 1343.52 | CA5: =IFERROR(VLOOKUP(DF5,源_6社保表_Sheet1!$C:$BZ,19,FALSE),0) -> 755.73 | CB5: =IFERROR(VLOOKUP(DF5,源_6社保表_Sheet1!$C:$BZ,24,FALSE),0) -> 587.79 | CC5: =IFERROR(VLOOKUP(DF5,源_6社保表_Sheet1!$C:$BZ,20,FALSE),0) -> 41.985 | CD5: =IFERROR(VLOOKUP(DF5,源_6社保表_Sheet1!$C:$BZ,21,FALSE),0) -> 26.8704 | CE5: =IFERROR(VLOOKUP(DF5,源_6社保表_Sheet1!$C:$BZ,22,FALSE),0) -> 0 | CF5: =IFERROR(VLOOKUP(DF5,源_6社保表_Sheet1!$C:$BZ,23,FALSE),0) -> 0 | CG5: =IFERROR(VLOOKUP(DF5,源_6社保表_Sheet1!$C:$BZ,32,FALSE),0) -> 0 | CH5: =IFERROR(VLOOKUP(DF5,源_6社保表_Sheet1!$C:$BZ,33,FALSE),0) -> 0 | CI5: =IFERROR(VLOOKUP(DF5,源_6社保表_Sheet1!$C:$BZ,34,FALSE),0) -> 0 | CJ5: =IFERROR(VLOOKUP(DF5,源_6社保表_Sheet1!$C:$BZ,38,FALSE),0) -> 0 | CK5: =IFERROR(VLOOKUP(DF5,源_6社保表_Sheet1!$C:$BZ,35,FALSE),0) -> 0 | CL5: =IFERROR(VLOOKUP(DF5,源_6社保表_Sheet1!$C:$BZ,36,FALSE),0) -> 0 | CM5: =IFERROR(VLOOKUP(DF5,源_6社保表_Sheet1!$C:$BZ,37,FALSE),0) -> 0 | CN5: =BZ5+CA5+CB5+CC5+CD5+CE5+CF5+CG5+CH5+CI5+CJ5+CK5+CL5+CM5 -> 2755.8954 | CO5: =BI5+BG5+CN5+BE5+BH5 -> 14413.205 | CP5: =IF(IFERROR(VLOOKUP(K5,源_13残疾人信息_残疾人信息!$A:$M,1,FALSE),"")<>"",0,IF(OR(P5="门店全职",P5="门店管理组",P5="全职(非门店)"),(BI5-AT5)*IFERROR(VLOOKUP(D5,源_12计提残保金规则_Sheet1!$A:$E,4,FALSE),0)*IFERROR(VLOOKUP(D5,源_12计提残保金规则_Sheet1!$A:$E,5,FALSE),0),0)) -> 157.28593 | CQ5: =IF(M5="行政",0,16.05) -> 16.05 | CR5: =IF(M5="门卫",0,20.67) -> 20.67 | CS5: =IF(DATEVALUE(N5)>DATE(参数!$B$2,9,30),0,IF(M5="行政",0,IF(O5="",R5/12,IF(MONTH(DATEVALUE(O5))=参数!$B$3,0,IF(DATEVALUE(O5)<DATE(参数!$B$2,参数!$B$3,1),0,R5/12))))) -> 665 | CT5: =IF(P5="门店管理组",R5*0.12*0.85,0) -> 813.96 | CU5: =IFERROR(VLOOKUP(DF5,源_6社保表_Sheet1!$C:$I,2,FALSE),0) -> 8397 | CV5: =IFERROR(VLOOKUP(DF5,源_6社保表_Sheet1!$C:$I,7,FALSE),0) -> 8397 | CW5: =IFERROR(VLOOKUP(DF5,源_6社保表_Sheet1!$C:$I,3,FALSE),0) -> 8397 | CX5: =IFERROR(VLOOKUP(DF5,源_6社保表_Sheet1!$C:$I,4,FALSE),0) -> 8397 | CY5: =IFERROR(VLOOKUP(DF5,源_6社保表_Sheet1!$C:$I,5,FALSE),0) -> 8397 | CZ5: =IFERROR(VLOOKUP(DF5,源_6社保表_Sheet1!$C:$I,6,FALSE),0) -> 0 | DA5: =BI5+CN5-AG5-AH5-AI5-AJ5-AK5-AL5-AM5-AQ5-AR5-AS5-AT5 -> 12245.705 | DB5: =DA5+CP5+CQ5+CR5+CS5+CT5+BH5 -> 13925.171 | DC5: =IFERROR(VLOOKUP(K5,源_7银行卡表_Sheet1!$A:$J,8,FALSE),"") -> 招商银行 | DD5: =IFERROR(VLOOKUP(K5,源_7银行卡表_Sheet1!$A:$J,9,FALSE),"") -> 6681360063544614654 | DE5: =IFERROR(VLOOKUP(K5,源_7银行卡表_Sheet1!$A:$J,10,FALSE),"") -> 成都星宸国际支行 | DF5: 140000198209249885 | DG5: 13793270325 | DH5: 上海 | DI5: 0 | DJ5: 0 | DK5: 0 | DL5: 0 | DM5: 0 | DN5: 0 | DO5: 0 | DP5: 0 | DQ5: 0 | DR5: =IF(OR(IFERROR(VLOOKUP(K5,源_3考勤报表_考勤表!$F:$BG,39,FALSE),0)+IFERROR(VLOOKUP(K5,源_8补工时表_补当月工时!$A:$AC,24,FALSE),0)=0,IFERROR(VLOOKUP(K5,源_3考勤报表_考勤表!$F:$BG,43,FALSE),0)+IFERROR(VLOOKUP(K5,源_8补工时表_补当月工时!$A:$AC,26,FALSE),0)=0),IF(BI5+BG5-BT5<0,BI5+BG5-BT5,0),0) -> 0
